Workbook

Sheet Arabica Dbse
A1: =_xll.RHistory(D4:Z4,"TRDPRC_1.Timestamp;TRDPRC_1.Close","START:01-Aug-2010 INTERVAL:1D",,"TSREPEAT:NO CH:Fd",C6) -> Updated at 14:05:36 | Q1: Brazil NY 3/4 MGTB | R1: Brazil Santos | S1: Brazil Rio Minas 15/16 | T1: Brazil Rio Minas 17/18 | U1: Ethiopia Djimmah 5 | V1: Uganda Drugar | W1: India Cherry AB | X1: Colombia Excelso | Y1: Honduras HG | Z1: Brazil WARB Bahia | AA1: Peru MCM Grd 1 | AB1: Guatemala SHB | AC1: None | AD1: Vietnam Grd 1 | AE1: Vietnam Grd 2 | AF1: Vietnam Grd 2: 5% Black | AG1: Vietnam Grd 2: 8% Blck | AH1: Indonesia | AI1: Uganda Screen 12 | AJ1: Uganda Screen 15 | AK1: India Cherry AB | AL1: Ivy Cst Grd 1 | AM1: None
D2: Arabica | K2: Washed Arabica
D3: 1 | E3: 2 | F3: 3 | G3: 4 | H3: 5 | I3: 6 | J3: 7 | K3: 8 | L3: 9 | M3: 10 | N3: 11 | O3: 12
D4: COF-ARB-BRDIF | E4: COF-ARB-BRSDF | F4: COF-ARB-BRMIF | G4: COF-ARB-BRRDF | H4: COF-ARB-ETDIF | I4: COF-ARB-UGDIF | J4: COF-ARB-INDIF | K4: COF-WARB-CODIF | L4: COF-WARB-HNHDF | M4: COF-WARB-BRDIF | N4: COF-WARB-PEDIF | O4: COF-WARB-GTDIF
A5: LRC | B5: KC | D5: Brazil NY 3/4 MGTB | E5: Brazil Santos | F5: Brazil Rio Minas 15/16 | G5: Brazil Rio Minas 17/18 | H5: Ethiopia Djimmah 5 | I5: Uganda Drugar | J5: India Cherry AB | K5: Colombia Excelso | L5: Honduras HG | M5: Brazil WARB Bahia | N5: Peru MCM Grd 1 | O5: Guatemala SHB | S5: KCc2 | T5: LRCc2 | U5: LRC
C6: Timestamp | D6: Trade Close | E6: Trade Close | F6: Trade Close | G6: Trade Close | H6: Trade Close | I6: Trade Close | J6: Trade Close | K6: Trade Close | L6: Trade Close | M6: Trade Close | N6: Trade Close | O6: Trade Close | Q6: =_xll.RHistory($S$5:$T$5,".Timestamp;.Close","START:01-Aug-2001 INTERVAL:1D",,"TSREPEAT:NO CH:Fd",R7) -> Updated at 14:05:37 | W6: Date | X6: Brazil NY 3/4 MGTB | Y6: Brazil Santos | Z6: Brazil Rio Minas 15/16 | AA6: Brazil Rio Minas 17/18 | AB6: Ethiopia Djimmah 5 | AC6: Uganda Drugar | AD6: India Cherry AB | AE6: Colombia Excelso | AF6: Honduras HG | AG6: Brazil WARB Bahia | AH6: Peru MCM Grd 1 | AI6: Guatemala SHB
A7: =IF(_xlfn.XLOOKUP($C7,R:R,U:U)=0,A8,_xlfn.XLOOKUP($C7,R:R,U:U)) -> #N/A | B7: =IF(_xlfn.XLOOKUP($C7,R:R,S:S)=0,B8,_xlfn.XLOOKUP($C7,R:R,S:S)) -> #N/A | C7: 46317 | D7: -16 | E7: -6 | F7: -70 | G7: -45 | H7: -19 | I7: -18 | J7: -5 | K7: 70 | L7: 27 | M7: 30 | N7: 50 | O7: 60 | R7: Timestamp | S7: Trade Close | T7: Trade Close | W7: =C7 -> 46317 | X7: =IF(D7=0,NA(),($B7+D7)*22.406) -> #N/A | Y7: =IF(E7=0,NA(),($B7+E7)*22.406) -> #N/A | Z7: =IF(F7=0,NA(),($B7+F7)*22.406) -> #N/A | AA7: =IF(G7=0,NA(),($B7+G7)*22.406) -> #N/A | AB7: =IF(H7=0,NA(),($B7+H7)*22.406) -> #N/A | AC7: =IF(I7=0,NA(),($B7+I7)*22.406) -> #N/A | AD7: =IF(J7=0,NA(),($B7+J7)*22.406) -> #N/A | AE7: =IF(K7=0,NA(),($B7+K7)*22.406) -> #N/A | ... AI7: =IF(O7=0,NA(),($B7+O7)*22.406) -> #N/A
A8: =IF(_xlfn.XLOOKUP($C8,R:R,U:U)=0,A9,_xlfn.XLOOKUP($C8,R:R,U:U)) -> #N/A | B8: =IF(_xlfn.XLOOKUP($C8,R:R,S:S)=0,B9,_xlfn.XLOOKUP($C8,R:R,S:S)) -> #N/A | C8: 46310 | D8: -15 | E8: -5 | F8: -60 | G8: -35 | H8: -18 | I8: -18 | J8: -5 | K8: 72 | L8: 25 | M8: 30 | N8: 50 | O8: 60 | R8: 46009 | S8: 346.85 | T8: 3679 | U8: =IF(T8=0,T9,T8) -> 3679 | W8: =C8 -> 46310 | X8: =IF(D8=0,NA(),($B8+D8)*22.406) -> #N/A | Y8: =IF(E8=0,NA(),($B8+E8)*22.406) -> #N/A | Z8: =IF(F8=0,NA(),($B8+F8)*22.406) -> #N/A | AA8: =IF(G8=0,NA(),($B8+G8)*22.406) -> #N/A | AB8: =IF(H8=0,NA(),($B8+H8)*22.406) -> #N/A | AC8: =IF(I8=0,NA(),($B8+I8)*22.406) -> #N/A | AD8: =IF(J8=0,NA(),($B8+J8)*22.406) -> #N/A | AE8: =IF(K8=0,NA(),($B8+K8)*22.406) -> #N/A | ... AI8: =IF(O8=0,NA(),($B8+O8)*22.406) -> #N/A
A9: =IF(_xlfn.XLOOKUP($C9,R:R,U:U)=0,A10,_xlfn.XLOOKUP($C9,R:R,U:U)) -> #N/A | B9: =IF(_xlfn.XLOOKUP($C9,R:R,S:S)=0,B10,_xlfn.XLOOKUP($C9,R:R,S:S)) -> #N/A | C9: 46303 | D9: -14 | E9: -3 | F9: -48 | G9: -35 | H9: -17 | I9: -18 | J9: -5 | K9: 75 | L9: 23 | M9: 30 | N9: 50 | O9: 60 | R9: 46008 | S9: 347.4 | T9: 3705 | U9: =IF(T9=0,T10,T9) -> 3705 | W9: =C9 -> 46303 | X9: =IF(D9=0,NA(),($B9+D9)*22.406) -> #N/A | Y9: =IF(E9=0,NA(),($B9+E9)*22.406) -> #N/A | Z9: =IF(F9=0,NA(),($B9+F9)*22.406) -> #N/A | AA9: =IF(G9=0,NA(),($B9+G9)*22.406) -> #N/A | AB9: =IF(H9=0,NA(),($B9+H9)*22.406) -> #N/A | AC9: =IF(I9=0,NA(),($B9+I9)*22.406) -> #N/A | AD9: =IF(J9=0,NA(),($B9+J9)*22.406) -> #N/A | AE9: =IF(K9=0,NA(),($B9+K9)*22.406) -> #N/A | ... AI9: =IF(O9=0,NA(),($B9+O9)*22.406) -> #N/A
A10: =IF(_xlfn.XLOOKUP($C10,R:R,U:U)=0,A11,_xlfn.XLOOKUP($C10,R:R,U:U)) -> #N/A | B10: =IF(_xlfn.XLOOKUP($C10,R:R,S:S)=0,B11,_xlfn.XLOOKUP($C10,R:R,S:S)) -> #N/A | C10: 46296 | D10: -15 | E10: -5 | F10: -48 | G10: -35 | H10: -17 | I10: -20 | J10: -5 | K10: 75 | L10: 23 | M10: 30 | N10: 50 | O10: 60 | R10: 46007 | S10: 352.1 | T10: 3832 | U10: =IF(T10=0,T11,T10) -> 3832 | W10: =C10 -> 46296 | X10: =IF(D10=0,NA(),($B10+D10)*22.406) -> #N/A | Y10: =IF(E10=0,NA(),($B10+E10)*22.406) -> #N/A | Z10: =IF(F10=0,NA(),($B10+F10)*22.406) -> #N/A | AA10: =IF(G10=0,NA(),($B10+G10)*22.406) -> #N/A | AB10: =IF(H10=0,NA(),($B10+H10)*22.406) -> #N/A | AC10: =IF(I10=0,NA(),($B10+I10)*22.406) -> #N/A | AD10: =IF(J10=0,NA(),($B10+J10)*22.406) -> #N/A | AE10: =IF(K10=0,NA(),($B10+K10)*22.406) -> #N/A | ... AI10: =IF(O10=0,NA(),($B10+O10)*22.406) -> #N/A
A11: =IF(_xlfn.XLOOKUP($C11,R:R,U:U)=0,A12,_xlfn.XLOOKUP($C11,R:R,U:U)) -> #N/A | B11: =IF(_xlfn.XLOOKUP($C11,R:R,S:S)=0,B12,_xlfn.XLOOKUP($C11,R:R,S:S)) -> #N/A | C11: 46289 | D11: -16 | E11: -6 | F11: -50 | G11: -35 | H11: -18 | I11: -20 | J11: -5 | K11: 78 | L11: 23 | M11: 30 | N11: 50 | O11: 60 | R11: 46006 | S11: 360.3 | T11: 3923 | U11: =IF(T11=0,T12,T11) -> 3923 | W11: =C11 -> 46289 | X11: =IF(D11=0,NA(),($B11+D11)*22.406) -> #N/A | Y11: =IF(E11=0,NA(),($B11+E11)*22.406) -> #N/A | Z11: =IF(F11=0,NA(),($B11+F11)*22.406) -> #N/A | AA11: =IF(G11=0,NA(),($B11+G11)*22.406) -> #N/A | AB11: =IF(H11=0,NA(),($B11+H11)*22.406) -> #N/A | AC11: =IF(I11=0,NA(),($B11+I11)*22.406) -> #N/A | AD11: =IF(J11=0,NA(),($B11+J11)*22.406) -> #N/A | AE11: =IF(K11=0,NA(),($B11+K11)*22.406) -> #N/A | ... AI11: =IF(O11=0,NA(),($B11+O11)*22.406) -> #N/A
A12: =IF(_xlfn.XLOOKUP($C12,R:R,U:U)=0,A13,_xlfn.XLOOKUP($C12,R:R,U:U)) -> #N/A | B12: =IF(_xlfn.XLOOKUP($C12,R:R,S:S)=0,B13,_xlfn.XLOOKUP($C12,R:R,S:S)) -> #N/A | C12: 46282 | D12: -21 | E12: -8 | F12: -55 | G12: -35 | H12: -25 | I12: -25 | J12: -5 | K12: 78 | L12: 23 | M12: 30 | N12: 50 | O12: 62 | R12: 46003 | S12: 369.3 | T12: 3999 | U12: =IF(T12=0,T13,T12) -> 3999 | W12: =C12 -> 46282 | X12: =IF(D12=0,NA(),($B12+D12)*22.406) -> #N/A | Y12: =IF(E12=0,NA(),($B12+E12)*22.406) -> #N/A | Z12: =IF(F12=0,NA(),($B12+F12)*22.406) -> #N/A | AA12: =IF(G12=0,NA(),($B12+G12)*22.406) -> #N/A | AB12: =IF(H12=0,NA(),($B12+H12)*22.406) -> #N/A | AC12: =IF(I12=0,NA(),($B12+I12)*22.406) -> #N/A | AD12: =IF(J12=0,NA(),($B12+J12)*22.406) -> #N/A | AE12: =IF(K12=0,NA(),($B12+K12)*22.406) -> #N/A | ... AI12: =IF(O12=0,NA(),($B12+O12)*22.406) -> #N/A
A13: =IF(_xlfn.XLOOKUP($C13,R:R,U:U)=0,A14,_xlfn.XLOOKUP($C13,R:R,U:U)) -> #N/A | B13: =IF(_xlfn.XLOOKUP($C13,R:R,S:S)=0,B14,_xlfn.XLOOKUP($C13,R:R,S:S)) -> #N/A | C13: 46275 | D13: -20 | E13: -10 | F13: -60 | G13: -40 | H13: -28 | I13: -28 | J13: -5 | K13: 75 | L13: 23 | M13: 30 | N13: 45 | O13: 62 | R13: 46002 | S13: 376.2 | T13: 4107 | U13: =IF(T13=0,T14,T13) -> 4107 | W13: =C13 -> 46275 | X13: =IF(D13=0,NA(),($B13+D13)*22.406) -> #N/A | Y13: =IF(E13=0,NA(),($B13+E13)*22.406) -> #N/A | Z13: =IF(F13=0,NA(),($B13+F13)*22.406) -> #N/A | AA13: =IF(G13=0,NA(),($B13+G13)*22.406) -> #N/A | AB13: =IF(H13=0,NA(),($B13+H13)*22.406) -> #N/A | AC13: =IF(I13=0,NA(),($B13+I13)*22.406) -> #N/A | AD13: =IF(J13=0,NA(),($B13+J13)*22.406) -> #N/A | AE13: =IF(K13=0,NA(),($B13+K13)*22.406) -> #N/A | ... AI13: =IF(O13=0,NA(),($B13+O13)*22.406) -> #N/A
A14: =IF(_xlfn.XLOOKUP($C14,R:R,U:U)=0,A15,_xlfn.XLOOKUP($C14,R:R,U:U)) -> #N/A | B14: =IF(_xlfn.XLOOKUP($C14,R:R,S:S)=0,B15,_xlfn.XLOOKUP($C14,R:R,S:S)) -> #N/A | C14: 46268 | D14: -18 | E14: -10 | F14: -60 | G14: -48 | H14: -28 | I14: -28 | J14: -5 | K14: 75 | L14: 23 | M14: 30 | N14: 40 | O14: 65 | R14: 46001 | S14: 372.3 | T14: 4138 | U14: =IF(T14=0,T15,T14) -> 4138 | W14: =C14 -> 46268 | X14: =IF(D14=0,NA(),($B14+D14)*22.406) -> #N/A | Y14: =IF(E14=0,NA(),($B14+E14)*22.406) -> #N/A | Z14: =IF(F14=0,NA(),($B14+F14)*22.406) -> #N/A | AA14: =IF(G14=0,NA(),($B14+G14)*22.406) -> #N/A | AB14: =IF(H14=0,NA(),($B14+H14)*22.406) -> #N/A | AC14: =IF(I14=0,NA(),($B14+I14)*22.406) -> #N/A | AD14: =IF(J14=0,NA(),($B14+J14)*22.406) -> #N/A | AE14: =IF(K14=0,NA(),($B14+K14)*22.406) -> #N/A | ... AI14: =IF(O14=0,NA(),($B14+O14)*22.406) -> #N/A
A15: =IF(_xlfn.XLOOKUP($C15,R:R,U:U)=0,A16,_xlfn.XLOOKUP($C15,R:R,U:U)) -> #N/A | B15: =IF(_xlfn.XLOOKUP($C15,R:R,S:S)=0,B16,_xlfn.XLOOKUP($C15,R:R,S:S)) -> #N/A | C15: 46261 | D15: -18 | E15: -7 | F15: -55 | G15: -45 | H15: -25 | I15: -25 | J15: -5 | K15: 75 | L15: 23 | M15: 30 | N15: 40 | O15: 65 | R15: 46000 | S15: 368.75 | T15: 4109 | U15: =IF(T15=0,T16,T15) -> 4109 | W15: =C15 -> 46261 | X15: =IF(D15=0,NA(),($B15+D15)*22.406) -> #N/A | Y15: =IF(E15=0,NA(),($B15+E15)*22.406) -> #N/A | Z15: =IF(F15=0,NA(),($B15+F15)*22.406) -> #N/A | AA15: =IF(G15=0,NA(),($B15+G15)*22.406) -> #N/A | AB15: =IF(H15=0,NA(),($B15+H15)*22.406) -> #N/A | AC15: =IF(I15=0,NA(),($B15+I15)*22.406) -> #N/A | AD15: =IF(J15=0,NA(),($B15+J15)*22.406) -> #N/A | AE15: =IF(K15=0,NA(),($B15+K15)*22.406) -> #N/A | ... AI15: =IF(O15=0,NA(),($B15+O15)*22.406) -> #N/A
A16: =IF(_xlfn.XLOOKUP($C16,R:R,U:U)=0,A17,_xlfn.XLOOKUP($C16,R:R,U:U)) -> #N/A | B16: =IF(_xlfn.XLOOKUP($C16,R:R,S:S)=0,B17,_xlfn.XLOOKUP($C16,R:R,S:S)) -> #N/A | C16: 46254 | D16: -17 | E16: -5 | F16: -50 | G16: -40 | H16: -25 | I16: -25 | J16: -5 | K16: 78 | L16: 23 | M16: 30 | N16: 40 | O16: 65 | R16: 45999 | S16: 366.2 | T16: 4092 | U16: =IF(T16=0,T17,T16) -> 4092 | W16: =C16 -> 46254 | X16: =IF(D16=0,NA(),($B16+D16)*22.406) -> #N/A | Y16: =IF(E16=0,NA(),($B16+E16)*22.406) -> #N/A | Z16: =IF(F16=0,NA(),($B16+F16)*22.406) -> #N/A | AA16: =IF(G16=0,NA(),($B16+G16)*22.406) -> #N/A | AB16: =IF(H16=0,NA(),($B16+H16)*22.406) -> #N/A | AC16: =IF(I16=0,NA(),($B16+I16)*22.406) -> #N/A | AD16: =IF(J16=0,NA(),($B16+J16)*22.406) -> #N/A | AE16: =IF(K16=0,NA(),($B16+K16)*22.406) -> #N/A | ... AI16: =IF(O16=0,NA(),($B16+O16)*22.406) -> #N/A
A17: =IF(_xlfn.XLOOKUP($C17,R:R,U:U)=0,A18,_xlfn.XLOOKUP($C17,R:R,U:U)) -> #N/A | B17: =IF(_xlfn.XLOOKUP($C17,R:R,S:S)=0,B18,_xlfn.XLOOKUP($C17,R:R,S:S)) -> #N/A | C17: 46247 | D17: -15 | E17: -2 | F17: -50 | G17: -40 | H17: -25 | I17: -20 | J17: -5 | K17: 76 | L17: 23 | M17: 30 | N17: 34 | O17: 65 | R17: 45996 | S17: 374.85 | T17: 4178 | U17: =IF(T17=0,T18,T17) -> 4178 | W17: =C17 -> 46247 | X17: =IF(D17=0,NA(),($B17+D17)*22.406) -> #N/A | Y17: =IF(E17=0,NA(),($B17+E17)*22.406) -> #N/A | Z17: =IF(F17=0,NA(),($B17+F17)*22.406) -> #N/A | AA17: =IF(G17=0,NA(),($B17+G17)*22.406) -> #N/A | AB17: =IF(H17=0,NA(),($B17+H17)*22.406) -> #N/A | AC17: =IF(I17=0,NA(),($B17+I17)*22.406) -> #N/A | AD17: =IF(J17=0,NA(),($B17+J17)*22.406) -> #N/A | AE17: =IF(K17=0,NA(),($B17+K17)*22.406) -> #N/A | ... AI17: =IF(O17=0,NA(),($B17+O17)*22.406) -> #N/A
A18: =IF(_xlfn.XLOOKUP($C18,R:R,U:U)=0,A19,_xlfn.XLOOKUP($C18,R:R,U:U)) -> #N/A | B18: =IF(_xlfn.XLOOKUP($C18,R:R,S:S)=0,B19,_xlfn.XLOOKUP($C18,R:R,S:S)) -> #N/A | C18: 46240 | D18: -16 | E18: -5 | F18: -50 | G18: -40 | H18: -25 | I18: -20 | J18: -8 | K18: 75 | L18: 18 | M18: 25 | N18: 32 | O18: 55 | R18: 45995 | S18: 380.5 | T18: 4232 | U18: =IF(T18=0,T19,T18) -> 4232 | W18: =C18 -> 46240 | X18: =IF(D18=0,NA(),($B18+D18)*22.406) -> #N/A | Y18: =IF(E18=0,NA(),($B18+E18)*22.406) -> #N/A | Z18: =IF(F18=0,NA(),($B18+F18)*22.406) -> #N/A | AA18: =IF(G18=0,NA(),($B18+G18)*22.406) -> #N/A | AB18: =IF(H18=0,NA(),($B18+H18)*22.406) -> #N/A | AC18: =IF(I18=0,NA(),($B18+I18)*22.406) -> #N/A | AD18: =IF(J18=0,NA(),($B18+J18)*22.406) -> #N/A | AE18: =IF(K18=0,NA(),($B18+K18)*22.406) -> #N/A | ... AI18: =IF(O18=0,NA(),($B18+O18)*22.406) -> #N/A
A19: =IF(_xlfn.XLOOKUP($C19,R:R,U:U)=0,A20,_xlfn.XLOOKUP($C19,R:R,U:U)) -> #N/A | B19: =IF(_xlfn.XLOOKUP($C19,R:R,S:S)=0,B20,_xlfn.XLOOKUP($C19,R:R,S:S)) -> #N/A | C19: 46233 | D19: -18 | E19: -8 | F19: -50 | G19: -40 | H19: -30 | I19: -22 | J19: -5 | K19: 72 | L19: 18 | M19: 25 | N19: 32 | O19: 55 | R19: 45994 | S19: 372.45 | T19: 4212 | U19: =IF(T19=0,T20,T19) -> 4212 | W19: =C19 -> 46233 | X19: =IF(D19=0,NA(),($B19+D19)*22.406) -> #N/A | Y19: =IF(E19=0,NA(),($B19+E19)*22.406) -> #N/A | Z19: =IF(F19=0,NA(),($B19+F19)*22.406) -> #N/A | AA19: =IF(G19=0,NA(),($B19+G19)*22.406) -> #N/A | AB19: =IF(H19=0,NA(),($B19+H19)*22.406) -> #N/A | AC19: =IF(I19=0,NA(),($B19+I19)*22.406) -> #N/A | AD19: =IF(J19=0,NA(),($B19+J19)*22.406) -> #N/A | AE19: =IF(K19=0,NA(),($B19+K19)*22.406) -> #N/A | ... AI19: =IF(O19=0,NA(),($B19+O19)*22.406) -> #N/A
... A22: =IF(_xlfn.XLOOKUP($C22,R:R,U:U)=0,A23,_xlfn.XLOOKUP($C22,R:R,U:U)) -> #N/A | B22: =IF(_xlfn.XLOOKUP($C22,R:R,S:S)=0,B23,_xlfn.XLOOKUP($C22,R:R,S:S)) -> #N/A | C22: 46212 | D22: -18 | E22: -6 | F22: -50 | G22: -40 | H22: -25 | I22: -22 | J22: -5 | K22: 82 | L22: 20 | M22: 30 | N22: 32 | O22: 60 | R22: 45989 | S22: 381.2 | T22: 4413 | U22: =IF(T22=0,T23,T22) -> 4413 | W22: =C22 -> 46212 | X22: =IF(D22=0,NA(),($B22+D22)*22.406) -> #N/A | Y22: =IF(E22=0,NA(),($B22+E22)*22.406) -> #N/A | Z22: =IF(F22=0,NA(),($B22+F22)*22.406) -> #N/A | AA22: =IF(G22=0,NA(),($B22+G22)*22.406) -> #N/A | AB22: =IF(H22=0,NA(),($B22+H22)*22.406) -> #N/A | AC22: =IF(I22=0,NA(),($B22+I22)*22.406) -> #N/A | AD22: =IF(J22=0,NA(),($B22+J22)*22.406) -> #N/A | AE22: =IF(K22=0,NA(),($B22+K22)*22.406) -> #N/A | ... AI22: =IF(O22=0,NA(),($B22+O22)*22.406) -> #N/A
A23: =IF(_xlfn.XLOOKUP($C23,R:R,U:U)=0,A24,_xlfn.XLOOKUP($C23,R:R,U:U)) -> #N/A | B23: =IF(_xlfn.XLOOKUP($C23,R:R,S:S)=0,B24,_xlfn.XLOOKUP($C23,R:R,S:S)) -> #N/A | C23: 46205 | D23: -18 | E23: -6 | F23: -50 | G23: -40 | H23: -20 | I23: -20 | J23: -5 | K23: 82 | L23: 20 | M23: 30 | N23: 32 | O23: 58 | R23: 45988 | T23: 4389 | U23: =IF(T23=0,T24,T23) -> 4389 | W23: =C23 -> 46205 | X23: =IF(D23=0,NA(),($B23+D23)*22.406) -> #N/A | Y23: =IF(E23=0,NA(),($B23+E23)*22.406) -> #N/A | Z23: =IF(F23=0,NA(),($B23+F23)*22.406) -> #N/A | AA23: =IF(G23=0,NA(),($B23+G23)*22.406) -> #N/A | AB23: =IF(H23=0,NA(),($B23+H23)*22.406) -> #N/A | AC23: =IF(I23=0,NA(),($B23+I23)*22.406) -> #N/A | AD23: =IF(J23=0,NA(),($B23+J23)*22.406) -> #N/A | AE23: =IF(K23=0,NA(),($B23+K23)*22.406) -> #N/A | ... AI23: =IF(O23=0,NA(),($B23+O23)*22.406) -> #N/A
A24: =IF(_xlfn.XLOOKUP($C24,R:R,U:U)=0,A25,_xlfn.XLOOKUP($C24,R:R,U:U)) -> #N/A | B24: =IF(_xlfn.XLOOKUP($C24,R:R,S:S)=0,B25,_xlfn.XLOOKUP($C24,R:R,S:S)) -> #N/A | C24: 46198 | D24: -17 | E24: -6 | F24: -50 | G24: -40 | H24: -10 | I24: -17 | J24: -5 | K24: 80 | L24: 22 | M24: 30 | N24: 32 | O24: 58 | R24: 45987 | S24: 379.7 | T24: 4377 | U24: =IF(T24=0,T25,T24) -> 4377 | W24: =C24 -> 46198 | X24: =IF(D24=0,NA(),($B24+D24)*22.406) -> #N/A | Y24: =IF(E24=0,NA(),($B24+E24)*22.406) -> #N/A | Z24: =IF(F24=0,NA(),($B24+F24)*22.406) -> #N/A | AA24: =IF(G24=0,NA(),($B24+G24)*22.406) -> #N/A | AB24: =IF(H24=0,NA(),($B24+H24)*22.406) -> #N/A | AC24: =IF(I24=0,NA(),($B24+I24)*22.406) -> #N/A | AD24: =IF(J24=0,NA(),($B24+J24)*22.406) -> #N/A | AE24: =IF(K24=0,NA(),($B24+K24)*22.406) -> #N/A | ... AI24: =IF(O24=0,NA(),($B24+O24)*22.406) -> #N/A
A25: =IF(_xlfn.XLOOKUP($C25,R:R,U:U)=0,A26,_xlfn.XLOOKUP($C25,R:R,U:U)) -> #N/A | B25: =IF(_xlfn.XLOOKUP($C25,R:R,S:S)=0,B26,_xlfn.XLOOKUP($C25,R:R,S:S)) -> #N/A | C25: 46191 | D25: -14 | E25: -3 | F25: -55 | G25: -45 | H25: -10 | I25: -17 | J25: -5 | K25: 80 | L25: 20 | M25: 30 | N25: 32 | O25: 58 | R25: 45986 | S25: 383.3 | T25: 4414 | U25: =IF(T25=0,T26,T25) -> 4414 | W25: =C25 -> 46191 | X25: =IF(D25=0,NA(),($B25+D25)*22.406) -> #N/A | Y25: =IF(E25=0,NA(),($B25+E25)*22.406) -> #N/A | Z25: =IF(F25=0,NA(),($B25+F25)*22.406) -> #N/A | AA25: =IF(G25=0,NA(),($B25+G25)*22.406) -> #N/A | AB25: =IF(H25=0,NA(),($B25+H25)*22.406) -> #N/A | AC25: =IF(I25=0,NA(),($B25+I25)*22.406) -> #N/A | AD25: =IF(J25=0,NA(),($B25+J25)*22.406) -> #N/A | AE25: =IF(K25=0,NA(),($B25+K25)*22.406) -> #N/A | ... AI25: =IF(O25=0,NA(),($B25+O25)*22.406) -> #N/A
A26: =IF(_xlfn.XLOOKUP($C26,R:R,U:U)=0,A27,_xlfn.XLOOKUP($C26,R:R,U:U)) -> #N/A | B26: =IF(_xlfn.XLOOKUP($C26,R:R,S:S)=0,B27,_xlfn.XLOOKUP($C26,R:R,S:S)) -> #N/A | C26: 46184 | D26: -11 | E26: 3 | F26: -55 | G26: -45 | H26: 0 | I26: -17 | J26: -5 | K26: 68 | L26: 15 | M26: 32 | N26: 30 | O26: 58 | R26: 45985 | S26: 376.55 | T26: 4453 | U26: =IF(T26=0,T27,T26) -> 4453 | W26: =C26 -> 46184 | X26: =IF(D26=0,NA(),($B26+D26)*22.406) -> #N/A | Y26: =IF(E26=0,NA(),($B26+E26)*22.406) -> #N/A | Z26: =IF(F26=0,NA(),($B26+F26)*22.406) -> #N/A | AA26: =IF(G26=0,NA(),($B26+G26)*22.406) -> #N/A | AB26: =IF(H26=0,NA(),($B26+H26)*22.406) -> #N/A | AC26: =IF(I26=0,NA(),($B26+I26)*22.406) -> #N/A | AD26: =IF(J26=0,NA(),($B26+J26)*22.406) -> #N/A | AE26: =IF(K26=0,NA(),($B26+K26)*22.406) -> #N/A | ... AI26: =IF(O26=0,NA(),($B26+O26)*22.406) -> #N/A
A27: =IF(_xlfn.XLOOKUP($C27,R:R,U:U)=0,A28,_xlfn.XLOOKUP($C27,R:R,U:U)) -> #N/A | B27: =IF(_xlfn.XLOOKUP($C27,R:R,S:S)=0,B28,_xlfn.XLOOKUP($C27,R:R,S:S)) -> #N/A | C27: 46177 | D27: -10 | E27: 12 | F27: -55 | G27: -45 | H27: 0 | I27: -17 | J27: -5 | K27: 58 | L27: 15 | M27: 32 | N27: 25 | O27: 58 | R27: 45982 | S27: 369.45 | T27: 4506 | U27: =IF(T27=0,T28,T27) -> 4506 | W27: =C27 -> 46177 | X27: =IF(D27=0,NA(),($B27+D27)*22.406) -> #N/A | Y27: =IF(E27=0,NA(),($B27+E27)*22.406) -> #N/A | Z27: =IF(F27=0,NA(),($B27+F27)*22.406) -> #N/A | AA27: =IF(G27=0,NA(),($B27+G27)*22.406) -> #N/A | AB27: =IF(H27=0,NA(),($B27+H27)*22.406) -> #N/A | AC27: =IF(I27=0,NA(),($B27+I27)*22.406) -> #N/A | AD27: =IF(J27=0,NA(),($B27+J27)*22.406) -> #N/A | AE27: =IF(K27=0,NA(),($B27+K27)*22.406) -> #N/A | ... AI27: =IF(O27=0,NA(),($B27+O27)*22.406) -> #N/A
A28: =IF(_xlfn.XLOOKUP($C28,R:R,U:U)=0,A29,_xlfn.XLOOKUP($C28,R:R,U:U)) -> #N/A | B28: =IF(_xlfn.XLOOKUP($C28,R:R,S:S)=0,B29,_xlfn.XLOOKUP($C28,R:R,S:S)) -> #N/A | C28: 46170 | D28: -10 | E28: 15 | F28: -55 | G28: -45 | H28: 0 | I28: -17 | J28: -5 | K28: 55 | L28: 15 | M28: 35 | N28: 20 | O28: 58 | R28: 45981 | S28: 376.65 | T28: 4631 | U28: =IF(T28=0,T29,T28) -> 4631 | W28: =C28 -> 46170 | X28: =IF(D28=0,NA(),($B28+D28)*22.406) -> #N/A | Y28: =IF(E28=0,NA(),($B28+E28)*22.406) -> #N/A | Z28: =IF(F28=0,NA(),($B28+F28)*22.406) -> #N/A | AA28: =IF(G28=0,NA(),($B28+G28)*22.406) -> #N/A | AB28: =IF(H28=0,NA(),($B28+H28)*22.406) -> #N/A | AC28: =IF(I28=0,NA(),($B28+I28)*22.406) -> #N/A | AD28: =IF(J28=0,NA(),($B28+J28)*22.406) -> #N/A | AE28: =IF(K28=0,NA(),($B28+K28)*22.406) -> #N/A | ... AI28: =IF(O28=0,NA(),($B28+O28)*22.406) -> #N/A
A29: =IF(_xlfn.XLOOKUP($C29,R:R,U:U)=0,A30,_xlfn.XLOOKUP($C29,R:R,U:U)) -> #N/A | B29: =IF(_xlfn.XLOOKUP($C29,R:R,S:S)=0,B30,_xlfn.XLOOKUP($C29,R:R,S:S)) -> #N/A | C29: 46163 | D29: -10 | E29: 15 | F29: -55 | G29: -45 | H29: -5 | I29: -17 | J29: -10 | K29: 43 | L29: 15 | M29: 40 | N29: 20 | O29: 50 | R29: 45980 | S29: 374.85 | T29: 4516 | U29: =IF(T29=0,T30,T29) -> 4516 | W29: =C29 -> 46163 | X29: =IF(D29=0,NA(),($B29+D29)*22.406) -> #N/A | Y29: =IF(E29=0,NA(),($B29+E29)*22.406) -> #N/A | Z29: =IF(F29=0,NA(),($B29+F29)*22.406) -> #N/A | AA29: =IF(G29=0,NA(),($B29+G29)*22.406) -> #N/A | AB29: =IF(H29=0,NA(),($B29+H29)*22.406) -> #N/A | AC29: =IF(I29=0,NA(),($B29+I29)*22.406) -> #N/A | AD29: =IF(J29=0,NA(),($B29+J29)*22.406) -> #N/A | AE29: =IF(K29=0,NA(),($B29+K29)*22.406) -> #N/A | ... AI29: =IF(O29=0,NA(),($B29+O29)*22.406) -> #N/A
A30: =IF(_xlfn.XLOOKUP($C30,R:R,U:U)=0,A31,_xlfn.XLOOKUP($C30,R:R,U:U)) -> #N/A | B30: =IF(_xlfn.XLOOKUP($C30,R:R,S:S)=0,B31,_xlfn.XLOOKUP($C30,R:R,S:S)) -> #N/A | C30: 46155 | D30: -7 | E30: 18 | F30: -50 | G30: -40 | H30: -22 | I30: -20 | J30: -14 | K30: 43 | L30: 15 | M30: 40 | N30: 20 | O30: 50 | R30: 45979 | S30: 387.7 | T30: 4573 | U30: =IF(T30=0,T31,T30) -> 4573 | W30: =C30 -> 46155 | X30: =IF(D30=0,NA(),($B30+D30)*22.406) -> #N/A | Y30: =IF(E30=0,NA(),($B30+E30)*22.406) -> #N/A | Z30: =IF(F30=0,NA(),($B30+F30)*22.406) -> #N/A | AA30: =IF(G30=0,NA(),($B30+G30)*22.406) -> #N/A | AB30: =IF(H30=0,NA(),($B30+H30)*22.406) -> #N/A | AC30: =IF(I30=0,NA(),($B30+I30)*22.406) -> #N/A | AD30: =IF(J30=0,NA(),($B30+J30)*22.406) -> #N/A | AE30: =IF(K30=0,NA(),($B30+K30)*22.406) -> #N/A | ... AI30: =IF(O30=0,NA(),($B30+O30)*22.406) -> #N/A
A31: =IF(_xlfn.XLOOKUP($C31,R:R,U:U)=0,A32,_xlfn.XLOOKUP($C31,R:R,U:U)) -> #N/A | B31: =IF(_xlfn.XLOOKUP($C31,R:R,S:S)=0,B32,_xlfn.XLOOKUP($C31,R:R,S:S)) -> #N/A | C31: 46148 | D31: -5 | E31: 18 | F31: -50 | G31: -40 | H31: -20 | I31: -20 | J31: -12 | K31: 43 | L31: 15 | M31: 40 | N31: 15 | O31: 50 | R31: 45978 | S31: 376.6 | T31: 4483 | U31: =IF(T31=0,T32,T31) -> 4483 | W31: =C31 -> 46148 | X31: =IF(D31=0,NA(),($B31+D31)*22.406) -> #N/A | Y31: =IF(E31=0,NA(),($B31+E31)*22.406) -> #N/A | Z31: =IF(F31=0,NA(),($B31+F31)*22.406) -> #N/A | AA31: =IF(G31=0,NA(),($B31+G31)*22.406) -> #N/A | AB31: =IF(H31=0,NA(),($B31+H31)*22.406) -> #N/A | AC31: =IF(I31=0,NA(),($B31+I31)*22.406) -> #N/A | AD31: =IF(J31=0,NA(),($B31+J31)*22.406) -> #N/A | AE31: =IF(K31=0,NA(),($B31+K31)*22.406) -> #N/A | ... AI31: =IF(O31=0,NA(),($B31+O31)*22.406) -> #N/A
A32: =IF(_xlfn.XLOOKUP($C32,R:R,U:U)=0,A33,_xlfn.XLOOKUP($C32,R:R,U:U)) -> #N/A | B32: =IF(_xlfn.XLOOKUP($C32,R:R,S:S)=0,B33,_xlfn.XLOOKUP($C32,R:R,S:S)) -> #N/A | C32: 46142 | D32: -2 | E32: 18 | F32: -50 | G32: -40 | H32: -18 | I32: -18 | J32: -12 | K32: 45 | L32: 15 | M32: 40 | N32: 12 | O32: 50 | R32: 45975 | S32: 374 | T32: 4223 | U32: =IF(T32=0,T33,T32) -> 4223 | W32: =C32 -> 46142 | X32: =IF(D32=0,NA(),($B32+D32)*22.406) -> #N/A | Y32: =IF(E32=0,NA(),($B32+E32)*22.406) -> #N/A | Z32: =IF(F32=0,NA(),($B32+F32)*22.406) -> #N/A | AA32: =IF(G32=0,NA(),($B32+G32)*22.406) -> #N/A | AB32: =IF(H32=0,NA(),($B32+H32)*22.406) -> #N/A | AC32: =IF(I32=0,NA(),($B32+I32)*22.406) -> #N/A | AD32: =IF(J32=0,NA(),($B32+J32)*22.406) -> #N/A | AE32: =IF(K32=0,NA(),($B32+K32)*22.406) -> #N/A | ... AI32: =IF(O32=0,NA(),($B32+O32)*22.406) -> #N/A
A33: =IF(_xlfn.XLOOKUP($C33,R:R,U:U)=0,A34,_xlfn.XLOOKUP($C33,R:R,U:U)) -> #N/A | B33: =IF(_xlfn.XLOOKUP($C33,R:R,S:S)=0,B34,_xlfn.XLOOKUP($C33,R:R,S:S)) -> #N/A | C33: 46135 | D33: -2 | E33: 20 | F33: -50 | G33: -40 | H33: -18 | I33: -20 | J33: -10 | K33: 45 | L33: 15 | M33: 40 | N33: 10 | O33: 50 | R33: 45974 | S33: 374.25 | T33: 4343 | U33: =IF(T33=0,T34,T33) -> 4343 | W33: =C33 -> 46135 | X33: =IF(D33=0,NA(),($B33+D33)*22.406) -> #N/A | Y33: =IF(E33=0,NA(),($B33+E33)*22.406) -> #N/A | Z33: =IF(F33=0,NA(),($B33+F33)*22.406) -> #N/A | AA33: =IF(G33=0,NA(),($B33+G33)*22.406) -> #N/A | AB33: =IF(H33=0,NA(),($B33+H33)*22.406) -> #N/A | AC33: =IF(I33=0,NA(),($B33+I33)*22.406) -> #N/A | AD33: =IF(J33=0,NA(),($B33+J33)*22.406) -> #N/A | AE33: =IF(K33=0,NA(),($B33+K33)*22.406) -> #N/A | ... AI33: =IF(O33=0,NA(),($B33+O33)*22.406) -> #N/A
A34: =IF(_xlfn.XLOOKUP($C34,R:R,U:U)=0,A35,_xlfn.XLOOKUP($C34,R:R,U:U)) -> #N/A | B34: =IF(_xlfn.XLOOKUP($C34,R:R,S:S)=0,B35,_xlfn.XLOOKUP($C34,R:R,S:S)) -> #N/A | C34: 46127 | D34: -2 | E34: 22 | F34: -50 | G34: -40 | H34: -15 | I34: -20 | J34: -10 | K34: 41 | L34: 10 | M34: 40 | N34: 10 | O34: 50 | R34: 45973 | S34: 376.65 | T34: 4366 | U34: =IF(T34=0,T35,T34) -> 4366 | W34: =C34 -> 46127 | X34: =IF(D34=0,NA(),($B34+D34)*22.406) -> #N/A | Y34: =IF(E34=0,NA(),($B34+E34)*22.406) -> #N/A | Z34: =IF(F34=0,NA(),($B34+F34)*22.406) -> #N/A | AA34: =IF(G34=0,NA(),($B34+G34)*22.406) -> #N/A | AB34: =IF(H34=0,NA(),($B34+H34)*22.406) -> #N/A | AC34: =IF(I34=0,NA(),($B34+I34)*22.406) -> #N/A | AD34: =IF(J34=0,NA(),($B34+J34)*22.406) -> #N/A | AE34: =IF(K34=0,NA(),($B34+K34)*22.406) -> #N/A | ... AI34: =IF(O34=0,NA(),($B34+O34)*22.406) -> #N/A
A35: =IF(_xlfn.XLOOKUP($C35,R:R,U:U)=0,A36,_xlfn.XLOOKUP($C35,R:R,U:U)) -> #N/A | B35: =IF(_xlfn.XLOOKUP($C35,R:R,S:S)=0,B36,_xlfn.XLOOKUP($C35,R:R,S:S)) -> #N/A | C35: 46121 | D35: -2 | E35: 22 | F35: -50 | G35: -40 | H35: -20 | I35: -20 | J35: -10 | K35: 41 | L35: 10 | M35: 45 | N35: 10 | O35: 50 | R35: 45972 | S35: 399.3 | T35: 4618 | U35: =IF(T35=0,T36,T35) -> 4618 | W35: =C35 -> 46121 | X35: =IF(D35=0,NA(),($B35+D35)*22.406) -> #N/A | Y35: =IF(E35=0,NA(),($B35+E35)*22.406) -> #N/A | Z35: =IF(F35=0,NA(),($B35+F35)*22.406) -> #N/A | AA35: =IF(G35=0,NA(),($B35+G35)*22.406) -> #N/A | AB35: =IF(H35=0,NA(),($B35+H35)*22.406) -> #N/A | AC35: =IF(I35=0,NA(),($B35+I35)*22.406) -> #N/A | AD35: =IF(J35=0,NA(),($B35+J35)*22.406) -> #N/A | AE35: =IF(K35=0,NA(),($B35+K35)*22.406) -> #N/A | ... AI35: =IF(O35=0,NA(),($B35+O35)*22.406) -> #N/A
... A85: =IF(_xlfn.XLOOKUP($C85,R:R,U:U)=0,A86,_xlfn.XLOOKUP($C85,R:R,U:U)) -> 5427 | B85: =IF(_xlfn.XLOOKUP($C85,R:R,S:S)=0,B86,_xlfn.XLOOKUP($C85,R:R,S:S)) -> 398.8 | C85: 45771 | D85: -12 | E85: 12 | F85: -45 | G85: -37 | H85: -60 | I85: -40 | J85: -20 | K85: 8 | L85: 5 | M85: 32 | N85: 18 | O85: 25 | R85: 45902 | S85: 370.35 | T85: 4399 | U85: =IF(T85=0,T86,T85) -> 4399 | W85: =C85 -> 45771 | X85: =IF(D85=0,NA(),($B85+D85)*22.406) -> 8666.6408 | Y85: =IF(E85=0,NA(),($B85+E85)*22.406) -> 9204.3848 | Z85: =IF(F85=0,NA(),($B85+F85)*22.406) -> 7927.2428 | AA85: =IF(G85=0,NA(),($B85+G85)*22.406) -> 8106.4908 | AB85: =IF(H85=0,NA(),($B85+H85)*22.406) -> 7591.1528 | AC85: =IF(I85=0,NA(),($B85+I85)*22.406) -> 8039.2728 | AD85: =IF(J85=0,NA(),($B85+J85)*22.406) -> 8487.3928 | AE85: =IF(K85=0,NA(),($B85+K85)*22.406) -> 9114.7608 | ... AI85: =IF(O85=0,NA(),($B85+O85)*22.406) -> 9495.6628
A86: =IF(_xlfn.XLOOKUP($C86,R:R,U:U)=0,A87,_xlfn.XLOOKUP($C86,R:R,U:U)) -> 5277 | B86: =IF(_xlfn.XLOOKUP($C86,R:R,S:S)=0,B87,_xlfn.XLOOKUP($C86,R:R,S:S)) -> 372.6 | C86: 45764 | D86: -10 | E86: 12 | F86: -45 | G86: -37 | H86: -60 | I86: -30 | J86: -20 | K86: 6 | L86: 3 | M86: 32 | N86: 18 | O86: 25 | R86: 45901 | T86: 4628 | U86: =IF(T86=0,T87,T86) -> 4628 | W86: =C86 -> 45764 | X86: =IF(D86=0,NA(),($B86+D86)*22.406) -> 8124.4156 | Y86: =IF(E86=0,NA(),($B86+E86)*22.406) -> 8617.3476 | Z86: =IF(F86=0,NA(),($B86+F86)*22.406) -> 7340.2056 | AA86: =IF(G86=0,NA(),($B86+G86)*22.406) -> 7519.4536 | AB86: =IF(H86=0,NA(),($B86+H86)*22.406) -> 7004.1156 | AC86: =IF(I86=0,NA(),($B86+I86)*22.406) -> 7676.2956 | AD86: =IF(J86=0,NA(),($B86+J86)*22.406) -> 7900.3556 | AE86: =IF(K86=0,NA(),($B86+K86)*22.406) -> 8482.9116 | ... AI86: =IF(O86=0,NA(),($B86+O86)*22.406) -> 8908.6256
A87: =IF(_xlfn.XLOOKUP($C87,R:R,U:U)=0,A88,_xlfn.XLOOKUP($C87,R:R,U:U)) -> 4896 | B87: =IF(_xlfn.XLOOKUP($C87,R:R,S:S)=0,B88,_xlfn.XLOOKUP($C87,R:R,S:S)) -> 341.6 | C87: 45757 | D87: -10 | E87: 12 | F87: -45 | G87: -37 | H87: -62 | I87: -20 | J87: -20 | K87: 6 | L87: 3 | M87: 32 | N87: 18 | O87: 25 | R87: 45898 | S87: 386.1 | T87: 4815 | U87: =IF(T87=0,T88,T87) -> 4815 | W87: =C87 -> 45757 | X87: =IF(D87=0,NA(),($B87+D87)*22.406) -> 7429.8296 | Y87: =IF(E87=0,NA(),($B87+E87)*22.406) -> 7922.7616 | Z87: =IF(F87=0,NA(),($B87+F87)*22.406) -> 6645.6196 | AA87: =IF(G87=0,NA(),($B87+G87)*22.406) -> 6824.8676 | AB87: =IF(H87=0,NA(),($B87+H87)*22.406) -> 6264.7176 | AC87: =IF(I87=0,NA(),($B87+I87)*22.406) -> 7205.7696 | AD87: =IF(J87=0,NA(),($B87+J87)*22.406) -> 7205.7696 | AE87: =IF(K87=0,NA(),($B87+K87)*22.406) -> 7788.3256 | ... AI87: =IF(O87=0,NA(),($B87+O87)*22.406) -> 8214.0396
A88: =IF(_xlfn.XLOOKUP($C88,R:R,U:U)=0,A89,_xlfn.XLOOKUP($C88,R:R,U:U)) -> 5388 | B88: =IF(_xlfn.XLOOKUP($C88,R:R,S:S)=0,B89,_xlfn.XLOOKUP($C88,R:R,S:S)) -> 381.75 | C88: 45750 | D88: -8 | E88: 12 | F88: -45 | G88: -37 | H88: -68 | I88: -20 | J88: -22 | K88: 6 | L88: 1 | M88: 32 | N88: 18 | O88: 20 | R88: 45897 | S88: 377.5 | T88: 4808 | U88: =IF(T88=0,T89,T88) -> 4808 | W88: =C88 -> 45750 | X88: =IF(D88=0,NA(),($B88+D88)*22.406) -> 8374.2425 | Y88: =IF(E88=0,NA(),($B88+E88)*22.406) -> 8822.3625 | Z88: =IF(F88=0,NA(),($B88+F88)*22.406) -> 7545.2205 | AA88: =IF(G88=0,NA(),($B88+G88)*22.406) -> 7724.4685 | AB88: =IF(H88=0,NA(),($B88+H88)*22.406) -> 7029.8825 | AC88: =IF(I88=0,NA(),($B88+I88)*22.406) -> 8105.3705 | AD88: =IF(J88=0,NA(),($B88+J88)*22.406) -> 8060.5585 | AE88: =IF(K88=0,NA(),($B88+K88)*22.406) -> 8687.9265 | ... AI88: =IF(O88=0,NA(),($B88+O88)*22.406) -> 9001.6105
A89: =IF(_xlfn.XLOOKUP($C89,R:R,U:U)=0,A90,_xlfn.XLOOKUP($C89,R:R,U:U)) -> 5361 | B89: =IF(_xlfn.XLOOKUP($C89,R:R,S:S)=0,B90,_xlfn.XLOOKUP($C89,R:R,S:S)) -> 374.95 | C89: 45743 | D89: -8 | E89: 12 | F89: -45 | G89: -37 | H89: -65 | I89: -20 | J89: -22 | K89: 6 | L89: 3 | M89: 32 | N89: 18 | O89: 14 | R89: 45896 | S89: 385.3 | T89: 4878 | U89: =IF(T89=0,T90,T89) -> 4878 | W89: =C89 -> 45743 | X89: =IF(D89=0,NA(),($B89+D89)*22.406) -> 8221.8817 | Y89: =IF(E89=0,NA(),($B89+E89)*22.406) -> 8670.0017 | Z89: =IF(F89=0,NA(),($B89+F89)*22.406) -> 7392.8597 | AA89: =IF(G89=0,NA(),($B89+G89)*22.406) -> 7572.1077 | AB89: =IF(H89=0,NA(),($B89+H89)*22.406) -> 6944.7397 | AC89: =IF(I89=0,NA(),($B89+I89)*22.406) -> 7953.0097 | AD89: =IF(J89=0,NA(),($B89+J89)*22.406) -> 7908.1977 | AE89: =IF(K89=0,NA(),($B89+K89)*22.406) -> 8535.5657 | ... AI89: =IF(O89=0,NA(),($B89+O89)*22.406) -> 8714.8137
A90: =IF(_xlfn.XLOOKUP($C90,R:R,U:U)=0,A91,_xlfn.XLOOKUP($C90,R:R,U:U)) -> 5497 | B90: =IF(_xlfn.XLOOKUP($C90,R:R,S:S)=0,B91,_xlfn.XLOOKUP($C90,R:R,S:S)) -> 385.35 | C90: 45736 | D90: -8 | E90: 15 | F90: -45 | G90: -37 | H90: -75 | I90: -18 | J90: -22 | K90: 6 | L90: 4 | M90: 35 | N90: 20 | O90: 15 | R90: 45895 | S90: 372.3 | T90: 4690 | U90: =IF(T90=0,T91,T90) -> 4690 | W90: =C90 -> 45736 | X90: =IF(D90=0,NA(),($B90+D90)*22.406) -> 8454.9041 | Y90: =IF(E90=0,NA(),($B90+E90)*22.406) -> 8970.2421 | Z90: =IF(F90=0,NA(),($B90+F90)*22.406) -> 7625.8821 | AA90: =IF(G90=0,NA(),($B90+G90)*22.406) -> 7805.1301 | AB90: =IF(H90=0,NA(),($B90+H90)*22.406) -> 6953.7021 | AC90: =IF(I90=0,NA(),($B90+I90)*22.406) -> 8230.8441 | AD90: =IF(J90=0,NA(),($B90+J90)*22.406) -> 8141.2201 | AE90: =IF(K90=0,NA(),($B90+K90)*22.406) -> 8768.5881 | ... AI90: =IF(O90=0,NA(),($B90+O90)*22.406) -> 8970.2421
A91: =IF(_xlfn.XLOOKUP($C91,R:R,U:U)=0,A92,_xlfn.XLOOKUP($C91,R:R,U:U)) -> 5528 | B91: =IF(_xlfn.XLOOKUP($C91,R:R,S:S)=0,B92,_xlfn.XLOOKUP($C91,R:R,S:S)) -> 385.7 | C91: 45729 | D91: -5 | E91: 17 | F91: -47 | G91: -39 | H91: -80 | I91: -20 | J91: -24 | K91: 7 | L91: 6 | M91: 35 | N91: 25 | O91: 16 | R91: 45894 | S91: 377.75 | U91: =IF(T91=0,T92,T91) -> 4650 | W91: =C91 -> 45729 | X91: =IF(D91=0,NA(),($B91+D91)*22.406) -> 8529.9642 | Y91: =IF(E91=0,NA(),($B91+E91)*22.406) -> 9022.8962 | Z91: =IF(F91=0,NA(),($B91+F91)*22.406) -> 7588.9122 | AA91: =IF(G91=0,NA(),($B91+G91)*22.406) -> 7768.1602 | AB91: =IF(H91=0,NA(),($B91+H91)*22.406) -> 6849.5142 | AC91: =IF(I91=0,NA(),($B91+I91)*22.406) -> 8193.8742 | AD91: =IF(J91=0,NA(),($B91+J91)*22.406) -> 8104.2502 | AE91: =IF(K91=0,NA(),($B91+K91)*22.406) -> 8798.8362 | ... AI91: =IF(O91=0,NA(),($B91+O91)*22.406) -> 9000.4902
...

Sheet timestamp
A1: =NOW() -> 46322.587

Sheet Robusta Dbse
A1: =_xll.RHistory($C$3:$K$3,"TRDPRC_1.Timestamp;TRDPRC_1.Close","START:01-Aug-2013 INTERVAL:1D",,"TSREPEAT:NO CH:Fd",B5) -> Updated at 14:05:36
C3: COF-RBST-VN1DF | D3: COF-RBST-VNDIF | E3: COF-RBST-VN2DF | F3: COF-RBST-VN8DF | G3: COF-RBST-IDDIF | H3: COF-RBST-UG2DF | I3: COF-RBST-UG1DF | J3: COF-RBST-INDIF | K3: COF-RBST-CI1DF
C4: Vietnam Grd 1 | D4: Vietnam Grd 2 | E4: Vietnam Grd 2: 5% Black | F4: Vietnam Grd 2: 8% Blck | G4: Indonesia | H4: Uganda Screen 12 | I4: Uganda Screen 15 | J4: India Cherry AB | K4: Ivy Cst Grd 1 | M4: 1 | N4: 2 | O4: 3 | P4: 4 | Q4: 5 | R4: 6 | S4: 7 | T4: 8 | U4: 9 | V4: 10 | W4: 11 | X4: 12 | Y4: 13 | Z4: 14 | AA4: 15 | AB4: 16 | AC4: 17 | AD4: 18 | AE4: 19 | AF4: 20 | AG4: 21
A5: LRC | B5: Timestamp | C5: Trade Close | D5: Trade Close | E5: Trade Close | F5: Trade Close | G5: Trade Close | H5: Trade Close | I5: Trade Close | J5: Trade Close | K5: Trade Close | L5: Date | M5: Vietnam Grd 1 | N5: Vietnam Grd 2 | O5: Vietnam Grd 2: 5% Black | P5: Vietnam Grd 2: 8% Blck | Q5: Indonesia | R5: Uganda Screen 12 | S5: Uganda Screen 15 | T5: India Cherry AB | U5: Ivy Cst Grd 1 | V5: =_xlfn.CONCAT('Arabica Dbse'!X6," (A)") -> Brazil NY 3/4 MGTB (A) | W5: =_xlfn.CONCAT('Arabica Dbse'!Y6," (A)") -> Brazil Santos (A) | X5: =_xlfn.CONCAT('Arabica Dbse'!Z6," (A)") -> Brazil Rio Minas 15/16 (A) | Y5: =_xlfn.CONCAT('Arabica Dbse'!AA6," (A)") -> Brazil Rio Minas 17/18 (A) | Z5: =_xlfn.CONCAT('Arabica Dbse'!AB6," (A)") -> Ethiopia Djimmah 5 (A) | AA5: =_xlfn.CONCAT('Arabica Dbse'!AC6," (A)") -> Uganda Drugar (A) | AB5: =_xlfn.CONCAT('Arabica Dbse'!AD6," (A)") -> India Cherry AB (A) | AC5: =_xlfn.CONCAT('Arabica Dbse'!AE6," (A)") -> Colombia Excelso (A) | ... AG5: =_xlfn.CONCAT('Arabica Dbse'!AI6," (A)") -> Guatemala SHB (A)
A6: =_xlfn.XLOOKUP(B6,'Arabica Dbse'!R:R,'Arabica Dbse'!U:U) -> #N/A | B6: 46317 | C6: 450 | D6: 170 | E6: 170 | F6: 140 | G6: 220 | H6: 470 | I6: 570 | J6: 730 | K6: 240 | L6: =B6 -> 46317 | M6: =IF(C6=0,NA(),$A6+C6) -> #N/A | N6: =IF(D6=0,NA(),$A6+D6) -> #N/A | O6: =IF(E6=0,NA(),$A6+E6) -> #N/A | P6: =IF(F6=0,NA(),$A6+F6) -> #N/A | Q6: =IF(G6=0,NA(),$A6+G6) -> #N/A | R6: =IF(H6=0,NA(),$A6+H6) -> #N/A | S6: =IF(I6=0,NA(),$A6+I6) -> #N/A | T6: =IF(J6=0,NA(),$A6+J6) -> #N/A | U6: =IF(K6=0,NA(),$A6+K6) -> #N/A | V6: =_xlfn.XLOOKUP($L6,'Arabica Dbse'!$W:$W,'Arabica Dbse'!X:X,NA()) -> #N/A | W6: =_xlfn.XLOOKUP($L6,'Arabica Dbse'!$W:$W,'Arabica Dbse'!Y:Y,NA()) -> #N/A | X6: =_xlfn.XLOOKUP($L6,'Arabica Dbse'!$W:$W,'Arabica Dbse'!Z:Z,NA()) -> #N/A | Y6: =_xlfn.XLOOKUP($L6,'Arabica Dbse'!$W:$W,'Arabica Dbse'!AA:AA,NA()) -> #N/A | Z6: =_xlfn.XLOOKUP($L6,'Arabica Dbse'!$W:$W,'Arabica Dbse'!AB:AB,NA()) -> #N/A | AA6: =_xlfn.XLOOKUP($L6,'Arabica Dbse'!$W:$W,'Arabica Dbse'!AC:AC,NA()) -> #N/A | AB6: =_xlfn.XLOOKUP($L6,'Arabica Dbse'!$W:$W,'Arabica Dbse'!AD:AD,NA()) -> #N/A | AC6: =_xlfn.XLOOKUP($L6,'Arabica Dbse'!$W:$W,'Arabica Dbse'!AE:AE,NA()) -> #N/A | AD6: =_xlfn.XLOOKUP($L6,'Arabica Dbse'!$W:$W,'Arabica Dbse'!AF:AF,NA()) -> #N/A | AE6: =_xlfn.XLOOKUP($L6,'Arabica Dbse'!$W:$W,'Arabica Dbse'!AG:AG,NA()) -> #N/A | AF6: =_xlfn.XLOOKUP($L6,'Arabica Dbse'!$W:$W,'Arabica Dbse'!AH:AH,NA()) -> #N/A | AG6: =_xlfn.XLOOKUP($L6,'Arabica Dbse'!$W:$W,'Arabica Dbse'!AI:AI,NA()) -> #N/A
A7: =_xlfn.XLOOKUP(B7,'Arabica Dbse'!R:R,'Arabica Dbse'!U:U) -> #N/A | B7: 46310 | C7: 450 | D7: 200 | E7: 200 | F7: 170 | G7: 250 | H7: 480 | I7: 580 | J7: 750 | K7: 240 | L7: =B7 -> 46310 | M7: =IF(C7=0,NA(),$A7+C7) -> #N/A | N7: =IF(D7=0,NA(),$A7+D7) -> #N/A | O7: =IF(E7=0,NA(),$A7+E7) -> #N/A | P7: =IF(F7=0,NA(),$A7+F7) -> #N/A | Q7: =IF(G7=0,NA(),$A7+G7) -> #N/A | R7: =IF(H7=0,NA(),$A7+H7) -> #N/A | S7: =IF(I7=0,NA(),$A7+I7) -> #N/A | T7: =IF(J7=0,NA(),$A7+J7) -> #N/A | U7: =IF(K7=0,NA(),$A7+K7) -> #N/A | V7: =_xlfn.XLOOKUP($L7,'Arabica Dbse'!$W:$W,'Arabica Dbse'!X:X,NA()) -> #N/A | W7: =_xlfn.XLOOKUP($L7,'Arabica Dbse'!$W:$W,'Arabica Dbse'!Y:Y,NA()) -> #N/A | X7: =_xlfn.XLOOKUP($L7,'Arabica Dbse'!$W:$W,'Arabica Dbse'!Z:Z,NA()) -> #N/A | Y7: =_xlfn.XLOOKUP($L7,'Arabica Dbse'!$W:$W,'Arabica Dbse'!AA:AA,NA()) -> #N/A | Z7: =_xlfn.XLOOKUP($L7,'Arabica Dbse'!$W:$W,'Arabica Dbse'!AB:AB,NA()) -> #N/A | AA7: =_xlfn.XLOOKUP($L7,'Arabica Dbse'!$W:$W,'Arabica Dbse'!AC:AC,NA()) -> #N/A | AB7: =_xlfn.XLOOKUP($L7,'Arabica Dbse'!$W:$W,'Arabica Dbse'!AD:AD,NA()) -> #N/A | AC7: =_xlfn.XLOOKUP($L7,'Arabica Dbse'!$W:$W,'Arabica Dbse'!AE:AE,NA()) -> #N/A | AD7: =_xlfn.XLOOKUP($L7,'Arabica Dbse'!$W:$W,'Arabica Dbse'!AF:AF,NA()) -> #N/A | AE7: =_xlfn.XLOOKUP($L7,'Arabica Dbse'!$W:$W,'Arabica Dbse'!AG:AG,NA()) -> #N/A | AF7: =_xlfn.XLOOKUP($L7,'Arabica Dbse'!$W:$W,'Arabica Dbse'!AH:AH,NA()) -> #N/A | AG7: =_xlfn.XLOOKUP($L7,'Arabica Dbse'!$W:$W,'Arabica Dbse'!AI:AI,NA()) -> #N/A
A8: =_xlfn.XLOOKUP(B8,'Arabica Dbse'!R:R,'Arabica Dbse'!U:U) -> #N/A | B8: 46303 | C8: 430 | D8: 220 | E8: 220 | F8: 200 | G8: 270 | H8: 450 | I8: 550 | J8: 700 | K8: 240 | L8: =B8 -> 46303 | M8: =IF(C8=0,NA(),$A8+C8) -> #N/A | N8: =IF(D8=0,NA(),$A8+D8) -> #N/A | O8: =IF(E8=0,NA(),$A8+E8) -> #N/A | P8: =IF(F8=0,NA(),$A8+F8) -> #N/A | Q8: =IF(G8=0,NA(),$A8+G8) -> #N/A | R8: =IF(H8=0,NA(),$A8+H8) -> #N/A | S8: =IF(I8=0,NA(),$A8+I8) -> #N/A | T8: =IF(J8=0,NA(),$A8+J8) -> #N/A | U8: =IF(K8=0,NA(),$A8+K8) -> #N/A | V8: =_xlfn.XLOOKUP($L8,'Arabica Dbse'!$W:$W,'Arabica Dbse'!X:X,NA()) -> #N/A | W8: =_xlfn.XLOOKUP($L8,'Arabica Dbse'!$W:$W,'Arabica Dbse'!Y:Y,NA()) -> #N/A | X8: =_xlfn.XLOOKUP($L8,'Arabica Dbse'!$W:$W,'Arabica Dbse'!Z:Z,NA()) -> #N/A | Y8: =_xlfn.XLOOKUP($L8,'Arabica Dbse'!$W:$W,'Arabica Dbse'!AA:AA,NA()) -> #N/A | Z8: =_xlfn.XLOOKUP($L8,'Arabica Dbse'!$W:$W,'Arabica Dbse'!AB:AB,NA()) -> #N/A | AA8: =_xlfn.XLOOKUP($L8,'Arabica Dbse'!$W:$W,'Arabica Dbse'!AC:AC,NA()) -> #N/A | AB8: =_xlfn.XLOOKUP($L8,'Arabica Dbse'!$W:$W,'Arabica Dbse'!AD:AD,NA()) -> #N/A | AC8: =_xlfn.XLOOKUP($L8,'Arabica Dbse'!$W:$W,'Arabica Dbse'!AE:AE,NA()) -> #N/A | AD8: =_xlfn.XLOOKUP($L8,'Arabica Dbse'!$W:$W,'Arabica Dbse'!AF:AF,NA()) -> #N/A | AE8: =_xlfn.XLOOKUP($L8,'Arabica Dbse'!$W:$W,'Arabica Dbse'!AG:AG,NA()) -> #N/A | AF8: =_xlfn.XLOOKUP($L8,'Arabica Dbse'!$W:$W,'Arabica Dbse'!AH:AH,NA()) -> #N/A | AG8: =_xlfn.XLOOKUP($L8,'Arabica Dbse'!$W:$W,'Arabica Dbse'!AI:AI,NA()) -> #N/A
A9: =_xlfn.XLOOKUP(B9,'Arabica Dbse'!R:R,'Arabica Dbse'!U:U) -> #N/A | B9: 46296 | C9: 430 | D9: 240 | E9: 240 | F9: 220 | G9: 280 | H9: 420 | I9: 530 | J9: 700 | K9: 240 | L9: =B9 -> 46296 | M9: =IF(C9=0,NA(),$A9+C9) -> #N/A | N9: =IF(D9=0,NA(),$A9+D9) -> #N/A | O9: =IF(E9=0,NA(),$A9+E9) -> #N/A | P9: =IF(F9=0,NA(),$A9+F9) -> #N/A | Q9: =IF(G9=0,NA(),$A9+G9) -> #N/A | R9: =IF(H9=0,NA(),$A9+H9) -> #N/A | S9: =IF(I9=0,NA(),$A9+I9) -> #N/A | T9: =IF(J9=0,NA(),$A9+J9) -> #N/A | U9: =IF(K9=0,NA(),$A9+K9) -> #N/A | V9: =_xlfn.XLOOKUP($L9,'Arabica Dbse'!$W:$W,'Arabica Dbse'!X:X,NA()) -> #N/A | W9: =_xlfn.XLOOKUP($L9,'Arabica Dbse'!$W:$W,'Arabica Dbse'!Y:Y,NA()) -> #N/A | X9: =_xlfn.XLOOKUP($L9,'Arabica Dbse'!$W:$W,'Arabica Dbse'!Z:Z,NA()) -> #N/A | Y9: =_xlfn.XLOOKUP($L9,'Arabica Dbse'!$W:$W,'Arabica Dbse'!AA:AA,NA()) -> #N/A | Z9: =_xlfn.XLOOKUP($L9,'Arabica Dbse'!$W:$W,'Arabica Dbse'!AB:AB,NA()) -> #N/A | AA9: =_xlfn.XLOOKUP($L9,'Arabica Dbse'!$W:$W,'Arabica Dbse'!AC:AC,NA()) -> #N/A | AB9: =_xlfn.XLOOKUP($L9,'Arabica Dbse'!$W:$W,'Arabica Dbse'!AD:AD,NA()) -> #N/A | AC9: =_xlfn.XLOOKUP($L9,'Arabica Dbse'!$W:$W,'Arabica Dbse'!AE:AE,NA()) -> #N/A | AD9: =_xlfn.XLOOKUP($L9,'Arabica Dbse'!$W:$W,'Arabica Dbse'!AF:AF,NA()) -> #N/A | AE9: =_xlfn.XLOOKUP($L9,'Arabica Dbse'!$W:$W,'Arabica Dbse'!AG:AG,NA()) -> #N/A | AF9: =_xlfn.XLOOKUP($L9,'Arabica Dbse'!$W:$W,'Arabica Dbse'!AH:AH,NA()) -> #N/A | AG9: =_xlfn.XLOOKUP($L9,'Arabica Dbse'!$W:$W,'Arabica Dbse'!AI:AI,NA()) -> #N/A
A10: =_xlfn.XLOOKUP(B10,'Arabica Dbse'!R:R,'Arabica Dbse'!U:U) -> #N/A | B10: 46289 | C10: 450 | D10: 240 | E10: 240 | F10: 220 | G10: 280 | H10: 420 | I10: 550 | J10: 750 | K10: 240 | L10: =B10 -> 46289 | M10: =IF(C10=0,NA(),$A10+C10) -> #N/A | N10: =IF(D10=0,NA(),$A10+D10) -> #N/A | O10: =IF(E10=0,NA(),$A10+E10) -> #N/A | P10: =IF(F10=0,NA(),$A10+F10) -> #N/A | Q10: =IF(G10=0,NA(),$A10+G10) -> #N/A | R10: =IF(H10=0,NA(),$A10+H10) -> #N/A | S10: =IF(I10=0,NA(),$A10+I10) -> #N/A | T10: =IF(J10=0,NA(),$A10+J10) -> #N/A | U10: =IF(K10=0,NA(),$A10+K10) -> #N/A | V10: =_xlfn.XLOOKUP($L10,'Arabica Dbse'!$W:$W,'Arabica Dbse'!X:X,NA()) -> #N/A | W10: =_xlfn.XLOOKUP($L10,'Arabica Dbse'!$W:$W,'Arabica Dbse'!Y:Y,NA()) -> #N/A | X10: =_xlfn.XLOOKUP($L10,'Arabica Dbse'!$W:$W,'Arabica Dbse'!Z:Z,NA()) -> #N/A | Y10: =_xlfn.XLOOKUP($L10,'Arabica Dbse'!$W:$W,'Arabica Dbse'!AA:AA,NA()) -> #N/A | Z10: =_xlfn.XLOOKUP($L10,'Arabica Dbse'!$W:$W,'Arabica Dbse'!AB:AB,NA()) -> #N/A | AA10: =_xlfn.XLOOKUP($L10,'Arabica Dbse'!$W:$W,'Arabica Dbse'!AC:AC,NA()) -> #N/A | AB10: =_xlfn.XLOOKUP($L10,'Arabica Dbse'!$W:$W,'Arabica Dbse'!AD:AD,NA()) -> #N/A | AC10: =_xlfn.XLOOKUP($L10,'Arabica Dbse'!$W:$W,'Arabica Dbse'!AE:AE,NA()) -> #N/A | AD10: =_xlfn.XLOOKUP($L10,'Arabica Dbse'!$W:$W,'Arabica Dbse'!AF:AF,NA()) -> #N/A | AE10: =_xlfn.XLOOKUP($L10,'Arabica Dbse'!$W:$W,'Arabica Dbse'!AG:AG,NA()) -> #N/A | AF10: =_xlfn.XLOOKUP($L10,'Arabica Dbse'!$W:$W,'Arabica Dbse'!AH:AH,NA()) -> #N/A | AG10: =_xlfn.XLOOKUP($L10,'Arabica Dbse'!$W:$W,'Arabica Dbse'!AI:AI,NA()) -> #N/A
A11: =_xlfn.XLOOKUP(B11,'Arabica Dbse'!R:R,'Arabica Dbse'!U:U) -> #N/A | B11: 46282 | C11: 390 | D11: 220 | E11: 220 | F11: 200 | G11: 230 | H11: 420 | I11: 550 | J11: 580 | K11: 240 | L11: =B11 -> 46282 | M11: =IF(C11=0,NA(),$A11+C11) -> #N/A | N11: =IF(D11=0,NA(),$A11+D11) -> #N/A | O11: =IF(E11=0,NA(),$A11+E11) -> #N/A | P11: =IF(F11=0,NA(),$A11+F11) -> #N/A | Q11: =IF(G11=0,NA(),$A11+G11) -> #N/A | R11: =IF(H11=0,NA(),$A11+H11) -> #N/A | S11: =IF(I11=0,NA(),$A11+I11) -> #N/A | T11: =IF(J11=0,NA(),$A11+J11) -> #N/A | U11: =IF(K11=0,NA(),$A11+K11) -> #N/A | V11: =_xlfn.XLOOKUP($L11,'Arabica Dbse'!$W:$W,'Arabica Dbse'!X:X,NA()) -> #N/A | W11: =_xlfn.XLOOKUP($L11,'Arabica Dbse'!$W:$W,'Arabica Dbse'!Y:Y,NA()) -> #N/A | X11: =_xlfn.XLOOKUP($L11,'Arabica Dbse'!$W:$W,'Arabica Dbse'!Z:Z,NA()) -> #N/A | Y11: =_xlfn.XLOOKUP($L11,'Arabica Dbse'!$W:$W,'Arabica Dbse'!AA:AA,NA()) -> #N/A | Z11: =_xlfn.XLOOKUP($L11,'Arabica Dbse'!$W:$W,'Arabica Dbse'!AB:AB,NA()) -> #N/A | AA11: =_xlfn.XLOOKUP($L11,'Arabica Dbse'!$W:$W,'Arabica Dbse'!AC:AC,NA()) -> #N/A | AB11: =_xlfn.XLOOKUP($L11,'Arabica Dbse'!$W:$W,'Arabica Dbse'!AD:AD,NA()) -> #N/A | AC11: =_xlfn.XLOOKUP($L11,'Arabica Dbse'!$W:$W,'Arabica Dbse'!AE:AE,NA()) -> #N/A | AD11: =_xlfn.XLOOKUP($L11,'Arabica Dbse'!$W:$W,'Arabica Dbse'!AF:AF,NA()) -> #N/A | AE11: =_xlfn.XLOOKUP($L11,'Arabica Dbse'!$W:$W,'Arabica Dbse'!AG:AG,NA()) -> #N/A | AF11: =_xlfn.XLOOKUP($L11,'Arabica Dbse'!$W:$W,'Arabica Dbse'!AH:AH,NA()) -> #N/A | AG11: =_xlfn.XLOOKUP($L11,'Arabica Dbse'!$W:$W,'Arabica Dbse'!AI:AI,NA()) -> #N/A
A12: =_xlfn.XLOOKUP(B12,'Arabica Dbse'!R:R,'Arabica Dbse'!U:U) -> #N/A | B12: 46275 | C12: 370 | D12: 200 | E12: 200 | F12: 180 | G12: 200 | H12: 400 | I12: 520 | J12: 580 | K12: 220 | L12: =B12 -> 46275 | M12: =IF(C12=0,NA(),$A12+C12) -> #N/A | N12: =IF(D12=0,NA(),$A12+D12) -> #N/A | O12: =IF(E12=0,NA(),$A12+E12) -> #N/A | P12: =IF(F12=0,NA(),$A12+F12) -> #N/A | Q12: =IF(G12=0,NA(),$A12+G12) -> #N/A | R12: =IF(H12=0,NA(),$A12+H12) -> #N/A | S12: =IF(I12=0,NA(),$A12+I12) -> #N/A | T12: =IF(J12=0,NA(),$A12+J12) -> #N/A | U12: =IF(K12=0,NA(),$A12+K12) -> #N/A | V12: =_xlfn.XLOOKUP($L12,'Arabica Dbse'!$W:$W,'Arabica Dbse'!X:X,NA()) -> #N/A | W12: =_xlfn.XLOOKUP($L12,'Arabica Dbse'!$W:$W,'Arabica Dbse'!Y:Y,NA()) -> #N/A | X12: =_xlfn.XLOOKUP($L12,'Arabica Dbse'!$W:$W,'Arabica Dbse'!Z:Z,NA()) -> #N/A | Y12: =_xlfn.XLOOKUP($L12,'Arabica Dbse'!$W:$W,'Arabica Dbse'!AA:AA,NA()) -> #N/A | Z12: =_xlfn.XLOOKUP($L12,'Arabica Dbse'!$W:$W,'Arabica Dbse'!AB:AB,NA()) -> #N/A | AA12: =_xlfn.XLOOKUP($L12,'Arabica Dbse'!$W:$W,'Arabica Dbse'!AC:AC,NA()) -> #N/A | AB12: =_xlfn.XLOOKUP($L12,'Arabica Dbse'!$W:$W,'Arabica Dbse'!AD:AD,NA()) -> #N/A | AC12: =_xlfn.XLOOKUP($L12,'Arabica Dbse'!$W:$W,'Arabica Dbse'!AE:AE,NA()) -> #N/A | AD12: =_xlfn.XLOOKUP($L12,'Arabica Dbse'!$W:$W,'Arabica Dbse'!AF:AF,NA()) -> #N/A | AE12: =_xlfn.XLOOKUP($L12,'Arabica Dbse'!$W:$W,'Arabica Dbse'!AG:AG,NA()) -> #N/A | AF12: =_xlfn.XLOOKUP($L12,'Arabica Dbse'!$W:$W,'Arabica Dbse'!AH:AH,NA()) -> #N/A | AG12: =_xlfn.XLOOKUP($L12,'Arabica Dbse'!$W:$W,'Arabica Dbse'!AI:AI,NA()) -> #N/A
A13: =_xlfn.XLOOKUP(B13,'Arabica Dbse'!R:R,'Arabica Dbse'!U:U) -> #N/A | B13: 46268 | C13: 370 | D13: 200 | E13: 200 | F13: 180 | G13: 180 | H13: 450 | I13: 550 | J13: 580 | K13: 220 | L13: =B13 -> 46268 | M13: =IF(C13=0,NA(),$A13+C13) -> #N/A | N13: =IF(D13=0,NA(),$A13+D13) -> #N/A | O13: =IF(E13=0,NA(),$A13+E13) -> #N/A | P13: =IF(F13=0,NA(),$A13+F13) -> #N/A | Q13: =IF(G13=0,NA(),$A13+G13) -> #N/A | R13: =IF(H13=0,NA(),$A13+H13) -> #N/A | S13: =IF(I13=0,NA(),$A13+I13) -> #N/A | T13: =IF(J13=0,NA(),$A13+J13) -> #N/A | U13: =IF(K13=0,NA(),$A13+K13) -> #N/A | V13: =_xlfn.XLOOKUP($L13,'Arabica Dbse'!$W:$W,'Arabica Dbse'!X:X,NA()) -> #N/A | W13: =_xlfn.XLOOKUP($L13,'Arabica Dbse'!$W:$W,'Arabica Dbse'!Y:Y,NA()) -> #N/A | X13: =_xlfn.XLOOKUP($L13,'Arabica Dbse'!$W:$W,'Arabica Dbse'!Z:Z,NA()) -> #N/A | Y13: =_xlfn.XLOOKUP($L13,'Arabica Dbse'!$W:$W,'Arabica Dbse'!AA:AA,NA()) -> #N/A | Z13: =_xlfn.XLOOKUP($L13,'Arabica Dbse'!$W:$W,'Arabica Dbse'!AB:AB,NA()) -> #N/A | AA13: =_xlfn.XLOOKUP($L13,'Arabica Dbse'!$W:$W,'Arabica Dbse'!AC:AC,NA()) -> #N/A | AB13: =_xlfn.XLOOKUP($L13,'Arabica Dbse'!$W:$W,'Arabica Dbse'!AD:AD,NA()) -> #N/A | AC13: =_xlfn.XLOOKUP($L13,'Arabica Dbse'!$W:$W,'Arabica Dbse'!AE:AE,NA()) -> #N/A | AD13: =_xlfn.XLOOKUP($L13,'Arabica Dbse'!$W:$W,'Arabica Dbse'!AF:AF,NA()) -> #N/A | AE13: =_xlfn.XLOOKUP($L13,'Arabica Dbse'!$W:$W,'Arabica Dbse'!AG:AG,NA()) -> #N/A | AF13: =_xlfn.XLOOKUP($L13,'Arabica Dbse'!$W:$W,'Arabica Dbse'!AH:AH,NA()) -> #N/A | AG13: =_xlfn.XLOOKUP($L13,'Arabica Dbse'!$W:$W,'Arabica Dbse'!AI:AI,NA()) -> #N/A
A14: =_xlfn.XLOOKUP(B14,'Arabica Dbse'!R:R,'Arabica Dbse'!U:U) -> #N/A | B14: 46261 | C14: 370 | D14: 220 | E14: 220 | F14: 200 | G14: 200 | H14: 450 | I14: 550 | J14: 580 | K14: 220 | L14: =B14 -> 46261 | M14: =IF(C14=0,NA(),$A14+C14) -> #N/A | N14: =IF(D14=0,NA(),$A14+D14) -> #N/A | O14: =IF(E14=0,NA(),$A14+E14) -> #N/A | P14: =IF(F14=0,NA(),$A14+F14) -> #N/A | Q14: =IF(G14=0,NA(),$A14+G14) -> #N/A | R14: =IF(H14=0,NA(),$A14+H14) -> #N/A | S14: =IF(I14=0,NA(),$A14+I14) -> #N/A | T14: =IF(J14=0,NA(),$A14+J14) -> #N/A | U14: =IF(K14=0,NA(),$A14+K14) -> #N/A | V14: =_xlfn.XLOOKUP($L14,'Arabica Dbse'!$W:$W,'Arabica Dbse'!X:X,NA()) -> #N/A | W14: =_xlfn.XLOOKUP($L14,'Arabica Dbse'!$W:$W,'Arabica Dbse'!Y:Y,NA()) -> #N/A | X14: =_xlfn.XLOOKUP($L14,'Arabica Dbse'!$W:$W,'Arabica Dbse'!Z:Z,NA()) -> #N/A | Y14: =_xlfn.XLOOKUP($L14,'Arabica Dbse'!$W:$W,'Arabica Dbse'!AA:AA,NA()) -> #N/A | Z14: =_xlfn.XLOOKUP($L14,'Arabica Dbse'!$W:$W,'Arabica Dbse'!AB:AB,NA()) -> #N/A | AA14: =_xlfn.XLOOKUP($L14,'Arabica Dbse'!$W:$W,'Arabica Dbse'!AC:AC,NA()) -> #N/A | AB14: =_xlfn.XLOOKUP($L14,'Arabica Dbse'!$W:$W,'Arabica Dbse'!AD:AD,NA()) -> #N/A | AC14: =_xlfn.XLOOKUP($L14,'Arabica Dbse'!$W:$W,'Arabica Dbse'!AE:AE,NA()) -> #N/A | AD14: =_xlfn.XLOOKUP($L14,'Arabica Dbse'!$W:$W,'Arabica Dbse'!AF:AF,NA()) -> #N/A | AE14: =_xlfn.XLOOKUP($L14,'Arabica Dbse'!$W:$W,'Arabica Dbse'!AG:AG,NA()) -> #N/A | AF14: =_xlfn.XLOOKUP($L14,'Arabica Dbse'!$W:$W,'Arabica Dbse'!AH:AH,NA()) -> #N/A | AG14: =_xlfn.XLOOKUP($L14,'Arabica Dbse'!$W:$W,'Arabica Dbse'!AI:AI,NA()) -> #N/A
A15: =_xlfn.XLOOKUP(B15,'Arabica Dbse'!R:R,'Arabica Dbse'!U:U) -> #N/A | B15: 46254 | C15: 370 | D15: 200 | E15: 200 | F15: 180 | G15: 200 | H15: 450 | I15: 550 | J15: 580 | K15: 220 | L15: =B15 -> 46254 | M15: =IF(C15=0,NA(),$A15+C15) -> #N/A | N15: =IF(D15=0,NA(),$A15+D15) -> #N/A | O15: =IF(E15=0,NA(),$A15+E15) -> #N/A | P15: =IF(F15=0,NA(),$A15+F15) -> #N/A | Q15: =IF(G15=0,NA(),$A15+G15) -> #N/A | R15: =IF(H15=0,NA(),$A15+H15) -> #N/A | S15: =IF(I15=0,NA(),$A15+I15) -> #N/A | T15: =IF(J15=0,NA(),$A15+J15) -> #N/A | U15: =IF(K15=0,NA(),$A15+K15) -> #N/A | V15: =_xlfn.XLOOKUP($L15,'Arabica Dbse'!$W:$W,'Arabica Dbse'!X:X,NA()) -> #N/A | W15: =_xlfn.XLOOKUP($L15,'Arabica Dbse'!$W:$W,'Arabica Dbse'!Y:Y,NA()) -> #N/A | X15: =_xlfn.XLOOKUP($L15,'Arabica Dbse'!$W:$W,'Arabica Dbse'!Z:Z,NA()) -> #N/A | Y15: =_xlfn.XLOOKUP($L15,'Arabica Dbse'!$W:$W,'Arabica Dbse'!AA:AA,NA()) -> #N/A | Z15: =_xlfn.XLOOKUP($L15,'Arabica Dbse'!$W:$W,'Arabica Dbse'!AB:AB,NA()) -> #N/A | AA15: =_xlfn.XLOOKUP($L15,'Arabica Dbse'!$W:$W,'Arabica Dbse'!AC:AC,NA()) -> #N/A | AB15: =_xlfn.XLOOKUP($L15,'Arabica Dbse'!$W:$W,'Arabica Dbse'!AD:AD,NA()) -> #N/A | AC15: =_xlfn.XLOOKUP($L15,'Arabica Dbse'!$W:$W,'Arabica Dbse'!AE:AE,NA()) -> #N/A | AD15: =_xlfn.XLOOKUP($L15,'Arabica Dbse'!$W:$W,'Arabica Dbse'!AF:AF,NA()) -> #N/A | AE15: =_xlfn.XLOOKUP($L15,'Arabica Dbse'!$W:$W,'Arabica Dbse'!AG:AG,NA()) -> #N/A | AF15: =_xlfn.XLOOKUP($L15,'Arabica Dbse'!$W:$W,'Arabica Dbse'!AH:AH,NA()) -> #N/A | AG15: =_xlfn.XLOOKUP($L15,'Arabica Dbse'!$W:$W,'Arabica Dbse'!AI:AI,NA()) -> #N/A
A16: =_xlfn.XLOOKUP(B16,'Arabica Dbse'!R:R,'Arabica Dbse'!U:U) -> #N/A | B16: 46247 | C16: 350 | D16: 200 | E16: 200 | F16: 180 | G16: 300 | H16: 470 | I16: 550 | J16: 600 | K16: 220 | L16: =B16 -> 46247 | M16: =IF(C16=0,NA(),$A16+C16) -> #N/A | N16: =IF(D16=0,NA(),$A16+D16) -> #N/A | O16: =IF(E16=0,NA(),$A16+E16) -> #N/A | P16: =IF(F16=0,NA(),$A16+F16) -> #N/A | Q16: =IF(G16=0,NA(),$A16+G16) -> #N/A | R16: =IF(H16=0,NA(),$A16+H16) -> #N/A | S16: =IF(I16=0,NA(),$A16+I16) -> #N/A | T16: =IF(J16=0,NA(),$A16+J16) -> #N/A | U16: =IF(K16=0,NA(),$A16+K16) -> #N/A | V16: =_xlfn.XLOOKUP($L16,'Arabica Dbse'!$W:$W,'Arabica Dbse'!X:X,NA()) -> #N/A | W16: =_xlfn.XLOOKUP($L16,'Arabica Dbse'!$W:$W,'Arabica Dbse'!Y:Y,NA()) -> #N/A | X16: =_xlfn.XLOOKUP($L16,'Arabica Dbse'!$W:$W,'Arabica Dbse'!Z:Z,NA()) -> #N/A | Y16: =_xlfn.XLOOKUP($L16,'Arabica Dbse'!$W:$W,'Arabica Dbse'!AA:AA,NA()) -> #N/A | Z16: =_xlfn.XLOOKUP($L16,'Arabica Dbse'!$W:$W,'Arabica Dbse'!AB:AB,NA()) -> #N/A | AA16: =_xlfn.XLOOKUP($L16,'Arabica Dbse'!$W:$W,'Arabica Dbse'!AC:AC,NA()) -> #N/A | AB16: =_xlfn.XLOOKUP($L16,'Arabica Dbse'!$W:$W,'Arabica Dbse'!AD:AD,NA()) -> #N/A | AC16: =_xlfn.XLOOKUP($L16,'Arabica Dbse'!$W:$W,'Arabica Dbse'!AE:AE,NA()) -> #N/A | AD16: =_xlfn.XLOOKUP($L16,'Arabica Dbse'!$W:$W,'Arabica Dbse'!AF:AF,NA()) -> #N/A | AE16: =_xlfn.XLOOKUP($L16,'Arabica Dbse'!$W:$W,'Arabica Dbse'!AG:AG,NA()) -> #N/A | AF16: =_xlfn.XLOOKUP($L16,'Arabica Dbse'!$W:$W,'Arabica Dbse'!AH:AH,NA()) -> #N/A | AG16: =_xlfn.XLOOKUP($L16,'Arabica Dbse'!$W:$W,'Arabica Dbse'!AI:AI,NA()) -> #N/A
A17: =_xlfn.XLOOKUP(B17,'Arabica Dbse'!R:R,'Arabica Dbse'!U:U) -> #N/A | B17: 46240 | C17: 340 | D17: 180 | E17: 180 | F17: 160 | G17: 250 | H17: 420 | I17: 500 | J17: 550 | K17: 220 | L17: =B17 -> 46240 | M17: =IF(C17=0,NA(),$A17+C17) -> #N/A | N17: =IF(D17=0,NA(),$A17+D17) -> #N/A | O17: =IF(E17=0,NA(),$A17+E17) -> #N/A | P17: =IF(F17=0,NA(),$A17+F17) -> #N/A | Q17: =IF(G17=0,NA(),$A17+G17) -> #N/A | R17: =IF(H17=0,NA(),$A17+H17) -> #N/A | S17: =IF(I17=0,NA(),$A17+I17) -> #N/A | T17: =IF(J17=0,NA(),$A17+J17) -> #N/A | U17: =IF(K17=0,NA(),$A17+K17) -> #N/A | V17: =_xlfn.XLOOKUP($L17,'Arabica Dbse'!$W:$W,'Arabica Dbse'!X:X,NA()) -> #N/A | W17: =_xlfn.XLOOKUP($L17,'Arabica Dbse'!$W:$W,'Arabica Dbse'!Y:Y,NA()) -> #N/A | X17: =_xlfn.XLOOKUP($L17,'Arabica Dbse'!$W:$W,'Arabica Dbse'!Z:Z,NA()) -> #N/A | Y17: =_xlfn.XLOOKUP($L17,'Arabica Dbse'!$W:$W,'Arabica Dbse'!AA:AA,NA()) -> #N/A | Z17: =_xlfn.XLOOKUP($L17,'Arabica Dbse'!$W:$W,'Arabica Dbse'!AB:AB,NA()) -> #N/A | AA17: =_xlfn.XLOOKUP($L17,'Arabica Dbse'!$W:$W,'Arabica Dbse'!AC:AC,NA()) -> #N/A | AB17: =_xlfn.XLOOKUP($L17,'Arabica Dbse'!$W:$W,'Arabica Dbse'!AD:AD,NA()) -> #N/A | AC17: =_xlfn.XLOOKUP($L17,'Arabica Dbse'!$W:$W,'Arabica Dbse'!AE:AE,NA()) -> #N/A | AD17: =_xlfn.XLOOKUP($L17,'Arabica Dbse'!$W:$W,'Arabica Dbse'!AF:AF,NA()) -> #N/A | AE17: =_xlfn.XLOOKUP($L17,'Arabica Dbse'!$W:$W,'Arabica Dbse'!AG:AG,NA()) -> #N/A | AF17: =_xlfn.XLOOKUP($L17,'Arabica Dbse'!$W:$W,'Arabica Dbse'!AH:AH,NA()) -> #N/A | AG17: =_xlfn.XLOOKUP($L17,'Arabica Dbse'!$W:$W,'Arabica Dbse'!AI:AI,NA()) -> #N/A
... A144: =_xlfn.XLOOKUP(B144,'Arabica Dbse'!R:R,'Arabica Dbse'!U:U) -> 3095 | B144: 45351 | C144: 800 | D144: 600 | E144: 600 | F144: 580 | G144: 600 | H144: 500 | I144: 600 | J144: 550 | K144: 310 | L144: =B144 -> 45351 | M144: =IF(C144=0,NA(),$A144+C144) -> 3895 | N144: =IF(D144=0,NA(),$A144+D144) -> 3695 | O144: =IF(E144=0,NA(),$A144+E144) -> 3695 | P144: =IF(F144=0,NA(),$A144+F144) -> 3675 | Q144: =IF(G144=0,NA(),$A144+G144) -> 3695 | R144: =IF(H144=0,NA(),$A144+H144) -> 3595 | S144: =IF(I144=0,NA(),$A144+I144) -> 3695 | T144: =IF(J144=0,NA(),$A144+J144) -> 3645 | U144: =IF(K144=0,NA(),$A144+K144) -> 3405 | V144: =_xlfn.XLOOKUP($L144,'Arabica Dbse'!$W:$W,'Arabica Dbse'!X:X,NA()) -> 3884.0801 | W144: =_xlfn.XLOOKUP($L144,'Arabica Dbse'!$W:$W,'Arabica Dbse'!Y:Y,NA()) -> 4108.1401 | X144: =_xlfn.XLOOKUP($L144,'Arabica Dbse'!$W:$W,'Arabica Dbse'!Z:Z,NA()) -> 3749.6441 | Y144: =_xlfn.XLOOKUP($L144,'Arabica Dbse'!$W:$W,'Arabica Dbse'!AA:AA,NA()) -> 3816.8621 | Z144: =_xlfn.XLOOKUP($L144,'Arabica Dbse'!$W:$W,'Arabica Dbse'!AB:AB,NA()) -> 3727.2381 | AA144: =_xlfn.XLOOKUP($L144,'Arabica Dbse'!$W:$W,'Arabica Dbse'!AC:AC,NA()) -> 3749.6441 | AB144: =_xlfn.XLOOKUP($L144,'Arabica Dbse'!$W:$W,'Arabica Dbse'!AD:AD,NA()) -> 3906.4861 | AC144: =_xlfn.XLOOKUP($L144,'Arabica Dbse'!$W:$W,'Arabica Dbse'!AE:AE,NA()) -> 4421.8241 | AD144: =_xlfn.XLOOKUP($L144,'Arabica Dbse'!$W:$W,'Arabica Dbse'!AF:AF,NA()) -> 4264.9821 | AE144: =_xlfn.XLOOKUP($L144,'Arabica Dbse'!$W:$W,'Arabica Dbse'!AG:AG,NA()) -> 4309.7941 | AF144: =_xlfn.XLOOKUP($L144,'Arabica Dbse'!$W:$W,'Arabica Dbse'!AH:AH,NA()) -> 4399.4181 | AG144: =_xlfn.XLOOKUP($L144,'Arabica Dbse'!$W:$W,'Arabica Dbse'!AI:AI,NA()) -> 4511.4481
A145: =_xlfn.XLOOKUP(B145,'Arabica Dbse'!R:R,'Arabica Dbse'!U:U) -> 3113 | B145: 45344 | C145: 620 | D145: 420 | E145: 420 | F145: 400 | H145: 400 | I145: 520 | J145: 520 | K145: 310 | L145: =B145 -> 45344 | M145: =IF(C145=0,NA(),$A145+C145) -> 3733 | N145: =IF(D145=0,NA(),$A145+D145) -> 3533 | O145: =IF(E145=0,NA(),$A145+E145) -> 3533 | P145: =IF(F145=0,NA(),$A145+F145) -> 3513 | Q145: =IF(G145=0,NA(),$A145+G145) -> #N/A | R145: =IF(H145=0,NA(),$A145+H145) -> 3513 | S145: =IF(I145=0,NA(),$A145+I145) -> 3633 | T145: =IF(J145=0,NA(),$A145+J145) -> 3633 | U145: =IF(K145=0,NA(),$A145+K145) -> 3423 | V145: =_xlfn.XLOOKUP($L145,'Arabica Dbse'!$W:$W,'Arabica Dbse'!X:X,NA()) -> 3834.7869 | W145: =_xlfn.XLOOKUP($L145,'Arabica Dbse'!$W:$W,'Arabica Dbse'!Y:Y,NA()) -> 4036.4409 | X145: =_xlfn.XLOOKUP($L145,'Arabica Dbse'!$W:$W,'Arabica Dbse'!Z:Z,NA()) -> 3700.3509 | Y145: =_xlfn.XLOOKUP($L145,'Arabica Dbse'!$W:$W,'Arabica Dbse'!AA:AA,NA()) -> 3767.5689 | Z145: =_xlfn.XLOOKUP($L145,'Arabica Dbse'!$W:$W,'Arabica Dbse'!AB:AB,NA()) -> 3700.3509 | AA145: =_xlfn.XLOOKUP($L145,'Arabica Dbse'!$W:$W,'Arabica Dbse'!AC:AC,NA()) -> 3722.7569 | AB145: =_xlfn.XLOOKUP($L145,'Arabica Dbse'!$W:$W,'Arabica Dbse'!AD:AD,NA()) -> 3879.5989 | AC145: =_xlfn.XLOOKUP($L145,'Arabica Dbse'!$W:$W,'Arabica Dbse'!AE:AE,NA()) -> 4372.5309 | AD145: =_xlfn.XLOOKUP($L145,'Arabica Dbse'!$W:$W,'Arabica Dbse'!AF:AF,NA()) -> 4260.5009 | AE145: =_xlfn.XLOOKUP($L145,'Arabica Dbse'!$W:$W,'Arabica Dbse'!AG:AG,NA()) -> 4282.9069 | AF145: =_xlfn.XLOOKUP($L145,'Arabica Dbse'!$W:$W,'Arabica Dbse'!AH:AH,NA()) -> 4372.5309 | AG145: =_xlfn.XLOOKUP($L145,'Arabica Dbse'!$W:$W,'Arabica Dbse'!AI:AI,NA()) -> 4484.5609
A146: =_xlfn.XLOOKUP(B146,'Arabica Dbse'!R:R,'Arabica Dbse'!U:U) -> 3108 | B146: 45337 | C146: 620 | D146: 400 | E146: 400 | F146: 380 | H146: 400 | I146: 520 | J146: 520 | K146: 310 | L146: =B146 -> 45337 | M146: =IF(C146=0,NA(),$A146+C146) -> 3728 | N146: =IF(D146=0,NA(),$A146+D146) -> 3508 | O146: =IF(E146=0,NA(),$A146+E146) -> 3508 | P146: =IF(F146=0,NA(),$A146+F146) -> 3488 | Q146: =IF(G146=0,NA(),$A146+G146) -> #N/A | R146: =IF(H146=0,NA(),$A146+H146) -> 3508 | S146: =IF(I146=0,NA(),$A146+I146) -> 3628 | T146: =IF(J146=0,NA(),$A146+J146) -> 3628 | U146: =IF(K146=0,NA(),$A146+K146) -> 3418 | V146: =_xlfn.XLOOKUP($L146,'Arabica Dbse'!$W:$W,'Arabica Dbse'!X:X,NA()) -> 3879.5989 | W146: =_xlfn.XLOOKUP($L146,'Arabica Dbse'!$W:$W,'Arabica Dbse'!Y:Y,NA()) -> 4081.2529 | X146: =_xlfn.XLOOKUP($L146,'Arabica Dbse'!$W:$W,'Arabica Dbse'!Z:Z,NA()) -> 3745.1629 | Y146: =_xlfn.XLOOKUP($L146,'Arabica Dbse'!$W:$W,'Arabica Dbse'!AA:AA,NA()) -> 3812.3809 | Z146: =_xlfn.XLOOKUP($L146,'Arabica Dbse'!$W:$W,'Arabica Dbse'!AB:AB,NA()) -> 3745.1629 | AA146: =_xlfn.XLOOKUP($L146,'Arabica Dbse'!$W:$W,'Arabica Dbse'!AC:AC,NA()) -> 3767.5689 | AB146: =_xlfn.XLOOKUP($L146,'Arabica Dbse'!$W:$W,'Arabica Dbse'!AD:AD,NA()) -> 3924.4109 | AC146: =_xlfn.XLOOKUP($L146,'Arabica Dbse'!$W:$W,'Arabica Dbse'!AE:AE,NA()) -> 4394.9369 | AD146: =_xlfn.XLOOKUP($L146,'Arabica Dbse'!$W:$W,'Arabica Dbse'!AF:AF,NA()) -> 4305.3129 | AE146: =_xlfn.XLOOKUP($L146,'Arabica Dbse'!$W:$W,'Arabica Dbse'!AG:AG,NA()) -> 4327.7189 | AF146: =_xlfn.XLOOKUP($L146,'Arabica Dbse'!$W:$W,'Arabica Dbse'!AH:AH,NA()) -> 4417.3429 | AG146: =_xlfn.XLOOKUP($L146,'Arabica Dbse'!$W:$W,'Arabica Dbse'!AI:AI,NA()) -> 4529.3729
A147: =_xlfn.XLOOKUP(B147,'Arabica Dbse'!R:R,'Arabica Dbse'!U:U) -> 3109 | B147: 45330 | C147: 500 | D147: 320 | E147: 320 | F147: 300 | H147: 400 | I147: 520 | J147: 520 | K147: 310 | L147: =B147 -> 45330 | M147: =IF(C147=0,NA(),$A147+C147) -> 3609 | N147: =IF(D147=0,NA(),$A147+D147) -> 3429 | O147: =IF(E147=0,NA(),$A147+E147) -> 3429 | P147: =IF(F147=0,NA(),$A147+F147) -> 3409 | Q147: =IF(G147=0,NA(),$A147+G147) -> #N/A | R147: =IF(H147=0,NA(),$A147+H147) -> 3509 | S147: =IF(I147=0,NA(),$A147+I147) -> 3629 | T147: =IF(J147=0,NA(),$A147+J147) -> 3629 | U147: =IF(K147=0,NA(),$A147+K147) -> 3419 | V147: =_xlfn.XLOOKUP($L147,'Arabica Dbse'!$W:$W,'Arabica Dbse'!X:X,NA()) -> 3917.6891 | W147: =_xlfn.XLOOKUP($L147,'Arabica Dbse'!$W:$W,'Arabica Dbse'!Y:Y,NA()) -> 4096.9371 | X147: =_xlfn.XLOOKUP($L147,'Arabica Dbse'!$W:$W,'Arabica Dbse'!Z:Z,NA()) -> 3716.0351 | Y147: =_xlfn.XLOOKUP($L147,'Arabica Dbse'!$W:$W,'Arabica Dbse'!AA:AA,NA()) -> 3783.2531 | Z147: =_xlfn.XLOOKUP($L147,'Arabica Dbse'!$W:$W,'Arabica Dbse'!AB:AB,NA()) -> 3805.6591 | AA147: =_xlfn.XLOOKUP($L147,'Arabica Dbse'!$W:$W,'Arabica Dbse'!AC:AC,NA()) -> 3828.0651 | AB147: =_xlfn.XLOOKUP($L147,'Arabica Dbse'!$W:$W,'Arabica Dbse'!AD:AD,NA()) -> 3940.0951 | AC147: =_xlfn.XLOOKUP($L147,'Arabica Dbse'!$W:$W,'Arabica Dbse'!AE:AE,NA()) -> 4388.2151 | AD147: =_xlfn.XLOOKUP($L147,'Arabica Dbse'!$W:$W,'Arabica Dbse'!AF:AF,NA()) -> 4343.4031 | AE147: =_xlfn.XLOOKUP($L147,'Arabica Dbse'!$W:$W,'Arabica Dbse'!AG:AG,NA()) -> 4343.4031 | AF147: =_xlfn.XLOOKUP($L147,'Arabica Dbse'!$W:$W,'Arabica Dbse'!AH:AH,NA()) -> 4433.0271 | AG147: =_xlfn.XLOOKUP($L147,'Arabica Dbse'!$W:$W,'Arabica Dbse'!AI:AI,NA()) -> 4567.4631
A148: =_xlfn.XLOOKUP(B148,'Arabica Dbse'!R:R,'Arabica Dbse'!U:U) -> 3151 | B148: 45323 | C148: 450 | D148: 280 | E148: 280 | F148: 260 | H148: 400 | I148: 520 | J148: 520 | K148: 310 | L148: =B148 -> 45323 | M148: =IF(C148=0,NA(),$A148+C148) -> 3601 | N148: =IF(D148=0,NA(),$A148+D148) -> 3431 | O148: =IF(E148=0,NA(),$A148+E148) -> 3431 | P148: =IF(F148=0,NA(),$A148+F148) -> 3411 | Q148: =IF(G148=0,NA(),$A148+G148) -> #N/A | R148: =IF(H148=0,NA(),$A148+H148) -> 3551 | S148: =IF(I148=0,NA(),$A148+I148) -> 3671 | T148: =IF(J148=0,NA(),$A148+J148) -> 3671 | U148: =IF(K148=0,NA(),$A148+K148) -> 3461 | V148: =_xlfn.XLOOKUP($L148,'Arabica Dbse'!$W:$W,'Arabica Dbse'!X:X,NA()) -> 4031.9597 | W148: =_xlfn.XLOOKUP($L148,'Arabica Dbse'!$W:$W,'Arabica Dbse'!Y:Y,NA()) -> 4233.6137 | X148: =_xlfn.XLOOKUP($L148,'Arabica Dbse'!$W:$W,'Arabica Dbse'!Z:Z,NA()) -> 3830.3057 | Y148: =_xlfn.XLOOKUP($L148,'Arabica Dbse'!$W:$W,'Arabica Dbse'!AA:AA,NA()) -> 3897.5237 | Z148: =_xlfn.XLOOKUP($L148,'Arabica Dbse'!$W:$W,'Arabica Dbse'!AB:AB,NA()) -> 3830.3057 | AA148: =_xlfn.XLOOKUP($L148,'Arabica Dbse'!$W:$W,'Arabica Dbse'!AC:AC,NA()) -> 3942.3357 | AB148: =_xlfn.XLOOKUP($L148,'Arabica Dbse'!$W:$W,'Arabica Dbse'!AD:AD,NA()) -> 4054.3657 | AC148: =_xlfn.XLOOKUP($L148,'Arabica Dbse'!$W:$W,'Arabica Dbse'!AE:AE,NA()) -> 4502.4857 | AD148: =_xlfn.XLOOKUP($L148,'Arabica Dbse'!$W:$W,'Arabica Dbse'!AF:AF,NA()) -> 4412.8617 | AE148: =_xlfn.XLOOKUP($L148,'Arabica Dbse'!$W:$W,'Arabica Dbse'!AG:AG,NA()) -> 4457.6737 | AF148: =_xlfn.XLOOKUP($L148,'Arabica Dbse'!$W:$W,'Arabica Dbse'!AH:AH,NA()) -> 4547.2977 | AG148: =_xlfn.XLOOKUP($L148,'Arabica Dbse'!$W:$W,'Arabica Dbse'!AI:AI,NA()) -> 4681.7337
