Workbook

Sheet Menu
D1: CONAB
F5: Total Coffee
F7: Arabica
F9: Conilon

Sheet Total Coffee
L1: Total Coffee
D5: AREA IN PRODUCTION (ha) | N5: Production (k Bags) | X5: Productivity (sc/ha)
B6: Region | C6: 2018 | D6: 2019 | E6: 2020 | F6: 2021 | G6: 2022 | H6: 2023 | I6: 2024 | L6: Region | M6: 2018 | N6: 2019 | O6: 2020 | P6: 2021 | Q6: 2022 | R6: 2023 | S6: 2024 | V6: Region | W6: 2018 | X6: 2019 | Y6: 2020 | Z6: 2021 | AA6: 2022 | AB6: 2023 | AC6: 2024
B7: NORTE | C7: 63879 | D7: 62729 | E7: 63569 | F7: 68191 | G7: 64977 | H7: 61164.9 | I7: 54350.3 | L7: NORTE | M7: 1978.3 | N7: 2198.7 | O7: 2444.9 | P7: 2338.3 | Q7: 2800.5 | R7: 3054.3 | S7: 2749.7 | V7: NORTE | W7: 30.969489 | X7: 35.050774 | Y7: 38.46057 | Z7: 34.290449 | AA7: 43.099866 | AB7: 49.935502 | AC7: 50.592177
B8: RO | C8: 63879 | D8: 62729 | E8: 63569 | F8: 63569 | G8: 64977 | H8: 60621 | I8: 53792 | L8: RO | M8: 1978.3 | N8: 2198.7 | O8: 2444.9 | P8: 2263.1 | Q8: 2800.5 | R8: 3041.4 | S8: 2732.6 | V8: RO | W8: 30.969489 | X8: 35.050774 | Y8: 38.46057 | Z8: 35.600686 | AA8: 43.099866 | AB8: 50.170733 | AC8: 50.799375
B9: AM | D9: 0 | E9: 0 | F9: 4622 | G9: 0 | H9: 543.9 | I9: 558.3 | L9: AM | N9: 0 | O9: 0 | P9: 75.2 | Q9: 0 | R9: 12.9 | S9: 17.1 | V9: AM | X9: 0 | Y9: 0 | Z9: 16.270013 | AA9: 0 | AB9: 23.717595 | AC9: 30.628694
D10: 0 | E10: 0 | F10: 0 | G10: 0 | N10: 0 | O10: 0 | P10: 0 | Q10: 0 | X10: 0 | Y10: 0 | Z10: 0 | AA10: 0
B11: NORDESTE | C11: 130000 | D11: 97335 | E11: 106185 | F11: 98310 | G11: 92880 | H11: 97840 | I11: 101375 | L11: NORDESTE | M11: 4550.2 | N11: 3000 | O11: 3986.7 | P11: 3469 | Q11: 3603.5 | R11: 3396.7 | S11: 3564.6 | V11: NORDESTE | W11: 35.001538 | X11: 30.82139 | Y11: 37.544851 | Z11: 35.286339 | AA11: 38.797373 | AB11: 34.716885 | AC11: 35.162515
B12: BA | C12: 130000 | D12: 97335 | E12: 106185 | F12: 98310 | G12: 92880 | H12: 97840 | I12: 101375 | L12: BA | M12: 4550.2 | N12: 3000 | O12: 3986.7 | P12: 3469 | Q12: 3603.5 | R12: 3396.7 | S12: 3564.6 | V12: BA | W12: 35.001538 | X12: 30.82139 | Y12: 37.544851 | Z12: 35.286339 | AA12: 38.797373 | AB12: 34.716885 | AC12: 35.162515
B13: Cerrado | C13: 11300 | D13: 9000 | E13: 8600 | F13: 6250 | G13: 6500 | H13: 5180 | I13: 5200 | L13: Cerrado | M13: 497.2 | N13: 300 | O13: 350 | P13: 250 | Q13: 279.5 | R13: 205 | S13: 228.8 | V13: Cerrado | W13: 44 | X13: 33.333333 | Y13: 40.697674 | Z13: 40 | AA13: 43 | AB13: 39.57529 | AC13: 44
B14: Planalto | C14: 71000 | D14: 51335 | E14: 58335 | F14: 52060 | G14: 46100 | H14: 49800 | I14: 51845 | L14: Planalto | M14: 1383 | N14: 900 | O14: 1516.7 | P14: 979 | Q14: 991 | R14: 902.6 | S14: 853.9 | V14: Planalto | W14: 19.478873 | X14: 17.531898 | Y14: 25.999829 | Z14: 18.805225 | AA14: 21.496746 | AB14: 18.124498 | AC14: 16.470248
B15: Atlântico | C15: 47700 | D15: 37000 | E15: 39250 | F15: 40000 | G15: 40280 | H15: 42860 | I15: 44330 | L15: Atlântico | M15: 2670 | N15: 1800 | O15: 2120 | P15: 2240 | Q15: 2333 | R15: 2289.1 | S15: 2481.9 | V15: Atlântico | W15: 55.974843 | X15: 48.648649 | Y15: 54.012739 | Z15: 56 | AA15: 57.919563 | AB15: 53.408773 | AC15: 55.986916
B16: CENTRO-OESTE | C16: 15215 | D16: 15354 | E16: 15737 | F16: 16557 | G16: 17245 | H16: 16870 | I16: 17531 | L16: CENTRO-OESTE | M16: 299.6 | N16: 370.7 | O16: 406.2 | P16: 425.8 | Q16: 505.6 | R16: 462.1 | S16: 534.3 | V16: CENTRO-OESTE | W16: 19.691094 | X16: 24.143546 | Y16: 25.811781 | Z16: 25.717219 | AA16: 29.318643 | AB16: 27.39182 | AC16: 30.47744
B17: MT | C17: 9310 | D17: 8422 | E17: 9602 | F17: 10824 | G17: 11052 | H17: 11499 | I17: 11608 | L17: MT | M17: 104.2 | N17: 121.4 | O17: 158.4 | P17: 195.5 | Q17: 227.9 | R17: 260.3 | S17: 270.8 | V17: MT | W17: 11.192266 | X17: 14.414628 | Y17: 16.496563 | Z17: 18.061715 | AA17: 20.620702 | AB17: 22.636751 | AC17: 23.328739
B18: GO | C18: 5905 | D18: 6932 | E18: 6135 | F18: 5733 | G18: 6193 | H18: 5371 | I18: 5923 | L18: GO | M18: 195.4 | N18: 249.3 | O18: 247.8 | P18: 231.6 | Q18: 277.7 | R18: 201.8 | S18: 263.5 | V18: GO | W18: 33.090601 | X18: 35.963647 | Y18: 40.391198 | Z18: 40.397698 | AA18: 44.840949 | AB18: 37.572147 | AC18: 44.487591
B19: SUDESTE | C19: 1611132 | D19: 1590710 | E19: 1655171.4 | F19: 1588624 | G19: 1630727.4 | H19: 1667952 | I19: 1699771 | L19: SUDESTE | M19: 53747.7 | N19: 42636.11 | O19: 55156.812 | P19: 40541.3 | Q19: 43362.4 | R19: 47356.6 | S19: 51179.9 | V19: SUDESTE | W19: 33.360209 | X19: 26.803195 | Y19: 33.323929 | Z19: 25.519758 | AA19: 26.590833 | AB19: 28.392064 | AC19: 30.10988
B20: MG | C20: 1008595 | D20: 983726 | E20: 1041392.4 | F20: 979449 | G20: 1017984 | H20: 1082447 | I20: 1110753 | L20: MG | M20: 33360.4 | N20: 24553.61 | O20: 34647.112 | P20: 22142.3 | Q20: 21960.1 | R20: 29005.9 | S20: 30181.3 | V20: MG | W20: 33.076111 | X20: 24.959806 | Y20: 33.269989 | Z20: 22.606894 | AA20: 21.572147 | AB20: 26.796601 | AC20: 27.171928
B21: Sul e Centro-Oeste | C21: 514193 | D21: 496613.4 | E21: 538393.78 | F21: 491785 | G21: 496684 | H21: 533271 | I21: 552669 | L21: Sul e Centro-Oeste | M21: 17896.1 | N21: 13978.79 | O21: 19152.181 | P21: 11751.9 | Q21: 9599.6 | R21: 13513 | S21: 15042.3 | V21: Sul e Centro-Oeste | W21: 34.804247 | X21: 28.148234 | Y21: 35.572813 | Z21: 23.896418 | AA21: 19.327379 | AB21: 25.339837 | AC21: 27.217557
B22: Triângulo, Alto Paranaiba e Noroeste | C22: 189183 | D22: 185688.2 | E22: 193826.59 | F22: 189604 | G22: 181703 | H22: 199471 | I22: 195258 | L22: Triângulo, Alto Paranaiba e Noroeste | M22: 7138 | N22: 4591.91 | O22: 6000.7954 | P22: 4777.5 | Q22: 4198.5 | R22: 7588.6 | S22: 5592.8 | V22: Triângulo, Alto Paranaiba e Noroeste | W22: 37.730663 | X22: 24.729143 | Y22: 30.959609 | Z22: 25.197253 | AA22: 23.106388 | AB22: 38.043625 | AC22: 28.643129
... B33: BRASIL | C33: 1864322.8 | D33: 1812909 | E33: 1884315.4 | F33: 1809345 | G33: 1841528.4 | H33: 1873779.9 | I33: 1902816.3 | L33: BRASIL | M33: 61657.5 | N33: 49309.31 | O33: 63077.912 | P33: 47729.8 | Q33: 50920.1 | R33: 55072.3 | S33: 58813.8 | V33: BRASIL | W33: 33.072331 | X33: 27.198999 | Y33: 33.475242 | Z33: 26.379601 | AA33: 27.650999 | AB33: 29.391019 | AC33: 30.908817
D69: AREA IN Development (ha)
B70: Region | C70: 2018 | D70: 2019 | E70: 2020 | F70: 2021 | G70: 2022 | H70: 2023 | I70: 2024
B71: NORTE | C71: 9538 | D71: 7820 | E71: 6180 | F71: 6107 | G71: 6230 | H71: 5945.8 | I71: 5310.1
B72: RO | C72: 9538 | D72: 7820 | E72: 6180 | F72: 5630 | G72: 6230 | H72: 5800 | I72: 5050
B73: AM | C73: 0 | D73: 0 | E73: 0 | F73: 477 | G73: 0 | H73: 145.8 | I73: 260.1
C74: 0 | D74: 0 | E74: 0 | F74: 0 | G74: 0 | H74: 0 | I74: 0
B75: NORDESTE | C75: 7487 | D75: 12400 | E75: 8680 | F75: 10649 | G75: 18080 | H75: 17765 | I75: 14790
B76: BA | C76: 7487 | D76: 12400 | E76: 8680 | F76: 10649 | G76: 18080 | H76: 17765 | I76: 14790
B77: Cerrado | C77: 937 | D77: 2300 | E77: 1000 | F77: 1489 | G77: 1400 | H77: 2240 | I77: 1800
B78: Planalto | C78: 3650 | D78: 7200 | E78: 6000 | F78: 7200 | G78: 14400 | H78: 12745 | I78: 10700
B79: Atlântico | C79: 2900 | D79: 2900 | E79: 1680 | F79: 1960 | G79: 1960 | H79: 2780 | I79: 2290
B80: CENTRO-OESTE | C80: 5001 | D80: 4090 | E80: 2997 | F80: 1770 | G80: 1051 | H80: 2054 | I80: 1855
B81: MT | C81: 2856 | D81: 2790 | E81: 1425 | F81: 330 | G81: 225 | H81: 261 | I81: 583
B82: GO | C82: 2145 | D82: 1300 | E82: 1572 | F82: 1440 | G82: 826 | H82: 1793 | I82: 1272
B83: SUDESTE | C83: 267559 | D83: 291157 | E83: 256047.54 | F83: 399015 | G83: 371715 | H83: 332540 | I83: 319351
B84: MG | C84: 215038 | D84: 246281 | E84: 205988.54 | F84: 319065 | G84: 316498 | H84: 266094 | I84: 259947
B85: Sul e Centro-Oeste | C85: 118186 | D85: 155249 | E85: 129468.16 | F85: 175605 | G85: 186550 | H85: 159202 | I85: 150484
B86: Triângulo, Alto Paranaiba e Noroeste | C86: 42829 | D86: 40235 | E86: 32919.687 | F86: 48361 | G86: 61359 | H86: 40578 | I86: 49504
... B97: BRASIL | C97: 294194.1 | D97: 318917 | E97: 277283.54 | F97: 419513 | G97: 399630 | H97: 361609.8 | I97: 344611.1

Sheet Arabica
L1: Arabica
D5: AREA IN PRODUCTION (ha) | N5: Production (k Bags) | X5: Productivity (sc/ha)
B6: Region | C6: 2018 | D6: 2019 | E6: 2020 | F6: 2021 | G6: 2022 | H6: 2023 | I6: 2024 | L6: Region | M6: 2018 | N6: 2019 | O6: 2020 | P6: 2021 | Q6: 2022 | R6: 2023 | S6: 2024 | V6: Region | W6: 2018 | X6: 2019 | Y6: 2020 | Z6: 2021 | AA6: 2022 | AB6: 2023 | AC6: 2024
B7: NORDESTE | C7: 82300 | D7: 60335 | E7: 66935 | F7: 58310 | G7: 52600 | H7: 54980 | I7: 57045 | L7: NORDESTE | M7: 1880.2 | N7: 1200 | O7: 1866.7 | P7: 1229 | Q7: 1270.5 | R7: 1107.6 | S7: 1082.7 | V7: NORDESTE | W7: 22.845687 | X7: 19.888953 | Y7: 27.88825 | Z7: 21.077002 | AA7: 24.153992 | AB7: 20.145507 | AC7: 18.979753
B8: BA | C8: 82300 | D8: 60335 | E8: 66935 | F8: 58310 | G8: 52600 | H8: 54980 | I8: 57045 | L8: BA | M8: 1880.2 | N8: 1200 | O8: 1866.7 | P8: 1229 | Q8: 1270.5 | R8: 1107.6 | S8: 1082.7 | V8: BA | W8: 22.845687 | X8: 19.888953 | Y8: 27.88825 | Z8: 21.077002 | AA8: 24.153992 | AB8: 20.145507 | AC8: 18.979753
B9: Cerrado | C9: 11300 | D9: 9000 | E9: 8600 | F9: 6250 | G9: 6500 | H9: 5180 | I9: 5200 | L9: Cerrado | M9: 497.2 | N9: 300 | O9: 350 | P9: 250 | Q9: 279.5 | R9: 205 | S9: 228.8 | V9: Cerrado | W9: 44 | X9: 33.333333 | Y9: 40.697674 | Z9: 40 | AA9: 43 | AB9: 39.57529 | AC9: 44
B10: Planalto | C10: 71000 | D10: 51335 | E10: 58335 | F10: 52060 | G10: 46100 | H10: 49800 | I10: 51845 | L10: Planalto | M10: 1383 | N10: 900 | O10: 1516.7 | P10: 979 | Q10: 991 | R10: 902.6 | S10: 853.9 | V10: Planalto | W10: 19.478873 | X10: 17.531898 | Y10: 25.999829 | Z10: 18.805225 | AA10: 21.496746 | AB10: 18.124498 | AC10: 16.470248
B11: Atlântico | F11: 0 | L11: Atlântico | V11: Atlântico
B12: CENTRO-OESTE | C12: 5950 | D12: 6932 | E12: 6135 | F12: 5733 | G12: 6193 | H12: 5371 | I12: 5923 | L12: CENTRO-OESTE | M12: 196.3 | N12: 249.3 | O12: 247.8 | P12: 231.6 | Q12: 277.7 | R12: 201.8 | S12: 263.5 | V12: CENTRO-OESTE | W12: 32.991597 | X12: 35.963647 | Y12: 40.391198 | Z12: 40.397698 | AA12: 44.840949 | AB12: 37.572147 | AC12: 44.487591
B13: MT | C13: 45 | D13: 0 | E13: 0 | F13: 0 | G13: 0 | H13: 0 | I13: 0 | L13: MT | M13: 0.9 | N13: 0 | O13: 0 | P13: 0 | Q13: 0 | R13: 0 | S13: 0 | V13: MT
B14: GO | C14: 5905 | D14: 6932 | E14: 6135 | F14: 5733 | G14: 6193 | H14: 5371 | I14: 5923 | L14: GO | M14: 195.4 | N14: 249.3 | O14: 247.8 | P14: 231.6 | Q14: 277.7 | R14: 201.8 | S14: 263.5 | V14: GO | W14: 33.090601 | X14: 35.963647 | Y14: 40.391198 | Z14: 40.397698 | AA14: 44.840949 | AB14: 37.572147 | AC14: 44.487591
B15: SUDESTE | C15: 1366798 | D15: 1339448 | E15: 1402066.4 | F15: 1331251 | G15: 1361617.4 | H15: 1396952 | I15: 1427722 | L15: SUDESTE | M15: 44369.4 | N15: 31821.91 | O15: 45654.004 | P15: 29036.9 | Q15: 30614.4 | R15: 36846.1 | S15: 40026 | V15: SUDESTE | W15: 32.462295 | X15: 23.757481 | Y15: 32.561943 | Z15: 21.811739 | AA15: 22.483849 | AB15: 26.376067 | AC15: 28.03487
B16: MG | C16: 995584 | D16: 974269 | E16: 1032280.4 | F16: 970934 | G16: 1008048 | H16: 1073368 | I16: 1101692 | L16: MG | M16: 32970.1 | N16: 24235.41 | O16: 34337.304 | P16: 21858.9 | Q16: 21570.1 | R16: 28650.4 | S16: 29836.4 | V16: MG | W16: 33.116342 | X16: 24.875481 | Y16: 33.263545 | Z16: 22.513271 | AA16: 21.39789 | AB16: 26.692057 | AC16: 27.082342
B17: Sul e Centro-Oeste | C17: 514193 | D17: 496613.4 | E17: 538393.78 | F17: 491785 | G17: 496684 | H17: 533271 | I17: 552669 | L17: Sul e Centro-Oeste | M17: 17896.1 | N17: 13978.79 | O17: 19152.181 | P17: 11751.9 | Q17: 9599.6 | R17: 13513 | S17: 15042.3 | V17: Sul e Centro-Oeste | W17: 34.804247 | X17: 28.148234 | Y17: 35.572813 | Z17: 23.896418 | AA17: 19.327379 | AB17: 25.339837 | AC17: 27.217557
B18: Triângulo, Alto Paranaiba e Noroeste | C18: 189183 | D18: 185688.2 | E18: 193826.59 | F18: 189604 | G18: 181703 | H18: 199471 | I18: 195258 | L18: Triângulo, Alto Paranaiba e Noroeste | M18: 7138 | N18: 4591.91 | O18: 6000.7954 | P18: 4777.5 | Q18: 4198.5 | R18: 7588.6 | S18: 5592.8 | V18: Triângulo, Alto Paranaiba e Noroeste | W18: 37.730663 | X18: 24.729143 | Y18: 30.959609 | Z18: 25.197253 | AA18: 23.106388 | AB18: 38.043625 | AC18: 28.643129
B19: Zona da Mata, Rio Doce e Central | C19: 270354 | D19: 270373 | E19: 278170 | F19: 266368 | G19: 306351 | H19: 315548 | I19: 328631 | L19: Zona da Mata, Rio Doce e Central | M19: 7309.5 | N19: 5147.37 | O19: 8589.625 | P19: 4735.5 | Q19: 7104.6 | R19: 6785.7 | S19: 8303.9 | V19: Zona da Mata, Rio Doce e Central | W19: 27.036774 | X19: 19.038033 | Y19: 30.879049 | Z19: 17.778036 | AA19: 23.191046 | AB19: 21.504494 | AC19: 25.268158
B20: Norte, Jequitinhonha e Mucuri | C20: 21854 | D20: 21594.4 | E20: 21890 | F20: 23177 | G20: 23310 | H20: 25078 | I20: 25134 | L20: Norte, Jequitinhonha e Mucuri | M20: 626.5 | N20: 517.34 | O20: 594.703 | P20: 594 | Q20: 667.4 | R20: 763.1 | S20: 897.4 | V20: Norte, Jequitinhonha e Mucuri | W20: 28.667521 | X20: 23.957137 | Y20: 27.167794 | Z20: 25.628856 | AA20: 28.631489 | AB20: 30.429061 | AC20: 35.704623
B21: ES | C21: 156603 | D21: 152097 | E21: 156294 | F21: 151584 | G21: 143305 | H21: 130839 | I21: 128363 | L21: ES | M21: 4751 | N21: 3002 | O21: 4765 | P21: 2945 | Q21: 4363 | R21: 2859 | S21: 4252 | V21: ES | W21: 30.337861 | X21: 19.737404 | Y21: 30.487415 | Z21: 19.428172 | AA21: 30.445553 | AB21: 21.851283 | AC21: 33.12481
B22: RJ | C22: 12030 | D22: 11713 | E22: 11969 | F22: 10552 | G22: 10474.4 | H22: 11197 | I22: 11526 | L22: RJ | M22: 346 | N22: 245 | O22: 371 | P22: 224 | Q22: 294.3 | R22: 306 | S22: 330.6 | V22: RJ | W22: 28.76143 | X22: 20.91693 | Y22: 30.996742 | Z22: 21.228203 | AA22: 28.097075 | AB22: 27.328749 | AC22: 28.682978
B23: SP | C23: 202581 | D23: 201369 | E23: 201523 | F23: 198181 | G23: 199790 | H23: 181548 | I23: 186141 | L23: SP | M23: 6302.3 | N23: 4339.5 | O23: 6180.7 | P23: 4009 | Q23: 4387 | R23: 5030.7 | S23: 5607 | V23: SP | W23: 31.110025 | X23: 21.54999 | Y23: 30.669948 | Z23: 20.228983 | AA23: 21.958056 | AB23: 27.710027 | AC23: 30.122327
B24: SUL | C24: 37500 | D24: 36900 | E24: 34389 | F24: 33070 | G24: 27109 | H24: 25826 | I24: 25676 | L24: SUL | M24: 1000 | N24: 953 | O24: 967.5 | P24: 876.3 | Q24: 497.9 | R24: 718.5 | S24: 706.3 | V24: SUL | W24: 26.666667 | X24: 25.826558 | Y24: 28.133996 | Z24: 26.498337 | AA24: 18.366594 | AB24: 27.820801 | AC24: 27.508179
B25: PR | C25: 37500 | D25: 36900 | E25: 34389 | F25: 33070 | G25: 27109 | H25: 25826 | I25: 25676 | L25: PR | M25: 1000 | N25: 953 | O25: 967.5 | P25: 876.3 | Q25: 497.9 | R25: 718.5 | S25: 706.3 | V25: PR | W25: 26.666667 | X25: 25.826558 | Y25: 28.133996 | Z25: 26.498337 | AA25: 18.366594 | AB25: 27.820801 | AC25: 27.508179
... B29: BRASIL | C29: 1497059 | D29: 1449802 | E29: 1513273.4 | F29: 1433529 | G29: 1452577.4 | H29: 1485966 | I29: 1519215 | L29: BRASIL | M29: 47483.9 | N29: 34296.31 | O29: 48737.204 | P29: 31437.3 | Q29: 32720.8 | R29: 38904.9 | S29: 42106.7 | V29: BRASIL | W29: 31.718122 | X29: 23.655858 | Y29: 32.206477 | Z29: 21.930006 | AA29: 22.526029 | AB29: 26.181555 | AC29: 27.71609
D62: AREA IN DEVELOPMENT (ha)
B63: Region | C63: 2018 | D63: 2019 | E63: 2020 | F63: 2021 | G63: 2022 | H63: 2023 | I63: 2024
B64: NORDESTE | C64: 4587 | D64: 9500 | E64: 7000 | F64: 10649 | G64: 15800 | H64: 14985 | I64: 12500
B65: BA | C65: 4587 | D65: 9500 | E65: 7000 | F65: 10649 | G65: 15800 | H65: 14985 | I65: 12500
B66: Cerrado | C66: 937 | D66: 2300 | E66: 1000 | F66: 1489 | G66: 1400 | H66: 2240 | I66: 1800
B67: Planalto | C67: 3650 | D67: 7200 | E67: 6000 | F67: 7200 | G67: 14400 | H67: 12745 | I67: 10700
B68: Atlântico | C68: 0 | D68: 0 | E68: 0 | F68: 1960 | G68: 0 | H68: 0 | I68: 0
B69: CENTRO-OESTE | C69: 2155 | D69: 1300 | E69: 1572 | F69: 1770 | G69: 826 | H69: 1793 | I69: 1272
B70: MT | C70: 10 | D70: 0 | E70: 0 | F70: 330 | G70: 0 | H70: 0 | I70: 0
B71: GO | C71: 2145 | D71: 1300 | E71: 1572 | F71: 1440 | G71: 826 | H71: 1793 | I71: 1272
B72: SUDESTE | C72: 241689 | D72: 270007 | E72: 233205.54 | F72: 399015 | G72: 344198 | H72: 296961 | I72: 289177
B73: MG | C73: 214392 | D73: 244829 | E73: 204357.54 | F73: 319065 | G73: 315228 | H73: 265043 | I73: 258796
B74: Sul e Centro-Oeste | C74: 118186 | D74: 155249 | E74: 129468.16 | F74: 175605 | G74: 186550 | H74: 159202 | I74: 150484
... B86: BRASIL | C86: 252345 | D86: 283216 | E86: 244620.54 | F86: 419513 | G86: 363320 | H86: 317044 | I86: 306254

Sheet Conilon
L1: Conilon
D5: AREA IN PRODUCTION (ha) | N5: Production (k Bags) | X5: Productivity (sc/ha)
B6: Region | C6: 2018 | D6: 2019 | E6: 2020 | F6: 2021 | G6: 2022 | H6: 2023 | I6: 2024 | L6: Region | M6: 2018 | N6: 2019 | O6: 2020 | P6: 2021 | Q6: 2022 | R6: 2023 | S6: 2024 | V6: Region | W6: 2018 | X6: 2019 | Y6: 2020 | Z6: 2021 | AA6: 2022 | AB6: 2023 | AC6: 2024
B7: NORTE | C7: 63879 | D7: 62729 | E7: 65714 | F7: 66191 | G7: 64977 | H7: 61164.9 | I7: 54350.3 | L7: NORTE | M7: 1978.3 | N7: 2198.7 | O7: 2489.6 | P7: 2307.7 | Q7: 2800.5 | R7: 3054.3 | S7: 2749.7 | V7: NORTE | W7: 30.969489 | X7: 35.050774 | Y7: 38.46057 | Z7: 34.864256 | AA7: 43.099866 | AB7: 49.935502 | AC7: 50.592177
B8: RO | C8: 63879 | D8: 62729 | E8: 63569 | F8: 63569 | G8: 64977 | H8: 60621 | I8: 53792 | L8: RO | M8: 1978.3 | N8: 2198.7 | O8: 2444.9 | P8: 2263.1 | Q8: 2800.5 | R8: 3041.4 | S8: 2732.6 | V8: RO | W8: 30.969489 | X8: 35.050774 | Y8: 38.46057 | Z8: 35.600686 | AA8: 43.099866 | AB8: 50.170733 | AC8: 50.799375
B9: AM | E9: 2145 | F9: 2622 | H9: 543.9 | I9: 558.3 | L9: AM | O9: 44.7 | P9: 44.6 | Q9: 0 | R9: 12.9 | S9: 17.1 | V9: AM | Y9: 20.839161 | Z9: 17.009916 | AB9: 23.717595 | AC9: 30.628694
H10: 0 | AB10: 0 | AC10: 0
B11: NORDESTE | C11: 47700 | D11: 37000 | E11: 39250 | F11: 40000 | G11: 40280 | H11: 42860 | I11: 44330 | L11: NORDESTE | M11: 2670 | N11: 1800 | O11: 2120 | P11: 2240 | Q11: 2333 | R11: 2289.1 | S11: 2481.9 | V11: NORDESTE | W11: 55.974843 | X11: 48.648649 | Y11: 54.012739 | Z11: 56 | AA11: 57.919563 | AB11: 53.408773 | AC11: 55.986916
B12: BA | C12: 47700 | D12: 37000 | E12: 39250 | F12: 40000 | G12: 40280 | H12: 42860 | I12: 44330 | L12: BA | M12: 2670 | N12: 1800 | O12: 2120 | P12: 2240 | Q12: 2333 | R12: 2289.1 | S12: 2481.9 | V12: BA | W12: 55.974843 | X12: 48.648649 | Y12: 54.012739 | Z12: 56 | AA12: 57.919563 | AB12: 53.408773 | AC12: 55.986916
B13: Cerrado | L13: Cerrado | V13: Cerrado
B14: Planalto | L14: Planalto | V14: Planalto
B15: Atlântico | C15: 47700 | D15: 37000 | E15: 39250 | F15: 40000 | G15: 40280 | H15: 42860 | I15: 44330 | L15: Atlântico | M15: 2670 | N15: 1800 | O15: 2120 | P15: 2240 | Q15: 2333 | R15: 2289.1 | S15: 2481.9 | V15: Atlântico | W15: 55.974843 | X15: 48.648649 | Y15: 54.012739 | Z15: 56 | AA15: 57.919563 | AB15: 53.408773 | AC15: 55.986916
B16: CENTRO-OESTE | C16: 9265 | D16: 8422 | E16: 9602 | F16: 10824 | G16: 11052 | H16: 11499 | I16: 11608 | L16: CENTRO-OESTE | M16: 103.3 | N16: 121.4 | O16: 158.4 | P16: 194.2 | Q16: 227.9 | R16: 260.3 | S16: 270.8 | V16: CENTRO-OESTE | W16: 11.149487 | X16: 14.414628 | Y16: 16.496563 | Z16: 17.941611 | AA16: 20.620702 | AB16: 22.636751 | AC16: 23.328739
B17: MT | C17: 9265 | D17: 8422 | E17: 9602 | F17: 10824 | G17: 11052 | H17: 11499 | I17: 11608 | L17: MT | M17: 103.3 | N17: 121.4 | O17: 157.1 | P17: 195.5 | Q17: 227.9 | R17: 260.3 | S17: 270.8 | V17: MT | W17: 11.149487 | X17: 14.414628 | Y17: 16.496563 | Z17: 18.061715 | AA17: 20.620702 | AB17: 22.636751 | AC17: 23.328739
B18: GO | L18: GO | V18: GO
B19: SUDESTE | C19: 244334 | D19: 251262 | E19: 253105 | F19: 257373 | G19: 269110 | H19: 271000 | I19: 272049 | L19: SUDESTE | M19: 9378.3 | N19: 10814.2 | O19: 9502.808 | P19: 11504.4 | Q19: 12748 | R19: 10510.5 | S19: 11153.9 | V19: SUDESTE | W19: 38.383115 | X19: 43.039536 | Y19: 37.544924 | Z19: 44.699327 | AA19: 47.370964 | AB19: 38.784133 | AC19: 40.999599
B20: MG | C20: 13011 | D20: 9457 | E20: 9112 | F20: 8515 | G20: 9936 | H20: 9079 | I20: 9061 | L20: MG | M20: 390.3 | N20: 318.2 | O20: 309.808 | P20: 283.4 | Q20: 390 | R20: 355.5 | S20: 344.9 | V20: MG | W20: 29.997694 | X20: 33.647034 | Y20: 34 | Z20: 33.282443 | AA20: 39.251208 | AB20: 39.156295 | AC20: 38.064231
B21: Sul e Centro-Oeste | L21: Sul e Centro-Oeste | V21: Sul e Centro-Oeste
B22: Triângulo, Alto Paranaiba e Noroeste | L22: Triângulo, Alto Paranaiba e Noroeste | V22: Triângulo, Alto Paranaiba e Noroeste
B23: Zona da Mata, Rio Doce e Central | C23: 8457 | D23: 6147 | E23: 5923 | F23: 5535 | G23: 6458 | H23: 5901 | I23: 5890 | L23: Zona da Mata, Rio Doce e Central | M23: 253.7 | N23: 206.8 | O23: 201.375 | P23: 184.2 | Q23: 253.5 | R23: 231.1 | S23: 224.2 | V23: Zona da Mata, Rio Doce e Central | W23: 29.998818 | X23: 33.642427 | Y23: 33.998818 | Z23: 33.279133 | AA23: 39.253639 | AB23: 39.162854 | AC23: 38.064516
B24: Norte, Jequitinhonha e Mucuri | C24: 4554 | D24: 3310 | E24: 3189 | F24: 2980 | G24: 3478 | H24: 3178 | I24: 3171 | L24: Norte, Jequitinhonha e Mucuri | M24: 136.6 | N24: 111.4 | O24: 108.433 | P24: 99.2 | Q24: 136.5 | R24: 124.4 | S24: 120.7 | V24: Norte, Jequitinhonha e Mucuri | W24: 29.995608 | X24: 33.655589 | Y24: 34.002195 | Z24: 33.288591 | AA24: 39.246694 | AB24: 39.144116 | AC24: 38.063702
B25: ES | C25: 231323 | D25: 241805 | E25: 243993 | F25: 248858 | G25: 259174 | H25: 261921 | I25: 262988 | L25: ES | M25: 8988 | N25: 10496 | O25: 9193 | P25: 11221 | Q25: 12358 | R25: 10155 | S25: 10809 | V25: ES | W25: 38.854762 | X25: 43.406877 | Y25: 37.67731 | Z25: 45.089971 | AA25: 47.682252 | AB25: 38.771233 | AC25: 41.100735
B26: RJ | L26: RJ | V26: RJ
B27: SP | L27: SP | V27: SP
B28: SUL | L28: SUL | V28: SUL
B29: PR | L29: PR | V29: PR
B30: OUTROS (*) | C30: 2085.8 | D30: 3694 | E30: 1372 | F30: 1428 | G30: 3532 | H30: 1290 | I30: 1264 | L30: OUTROS (*) | M30: 43.7 | N30: 78.7 | O30: 40 | P30: 46.2 | Q30: 45.2 | R30: 53.2 | S30: 50.8 | V30: OUTROS (*) | W30: 20.951194 | X30: 21.304819 | Y30: 29.154519 | Z30: 32.352941 | AA30: 32.6 | AB30: 41.24031 | AC30: 40.189873
B31: NORTE/NORDESTE | C31: 111579 | D31: 99729 | E31: 104964 | F31: 106191 | G31: 105257 | H31: 104024.9 | I31: 98680.3 | L31: NORTE/NORDESTE | M31: 4648.3 | N31: 3998.7 | O31: 4609.6 | P31: 4547.7 | Q31: 5178.2 | R31: 5343.4 | S31: 5231.6 | V31: NORTE/NORDESTE | W31: 41.659273 | X31: 40.095659 | Y31: 44.397436 | Z31: 42.825663 | AA31: 48.213255 | AB31: 51.366548 | AC31: 53.015648
B32: CENTRO-SUL | C32: 253599 | D32: 259684 | E32: 262707 | F32: 268197 | G32: 280162 | H32: 282499 | I32: 283657 | L32: CENTRO-SUL | M32: 9481.6 | N32: 10935.6 | O32: 9661.208 | P32: 11698.6 | Q32: 12975.9 | R32: 10770.8 | S32: 11424.7 | V32: CENTRO-SUL | W32: 37.38816 | X32: 42.111181 | Y32: 36.775602 | Z32: 43.619429 | AA32: 46.315703 | AB32: 38.126861 | AC32: 40.276461
B33: BRASIL | C33: 367263.8 | D33: 363107 | E33: 369043 | F33: 375816 | G33: 388951 | H33: 387813.9 | I33: 383601.3 | L33: BRASIL | M33: 14173.6 | N33: 15013 | O33: 14310.808 | P33: 16292.5 | Q33: 18199.3 | R33: 16167.4 | S33: 16707.1 | V33: BRASIL | W33: 38.592423 | X33: 41.345939 | Y33: 38.778159 | Z33: 43.352332 | AA33: 46.8 | AB33: 41.688552 | AC33: 43.553293
D68: AREA IN Development (ha)
B69: Region | C69: 2018 | D69: 2019 | E69: 2020 | F69: 2021 | G69: 2022 | H69: 2023 | I69: 2024
B70: NORTE | C70: 9538 | D70: 7820 | E70: 6657 | F70: 6107 | G70: 6230 | H70: 5945.8 | I70: 5310.1
B71: RO | C71: 9538 | D71: 7820 | E71: 6180 | F71: 5630 | G71: 6230 | H71: 5800 | I71: 5050
B72: AM | E72: 477 | F72: 477 | H72: 145.8 | I72: 260.1
B74: NORDESTE | C74: 2900 | D74: 2900 | E74: 1680 | F74: 1960 | G74: 2280 | H74: 2780 | I74: 2290
B75: BA | C75: 2900 | D75: 2900 | E75: 1680 | F75: 1960 | G75: 2280 | H75: 2780 | I75: 2290
B76: Cerrado
B77: Planalto
B78: Atlântico | C78: 2900 | D78: 2900 | E78: 1680 | F78: 1960 | G78: 2280 | H78: 2780 | I78: 2290
...

Sheet Summary
L1: Summary
B5: Total Coffee | L5: Arabica | V5: Conilon
C6: 2018 | D6: 2019 | E6: 2020 | F6: 2021 | G6: 2022 | H6: 2023 | I6: 2024 | M6: 2018 | N6: 2019 | O6: 2020 | P6: 2021 | Q6: 2022 | R6: 2023 | S6: 2024 | W6: 2018 | X6: 2019 | Y6: 2020 | Z6: 2021 | AA6: 2022 | AB6: 2023 | AC6: 2024
B7: Total Area (ha) | C7: ='Total Coffee'!C33 -> 1864322.8 | D7: ='Total Coffee'!D33 -> 1812909 | E7: ='Total Coffee'!E33 -> 1884315.4 | F7: ='Total Coffee'!F33 -> 1809345 | G7: ='Total Coffee'!G33 -> 1841528.4 | H7: ='Total Coffee'!H33 -> 1873779.9 | I7: ='Total Coffee'!I33 -> 1902816.3 | L7: Total Area | M7: =Arabica!C29 -> 1497059 | N7: =Arabica!D29 -> 1449802 | O7: =Arabica!E29 -> 1513273.4 | P7: =Arabica!F29 -> 1433529 | Q7: =Arabica!G29 -> 1452577.4 | R7: =Arabica!H29 -> 1485966 | S7: =Arabica!I29 -> 1519215 | V7: Total Area | W7: =Conilon!C33 -> 367263.8 | X7: =Conilon!D33 -> 363107 | Y7: =Conilon!E33 -> 369043 | Z7: =Conilon!F33 -> 375816 | AA7: =Conilon!G33 -> 388951 | AB7: =Conilon!H33 -> 387813.9 | AC7: =Conilon!I33 -> 383601.3
B8: Production (k Bags) | C8: ='Total Coffee'!M33 -> 61657.5 | D8: ='Total Coffee'!N33 -> 49309.31 | E8: ='Total Coffee'!O33 -> 63077.912 | F8: ='Total Coffee'!P33 -> 47729.8 | G8: ='Total Coffee'!Q33 -> 50920.1 | H8: ='Total Coffee'!R33 -> 55072.3 | I8: ='Total Coffee'!S33 -> 58813.8 | L8: Production | M8: =Arabica!M29 -> 47483.9 | N8: =Arabica!N29 -> 34296.31 | O8: =Arabica!O29 -> 48737.204 | P8: =Arabica!P29 -> 31437.3 | Q8: =Arabica!Q29 -> 32720.8 | R8: =Arabica!R29 -> 38904.9 | S8: =Arabica!S29 -> 42106.7 | V8: Production | W8: =Conilon!M33 -> 14173.6 | X8: =Conilon!N33 -> 15013 | Y8: =Conilon!O33 -> 14310.808 | Z8: =Conilon!P33 -> 16292.5 | AA8: =Conilon!Q33 -> 18199.3 | AB8: =Conilon!R33 -> 16167.4 | AC8: =Conilon!S33 -> 16707.1
B9: Yield (sc/ha) | C9: ='Total Coffee'!W33 -> 33.072331 | D9: ='Total Coffee'!X33 -> 27.198999 | E9: ='Total Coffee'!Y33 -> 33.475242 | F9: ='Total Coffee'!Z33 -> 26.379601 | G9: ='Total Coffee'!AA33 -> 27.650999 | H9: ='Total Coffee'!AB33 -> 29.391019 | I9: ='Total Coffee'!AC33 -> 30.908817 | L9: Yield | M9: =Arabica!W29 -> 31.718122 | N9: =Arabica!X29 -> 23.655858 | O9: =Arabica!Y29 -> 32.206477 | P9: =Arabica!Z29 -> 21.930006 | Q9: =Arabica!AA29 -> 22.526029 | R9: =Arabica!AB29 -> 26.181555 | S9: =Arabica!AC29 -> 27.71609 | V9: Yield | W9: =Conilon!W33 -> 38.592423 | X9: =Conilon!X33 -> 41.345939 | Y9: =Conilon!Y33 -> 38.778159 | Z9: =Conilon!Z33 -> 43.352332 | AA9: =Conilon!AA33 -> 46.8 | AB9: =Conilon!AB33 -> 41.688552 | AC9: =Conilon!AC33 -> 43.553293

Sheet A&R
L1: Arabica vs Conilon
B5: Total Coffee | L5: Arabica | V5: Conilon
C6: 2018 | D6: 2019 | E6: 2020 | F6: 2021 | G6: 2022 | H6: 2023 | I6: 2024 | M6: 2018 | N6: 2019 | O6: 2020 | P6: 2021 | Q6: 2022 | R6: 2023 | S6: 2024 | W6: 2018 | X6: 2019 | Y6: 2020 | Z6: 2021 | AA6: 2022 | AB6: 2023 | AC6: 2024
B7: Total Area (ha) | C7: ='Total Coffee'!C33 -> 1864322.8 | D7: ='Total Coffee'!D33 -> 1812909 | E7: ='Total Coffee'!E33 -> 1884315.4 | F7: ='Total Coffee'!F33 -> 1809345 | G7: ='Total Coffee'!G33 -> 1841528.4 | H7: ='Total Coffee'!H33 -> 1873779.9 | I7: ='Total Coffee'!I33 -> 1902816.3 | L7: Total Area | M7: =Arabica!C29 -> 1497059 | N7: =Arabica!D29 -> 1449802 | O7: =Arabica!E29 -> 1513273.4 | P7: =Arabica!F29 -> 1433529 | Q7: =Arabica!G29 -> 1452577.4 | R7: =Arabica!H29 -> 1485966 | S7: =Arabica!I29 -> 1519215 | V7: Total Area | W7: =Conilon!C33 -> 367263.8 | X7: =Conilon!D33 -> 363107 | Y7: =Conilon!E33 -> 369043 | Z7: =Conilon!F33 -> 375816 | AA7: =Conilon!G33 -> 388951 | AB7: =Conilon!H33 -> 387813.9 | AC7: =Conilon!I33 -> 383601.3
B8: Production (k Bags) | C8: ='Total Coffee'!M33 -> 61657.5 | D8: ='Total Coffee'!N33 -> 49309.31 | E8: ='Total Coffee'!O33 -> 63077.912 | F8: ='Total Coffee'!P33 -> 47729.8 | G8: ='Total Coffee'!Q33 -> 50920.1 | H8: ='Total Coffee'!R33 -> 55072.3 | I8: ='Total Coffee'!S33 -> 58813.8 | L8: Production | M8: =Arabica!M29 -> 47483.9 | N8: =Arabica!N29 -> 34296.31 | O8: =Arabica!O29 -> 48737.204 | P8: =Arabica!P29 -> 31437.3 | Q8: =Arabica!Q29 -> 32720.8 | R8: =Arabica!R29 -> 38904.9 | S8: =Arabica!S29 -> 42106.7 | V8: Production | W8: =Conilon!M33 -> 14173.6 | X8: =Conilon!N33 -> 15013 | Y8: =Conilon!O33 -> 14310.808 | Z8: =Conilon!P33 -> 16292.5 | AA8: =Conilon!Q33 -> 18199.3 | AB8: =Conilon!R33 -> 16167.4 | AC8: =Conilon!S33 -> 16707.1
B9: Yield (sc/ha) | C9: ='Total Coffee'!W33 -> 33.072331 | D9: ='Total Coffee'!X33 -> 27.198999 | E9: ='Total Coffee'!Y33 -> 33.475242 | F9: ='Total Coffee'!Z33 -> 26.379601 | G9: ='Total Coffee'!AA33 -> 27.650999 | H9: ='Total Coffee'!AB33 -> 29.391019 | I9: ='Total Coffee'!AC33 -> 30.908817 | L9: Yield | M9: =Arabica!W29 -> 31.718122 | N9: =Arabica!X29 -> 23.655858 | O9: =Arabica!Y29 -> 32.206477 | P9: =Arabica!Z29 -> 21.930006 | Q9: =Arabica!AA29 -> 22.526029 | R9: =Arabica!AB29 -> 26.181555 | S9: =Arabica!AC29 -> 27.71609 | V9: Yield | W9: =Conilon!W33 -> 38.592423 | X9: =Conilon!X33 -> 41.345939 | Y9: =Conilon!Y33 -> 38.778159 | Z9: =Conilon!Z33 -> 43.352332 | AA9: =Conilon!AA33 -> 46.8 | AB9: =Conilon!AB33 -> 41.688552 | AC9: =Conilon!AC33 -> 43.553293
B12: Total Area ('000 ha) | L12: Production (mn bags) | V12: Productivity (sc/ha)
C13: 2018 | D13: 2019 | E13: 2020 | F13: 2021 | G13: 2022 | H13: 2023 | I13: 2024 | M13: 2018 | N13: 2019 | O13: 2020 | P13: 2021 | Q13: 2022 | R13: 2023 | S13: 2024 | W13: 2018 | X13: 2019 | Y13: 2020 | Z13: 2021 | AA13: 2022 | AB13: 2023 | AC13: 2024
B14: Arabica (Left) | C14: =M7/1000000 -> 1.497059 | D14: =N7/1000000 -> 1.449802 | E14: =O7/1000000 -> 1.5132734 | F14: =P7/1000000 -> 1.433529 | G14: =Q7/1000000 -> 1.4525774 | H14: =R7/1000000 -> 1.485966 | I14: =S7/1000000 -> 1.519215 | L14: Arabica | M14: =M8/1000 -> 47.4839 | N14: =N8/1000 -> 34.29631 | O14: =O8/1000 -> 48.737204 | P14: =P8/1000 -> 31.4373 | Q14: =Q8/1000 -> 32.7208 | R14: =R8/1000 -> 38.9049 | S14: =S8/1000 -> 42.1067 | V14: Arabica | W14: =M9 -> 31.718122 | X14: =N9 -> 23.655858 | Y14: =O9 -> 32.206477 | Z14: =P9 -> 21.930006 | AA14: =Q9 -> 22.526029 | AB14: =R9 -> 26.181555 | AC14: =S9 -> 27.71609
B15: Robusta (Right) | C15: =W7/1000000 -> 0.3672638 | D15: =X7/1000000 -> 0.363107 | E15: =Y7/1000000 -> 0.369043 | F15: =Z7/1000000 -> 0.375816 | G15: =AA7/1000000 -> 0.388951 | H15: =AB7/1000000 -> 0.3878139 | I15: =AC7/1000000 -> 0.3836013 | L15: Robusta | M15: =W8/1000 -> 14.1736 | N15: =X8/1000 -> 15.013 | O15: =Y8/1000 -> 14.310808 | P15: =Z8/1000 -> 16.2925 | Q15: =AA8/1000 -> 18.1993 | R15: =AB8/1000 -> 16.1674 | S15: =AC8/1000 -> 16.7071 | V15: Robusta | W15: =W9 -> 38.592423 | X15: =X9 -> 41.345939 | Y15: =Y9 -> 38.778159 | Z15: =Z9 -> 43.352332 | AA15: =AA9 -> 46.8 | AB15: =AB9 -> 41.688552 | AC15: =AC9 -> 43.553293
