Workbook
Name Slicer_Origin: #N/A

Sheet Pivot
T1: Origin | U1: Brazil
T3: Sum of GBE | U3: Column Labels
T4: Row Labels | U4: 1 | V4: 2 | W4: 3 | X4: 4 | Y4: 5 | Z4: 6 | AA4: 7 | AB4: 8 | AC4: 9 | AD4: 10 | AE4: 11 | AF4: 12 | AG4: Grand Total
T5: 2016 | U5: 2808927.8 | V5: 2938277.5 | W5: 3102405.8 | X5: 2458143.3 | Y5: 2528952.1 | Z5: 2450865.2 | AA5: 1967243.3 | AB5: 3044358.4 | AC5: 3068226 | AD5: 3362927.9 | AE5: 3276941.2 | AF5: 3261882.1 | AG5: 34269151
T6: 2017 | U6: 2646464.4 | V6: 2590825.4 | W6: 2834349.1 | X6: 2240098.3 | Y6: 2602453.4 | Z6: 2191499.2 | AA6: 1873670.7 | AB6: 2610143.6 | AC6: 2441617.9 | AD6: 2901977.5 | AE6: 2965514 | AF6: 3025954.5 | AG6: 30924568
T7: 2018 | U7: 2719936.4 | V7: 2511588.4 | W7: 2698364.4 | X7: 2388754.9 | Y7: 1729254.4 | Z7: 2583614.4 | AA7: 2465428.7 | AB7: 3544383.4 | AC7: 3150780.2 | AD7: 3937859.1 | AE7: 3902855.5 | AF7: 4004539.3 | AG7: 35637359
T8: 2019 | U8: 3470505.8 | V8: 3574654.8 | W8: 3117169.6 | X8: 3267213.7 | Y8: 3886596.1 | Z8: 3102695.8 | AA8: 3390434.2 | AB8: 3368913.6 | AC8: 3495386.6 | AD8: 3670113.2 | AE8: 3281473.3 | AF8: 3072707 | AG8: 40697864
T9: 2020 | U9: 3474087.5 | V9: 3007658.8 | W9: 3493433.1 | X9: 3599225.9 | Y9: 3282032.2 | Z9: 3075571.5 | AA9: 3242242.1 | AB9: 3574279.8 | AC9: 4232364.9 | AD9: 4504376.8 | AE9: 4770005.3 | AF9: 4409066.5 | AG9: 44664344
T10: 2021 | U10: 3657291.2 | V10: 3972949.6 | W10: 3833416.6 | X10: 3575943.7 | Y10: 3443874.4 | Z10: 3210269.5 | AA10: 2813525.2 | AB10: 2859143.3 | AC10: 3291463 | AD10: 3289593.3 | AE10: 3257809 | AF10: 3944334.1 | AG10: 41149613
T11: 2022 | U11: 3468385.6 | V11: 3536274.6 | W11: 3891975.8 | X11: 3016609.1 | Y11: 2961676.3 | Z11: 3125363 | AA11: 2752356.7 | AB11: 2951452.1 | AC11: 3444289.6 | AD11: 3589378.2 | AE11: 3583957.6 | AF11: 3137089.7 | AG11: 39458808
T12: 2023 | U12: 2591523.7 | V12: 2461834.5 | W12: 3166636.1 | X12: 2495688.7 | Y12: 2667981.5 | Z12: 2658586.2 | AA12: 3152174.1 | AB12: 3815631.6 | AC12: 3765915.8 | AD12: 4412709.5 | AE12: 4329650.4 | AF12: 4186199.8 | AG12: 39704532
T13: 2024 | U13: 3998730.6 | V13: 3742175.5 | W13: 4308615.3 | X13: 4276347.5 | Y13: 4446510.6 | Z13: 3770707 | AA13: 3881567 | AB13: 4092677.6 | AC13: 4921683.9 | AD13: 5112274.2 | AE13: 4323717.1 | AF13: 3872441.9 | AG13: 50747448
T14: 2025 | U14: 3770072.6 | V14: 3317751.2 | W14: 3067521.3 | X14: 2851110.3 | Y14: 3054295.4 | Z14: 2608187.6 | AA14: 2898313.2 | AB14: 3244664.7 | AC14: 4040788.4 | AD14: 4261080.6 | AE14: 3650504 | AF14: 3169202.8 | AG14: 39933492
T15: 2026 | U15: 2808075.7 | V15: 2618119.8 | W15: 3058938.6 | AG15: 8485134.1
T16: Grand Total | U16: 35414001 | V16: 34272110 | W16: 36572826 | X16: 30169135 | Y16: 30603626 | Z16: 28777360 | AA16: 28436955 | AB16: 33105648 | AC16: 35852516 | AD16: 39042290 | AE16: 37342427 | AF16: 36083418 | AG16: 4.0567231e+08
U20: 1 | V20: 2 | W20: 3 | X20: 4 | Y20: 5 | Z20: 6 | AA20: 7 | AB20: 8 | AC20: 9 | AD20: 10 | AE20: 11 | AF20: 12
T21: 2016 | U21: =IFERROR(IF(GETPIVOTDATA("GBE",$T$3,"Year",$T21,"Month",U$20)=0,NA(),GETPIVOTDATA("GBE",$T$3,"Year",$T21,"Month",U$20)),NA()) -> 2808927.8 | V21: =IFERROR(IF(GETPIVOTDATA("GBE",$T$3,"Year",$T21,"Month",V$20)=0,NA(),GETPIVOTDATA("GBE",$T$3,"Year",$T21,"Month",V$20)),NA()) -> 2938277.5 | W21: =IFERROR(IF(GETPIVOTDATA("GBE",$T$3,"Year",$T21,"Month",W$20)=0,NA(),GETPIVOTDATA("GBE",$T$3,"Year",$T21,"Month",W$20)),NA()) -> 3102405.8 | X21: =IFERROR(IF(GETPIVOTDATA("GBE",$T$3,"Year",$T21,"Month",X$20)=0,NA(),GETPIVOTDATA("GBE",$T$3,"Year",$T21,"Month",X$20)),NA()) -> 2458143.3 | Y21: =IFERROR(IF(GETPIVOTDATA("GBE",$T$3,"Year",$T21,"Month",Y$20)=0,NA(),GETPIVOTDATA("GBE",$T$3,"Year",$T21,"Month",Y$20)),NA()) -> 2528952.1 | Z21: =IFERROR(IF(GETPIVOTDATA("GBE",$T$3,"Year",$T21,"Month",Z$20)=0,NA(),GETPIVOTDATA("GBE",$T$3,"Year",$T21,"Month",Z$20)),NA()) -> 2450865.2 | AA21: =IFERROR(IF(GETPIVOTDATA("GBE",$T$3,"Year",$T21,"Month",AA$20)=0,NA(),GETPIVOTDATA("GBE",$T$3,"Year",$T21,"Month",AA$20)),NA()) -> 1967243.3 | AB21: =IFERROR(IF(GETPIVOTDATA("GBE",$T$3,"Year",$T21,"Month",AB$20)=0,NA(),GETPIVOTDATA("GBE",$T$3,"Year",$T21,"Month",AB$20)),NA()) -> 3044358.4 | ... AF21: =IFERROR(IF(GETPIVOTDATA("GBE",$T$3,"Year",$T21,"Month",AF$20)=0,NA(),GETPIVOTDATA("GBE",$T$3,"Year",$T21,"Month",AF$20)),NA()) -> 3261882.1
T22: =T21+1 -> 2017 | U22: =IFERROR(IF(GETPIVOTDATA("GBE",$T$3,"Year",$T22,"Month",U$20)=0,NA(),GETPIVOTDATA("GBE",$T$3,"Year",$T22,"Month",U$20)),NA()) -> 2646464.4 | V22: =IFERROR(IF(GETPIVOTDATA("GBE",$T$3,"Year",$T22,"Month",V$20)=0,NA(),GETPIVOTDATA("GBE",$T$3,"Year",$T22,"Month",V$20)),NA()) -> 2590825.4 | W22: =IFERROR(IF(GETPIVOTDATA("GBE",$T$3,"Year",$T22,"Month",W$20)=0,NA(),GETPIVOTDATA("GBE",$T$3,"Year",$T22,"Month",W$20)),NA()) -> 2834349.1 | X22: =IFERROR(IF(GETPIVOTDATA("GBE",$T$3,"Year",$T22,"Month",X$20)=0,NA(),GETPIVOTDATA("GBE",$T$3,"Year",$T22,"Month",X$20)),NA()) -> 2240098.3 | Y22: =IFERROR(IF(GETPIVOTDATA("GBE",$T$3,"Year",$T22,"Month",Y$20)=0,NA(),GETPIVOTDATA("GBE",$T$3,"Year",$T22,"Month",Y$20)),NA()) -> 2602453.4 | Z22: =IFERROR(IF(GETPIVOTDATA("GBE",$T$3,"Year",$T22,"Month",Z$20)=0,NA(),GETPIVOTDATA("GBE",$T$3,"Year",$T22,"Month",Z$20)),NA()) -> 2191499.2 | AA22: =IFERROR(IF(GETPIVOTDATA("GBE",$T$3,"Year",$T22,"Month",AA$20)=0,NA(),GETPIVOTDATA("GBE",$T$3,"Year",$T22,"Month",AA$20)),NA()) -> 1873670.7 | AB22: =IFERROR(IF(GETPIVOTDATA("GBE",$T$3,"Year",$T22,"Month",AB$20)=0,NA(),GETPIVOTDATA("GBE",$T$3,"Year",$T22,"Month",AB$20)),NA()) -> 2610143.6 | ... AF22: =IFERROR(IF(GETPIVOTDATA("GBE",$T$3,"Year",$T22,"Month",AF$20)=0,NA(),GETPIVOTDATA("GBE",$T$3,"Year",$T22,"Month",AF$20)),NA()) -> 3025954.5
T23: =T22+1 -> 2018 | U23: =IFERROR(IF(GETPIVOTDATA("GBE",$T$3,"Year",$T23,"Month",U$20)=0,NA(),GETPIVOTDATA("GBE",$T$3,"Year",$T23,"Month",U$20)),NA()) -> 2719936.4 | V23: =IFERROR(IF(GETPIVOTDATA("GBE",$T$3,"Year",$T23,"Month",V$20)=0,NA(),GETPIVOTDATA("GBE",$T$3,"Year",$T23,"Month",V$20)),NA()) -> 2511588.4 | W23: =IFERROR(IF(GETPIVOTDATA("GBE",$T$3,"Year",$T23,"Month",W$20)=0,NA(),GETPIVOTDATA("GBE",$T$3,"Year",$T23,"Month",W$20)),NA()) -> 2698364.4 | X23: =IFERROR(IF(GETPIVOTDATA("GBE",$T$3,"Year",$T23,"Month",X$20)=0,NA(),GETPIVOTDATA("GBE",$T$3,"Year",$T23,"Month",X$20)),NA()) -> 2388754.9 | Y23: =IFERROR(IF(GETPIVOTDATA("GBE",$T$3,"Year",$T23,"Month",Y$20)=0,NA(),GETPIVOTDATA("GBE",$T$3,"Year",$T23,"Month",Y$20)),NA()) -> 1729254.4 | Z23: =IFERROR(IF(GETPIVOTDATA("GBE",$T$3,"Year",$T23,"Month",Z$20)=0,NA(),GETPIVOTDATA("GBE",$T$3,"Year",$T23,"Month",Z$20)),NA()) -> 2583614.4 | AA23: =IFERROR(IF(GETPIVOTDATA("GBE",$T$3,"Year",$T23,"Month",AA$20)=0,NA(),GETPIVOTDATA("GBE",$T$3,"Year",$T23,"Month",AA$20)),NA()) -> 2465428.7 | AB23: =IFERROR(IF(GETPIVOTDATA("GBE",$T$3,"Year",$T23,"Month",AB$20)=0,NA(),GETPIVOTDATA("GBE",$T$3,"Year",$T23,"Month",AB$20)),NA()) -> 3544383.4 | ... AF23: =IFERROR(IF(GETPIVOTDATA("GBE",$T$3,"Year",$T23,"Month",AF$20)=0,NA(),GETPIVOTDATA("GBE",$T$3,"Year",$T23,"Month",AF$20)),NA()) -> 4004539.3
T24: =T23+1 -> 2019 | U24: =IFERROR(IF(GETPIVOTDATA("GBE",$T$3,"Year",$T24,"Month",U$20)=0,NA(),GETPIVOTDATA("GBE",$T$3,"Year",$T24,"Month",U$20)),NA()) -> 3470505.8 | V24: =IFERROR(IF(GETPIVOTDATA("GBE",$T$3,"Year",$T24,"Month",V$20)=0,NA(),GETPIVOTDATA("GBE",$T$3,"Year",$T24,"Month",V$20)),NA()) -> 3574654.8 | W24: =IFERROR(IF(GETPIVOTDATA("GBE",$T$3,"Year",$T24,"Month",W$20)=0,NA(),GETPIVOTDATA("GBE",$T$3,"Year",$T24,"Month",W$20)),NA()) -> 3117169.6 | X24: =IFERROR(IF(GETPIVOTDATA("GBE",$T$3,"Year",$T24,"Month",X$20)=0,NA(),GETPIVOTDATA("GBE",$T$3,"Year",$T24,"Month",X$20)),NA()) -> 3267213.7 | Y24: =IFERROR(IF(GETPIVOTDATA("GBE",$T$3,"Year",$T24,"Month",Y$20)=0,NA(),GETPIVOTDATA("GBE",$T$3,"Year",$T24,"Month",Y$20)),NA()) -> 3886596.1 | Z24: =IFERROR(IF(GETPIVOTDATA("GBE",$T$3,"Year",$T24,"Month",Z$20)=0,NA(),GETPIVOTDATA("GBE",$T$3,"Year",$T24,"Month",Z$20)),NA()) -> 3102695.8 | AA24: =IFERROR(IF(GETPIVOTDATA("GBE",$T$3,"Year",$T24,"Month",AA$20)=0,NA(),GETPIVOTDATA("GBE",$T$3,"Year",$T24,"Month",AA$20)),NA()) -> 3390434.2 | AB24: =IFERROR(IF(GETPIVOTDATA("GBE",$T$3,"Year",$T24,"Month",AB$20)=0,NA(),GETPIVOTDATA("GBE",$T$3,"Year",$T24,"Month",AB$20)),NA()) -> 3368913.6 | ... AF24: =IFERROR(IF(GETPIVOTDATA("GBE",$T$3,"Year",$T24,"Month",AF$20)=0,NA(),GETPIVOTDATA("GBE",$T$3,"Year",$T24,"Month",AF$20)),NA()) -> 3072707
T25: =T24+1 -> 2020 | U25: =IFERROR(IF(GETPIVOTDATA("GBE",$T$3,"Year",$T25,"Month",U$20)=0,NA(),GETPIVOTDATA("GBE",$T$3,"Year",$T25,"Month",U$20)),NA()) -> 3474087.5 | V25: =IFERROR(IF(GETPIVOTDATA("GBE",$T$3,"Year",$T25,"Month",V$20)=0,NA(),GETPIVOTDATA("GBE",$T$3,"Year",$T25,"Month",V$20)),NA()) -> 3007658.8 | W25: =IFERROR(IF(GETPIVOTDATA("GBE",$T$3,"Year",$T25,"Month",W$20)=0,NA(),GETPIVOTDATA("GBE",$T$3,"Year",$T25,"Month",W$20)),NA()) -> 3493433.1 | X25: =IFERROR(IF(GETPIVOTDATA("GBE",$T$3,"Year",$T25,"Month",X$20)=0,NA(),GETPIVOTDATA("GBE",$T$3,"Year",$T25,"Month",X$20)),NA()) -> 3599225.9 | Y25: =IFERROR(IF(GETPIVOTDATA("GBE",$T$3,"Year",$T25,"Month",Y$20)=0,NA(),GETPIVOTDATA("GBE",$T$3,"Year",$T25,"Month",Y$20)),NA()) -> 3282032.2 | Z25: =IFERROR(IF(GETPIVOTDATA("GBE",$T$3,"Year",$T25,"Month",Z$20)=0,NA(),GETPIVOTDATA("GBE",$T$3,"Year",$T25,"Month",Z$20)),NA()) -> 3075571.5 | AA25: =IFERROR(IF(GETPIVOTDATA("GBE",$T$3,"Year",$T25,"Month",AA$20)=0,NA(),GETPIVOTDATA("GBE",$T$3,"Year",$T25,"Month",AA$20)),NA()) -> 3242242.1 | AB25: =IFERROR(IF(GETPIVOTDATA("GBE",$T$3,"Year",$T25,"Month",AB$20)=0,NA(),GETPIVOTDATA("GBE",$T$3,"Year",$T25,"Month",AB$20)),NA()) -> 3574279.8 | ... AF25: =IFERROR(IF(GETPIVOTDATA("GBE",$T$3,"Year",$T25,"Month",AF$20)=0,NA(),GETPIVOTDATA("GBE",$T$3,"Year",$T25,"Month",AF$20)),NA()) -> 4409066.5
T26: =T25+1 -> 2021 | U26: =IFERROR(IF(GETPIVOTDATA("GBE",$T$3,"Year",$T26,"Month",U$20)=0,NA(),GETPIVOTDATA("GBE",$T$3,"Year",$T26,"Month",U$20)),NA()) -> 3657291.2 | V26: =IFERROR(IF(GETPIVOTDATA("GBE",$T$3,"Year",$T26,"Month",V$20)=0,NA(),GETPIVOTDATA("GBE",$T$3,"Year",$T26,"Month",V$20)),NA()) -> 3972949.6 | W26: =IFERROR(IF(GETPIVOTDATA("GBE",$T$3,"Year",$T26,"Month",W$20)=0,NA(),GETPIVOTDATA("GBE",$T$3,"Year",$T26,"Month",W$20)),NA()) -> 3833416.6 | X26: =IFERROR(IF(GETPIVOTDATA("GBE",$T$3,"Year",$T26,"Month",X$20)=0,NA(),GETPIVOTDATA("GBE",$T$3,"Year",$T26,"Month",X$20)),NA()) -> 3575943.7 | Y26: =IFERROR(IF(GETPIVOTDATA("GBE",$T$3,"Year",$T26,"Month",Y$20)=0,NA(),GETPIVOTDATA("GBE",$T$3,"Year",$T26,"Month",Y$20)),NA()) -> 3443874.4 | Z26: =IFERROR(IF(GETPIVOTDATA("GBE",$T$3,"Year",$T26,"Month",Z$20)=0,NA(),GETPIVOTDATA("GBE",$T$3,"Year",$T26,"Month",Z$20)),NA()) -> 3210269.5 | AA26: =IFERROR(IF(GETPIVOTDATA("GBE",$T$3,"Year",$T26,"Month",AA$20)=0,NA(),GETPIVOTDATA("GBE",$T$3,"Year",$T26,"Month",AA$20)),NA()) -> 2813525.2 | AB26: =IFERROR(IF(GETPIVOTDATA("GBE",$T$3,"Year",$T26,"Month",AB$20)=0,NA(),GETPIVOTDATA("GBE",$T$3,"Year",$T26,"Month",AB$20)),NA()) -> 2859143.3 | ... AF26: =IFERROR(IF(GETPIVOTDATA("GBE",$T$3,"Year",$T26,"Month",AF$20)=0,NA(),GETPIVOTDATA("GBE",$T$3,"Year",$T26,"Month",AF$20)),NA()) -> 3944334.1
T27: =T26+1 -> 2022 | U27: =IFERROR(IF(GETPIVOTDATA("GBE",$T$3,"Year",$T27,"Month",U$20)=0,NA(),GETPIVOTDATA("GBE",$T$3,"Year",$T27,"Month",U$20)),NA()) -> 3468385.6 | V27: =IFERROR(IF(GETPIVOTDATA("GBE",$T$3,"Year",$T27,"Month",V$20)=0,NA(),GETPIVOTDATA("GBE",$T$3,"Year",$T27,"Month",V$20)),NA()) -> 3536274.6 | W27: =IFERROR(IF(GETPIVOTDATA("GBE",$T$3,"Year",$T27,"Month",W$20)=0,NA(),GETPIVOTDATA("GBE",$T$3,"Year",$T27,"Month",W$20)),NA()) -> 3891975.8 | X27: =IFERROR(IF(GETPIVOTDATA("GBE",$T$3,"Year",$T27,"Month",X$20)=0,NA(),GETPIVOTDATA("GBE",$T$3,"Year",$T27,"Month",X$20)),NA()) -> 3016609.1 | Y27: =IFERROR(IF(GETPIVOTDATA("GBE",$T$3,"Year",$T27,"Month",Y$20)=0,NA(),GETPIVOTDATA("GBE",$T$3,"Year",$T27,"Month",Y$20)),NA()) -> 2961676.3 | Z27: =IFERROR(IF(GETPIVOTDATA("GBE",$T$3,"Year",$T27,"Month",Z$20)=0,NA(),GETPIVOTDATA("GBE",$T$3,"Year",$T27,"Month",Z$20)),NA()) -> 3125363 | AA27: =IFERROR(IF(GETPIVOTDATA("GBE",$T$3,"Year",$T27,"Month",AA$20)=0,NA(),GETPIVOTDATA("GBE",$T$3,"Year",$T27,"Month",AA$20)),NA()) -> 2752356.7 | AB27: =IFERROR(IF(GETPIVOTDATA("GBE",$T$3,"Year",$T27,"Month",AB$20)=0,NA(),GETPIVOTDATA("GBE",$T$3,"Year",$T27,"Month",AB$20)),NA()) -> 2951452.1 | ... AF27: =IFERROR(IF(GETPIVOTDATA("GBE",$T$3,"Year",$T27,"Month",AF$20)=0,NA(),GETPIVOTDATA("GBE",$T$3,"Year",$T27,"Month",AF$20)),NA()) -> 3137089.7
T28: =T27+1 -> 2023 | U28: =IFERROR(IF(GETPIVOTDATA("GBE",$T$3,"Year",$T28,"Month",U$20)=0,NA(),GETPIVOTDATA("GBE",$T$3,"Year",$T28,"Month",U$20)),NA()) -> 2591523.7 | V28: =IFERROR(IF(GETPIVOTDATA("GBE",$T$3,"Year",$T28,"Month",V$20)=0,NA(),GETPIVOTDATA("GBE",$T$3,"Year",$T28,"Month",V$20)),NA()) -> 2461834.5 | W28: =IFERROR(IF(GETPIVOTDATA("GBE",$T$3,"Year",$T28,"Month",W$20)=0,NA(),GETPIVOTDATA("GBE",$T$3,"Year",$T28,"Month",W$20)),NA()) -> 3166636.1 | X28: =IFERROR(IF(GETPIVOTDATA("GBE",$T$3,"Year",$T28,"Month",X$20)=0,NA(),GETPIVOTDATA("GBE",$T$3,"Year",$T28,"Month",X$20)),NA()) -> 2495688.7 | Y28: =IFERROR(IF(GETPIVOTDATA("GBE",$T$3,"Year",$T28,"Month",Y$20)=0,NA(),GETPIVOTDATA("GBE",$T$3,"Year",$T28,"Month",Y$20)),NA()) -> 2667981.5 | Z28: =IFERROR(IF(GETPIVOTDATA("GBE",$T$3,"Year",$T28,"Month",Z$20)=0,NA(),GETPIVOTDATA("GBE",$T$3,"Year",$T28,"Month",Z$20)),NA()) -> 2658586.2 | AA28: =IFERROR(IF(GETPIVOTDATA("GBE",$T$3,"Year",$T28,"Month",AA$20)=0,NA(),GETPIVOTDATA("GBE",$T$3,"Year",$T28,"Month",AA$20)),NA()) -> 3152174.1 | AB28: =IFERROR(IF(GETPIVOTDATA("GBE",$T$3,"Year",$T28,"Month",AB$20)=0,NA(),GETPIVOTDATA("GBE",$T$3,"Year",$T28,"Month",AB$20)),NA()) -> 3815631.6 | ... AF28: =IFERROR(IF(GETPIVOTDATA("GBE",$T$3,"Year",$T28,"Month",AF$20)=0,NA(),GETPIVOTDATA("GBE",$T$3,"Year",$T28,"Month",AF$20)),NA()) -> 4186199.8
T29: =T28+1 -> 2024 | U29: =IFERROR(IF(GETPIVOTDATA("GBE",$T$3,"Year",$T29,"Month",U$20)=0,NA(),GETPIVOTDATA("GBE",$T$3,"Year",$T29,"Month",U$20)),NA()) -> 3998730.6 | V29: =IFERROR(IF(GETPIVOTDATA("GBE",$T$3,"Year",$T29,"Month",V$20)=0,NA(),GETPIVOTDATA("GBE",$T$3,"Year",$T29,"Month",V$20)),NA()) -> 3742175.5 | W29: =IFERROR(IF(GETPIVOTDATA("GBE",$T$3,"Year",$T29,"Month",W$20)=0,NA(),GETPIVOTDATA("GBE",$T$3,"Year",$T29,"Month",W$20)),NA()) -> 4308615.3 | X29: =IFERROR(IF(GETPIVOTDATA("GBE",$T$3,"Year",$T29,"Month",X$20)=0,NA(),GETPIVOTDATA("GBE",$T$3,"Year",$T29,"Month",X$20)),NA()) -> 4276347.5 | Y29: =IFERROR(IF(GETPIVOTDATA("GBE",$T$3,"Year",$T29,"Month",Y$20)=0,NA(),GETPIVOTDATA("GBE",$T$3,"Year",$T29,"Month",Y$20)),NA()) -> 4446510.6 | Z29: =IFERROR(IF(GETPIVOTDATA("GBE",$T$3,"Year",$T29,"Month",Z$20)=0,NA(),GETPIVOTDATA("GBE",$T$3,"Year",$T29,"Month",Z$20)),NA()) -> 3770707 | AA29: =IFERROR(IF(GETPIVOTDATA("GBE",$T$3,"Year",$T29,"Month",AA$20)=0,NA(),GETPIVOTDATA("GBE",$T$3,"Year",$T29,"Month",AA$20)),NA()) -> 3881567 | AB29: =IFERROR(IF(GETPIVOTDATA("GBE",$T$3,"Year",$T29,"Month",AB$20)=0,NA(),GETPIVOTDATA("GBE",$T$3,"Year",$T29,"Month",AB$20)),NA()) -> 4092677.6 | ... AF29: =IFERROR(IF(GETPIVOTDATA("GBE",$T$3,"Year",$T29,"Month",AF$20)=0,NA(),GETPIVOTDATA("GBE",$T$3,"Year",$T29,"Month",AF$20)),NA()) -> 3872441.9
T30: =T29+1 -> 2025 | U30: =IFERROR(IF(GETPIVOTDATA("GBE",$T$3,"Year",$T30,"Month",U$20)=0,NA(),GETPIVOTDATA("GBE",$T$3,"Year",$T30,"Month",U$20)),NA()) -> 3770072.6 | V30: =IFERROR(IF(GETPIVOTDATA("GBE",$T$3,"Year",$T30,"Month",V$20)=0,NA(),GETPIVOTDATA("GBE",$T$3,"Year",$T30,"Month",V$20)),NA()) -> 3317751.2 | W30: =IFERROR(IF(GETPIVOTDATA("GBE",$T$3,"Year",$T30,"Month",W$20)=0,NA(),GETPIVOTDATA("GBE",$T$3,"Year",$T30,"Month",W$20)),NA()) -> 3067521.3 | X30: =IFERROR(IF(GETPIVOTDATA("GBE",$T$3,"Year",$T30,"Month",X$20)=0,NA(),GETPIVOTDATA("GBE",$T$3,"Year",$T30,"Month",X$20)),NA()) -> 2851110.3 | Y30: =IFERROR(IF(GETPIVOTDATA("GBE",$T$3,"Year",$T30,"Month",Y$20)=0,NA(),GETPIVOTDATA("GBE",$T$3,"Year",$T30,"Month",Y$20)),NA()) -> 3054295.4 | Z30: =IFERROR(IF(GETPIVOTDATA("GBE",$T$3,"Year",$T30,"Month",Z$20)=0,NA(),GETPIVOTDATA("GBE",$T$3,"Year",$T30,"Month",Z$20)),NA()) -> 2608187.6 | AA30: =IFERROR(IF(GETPIVOTDATA("GBE",$T$3,"Year",$T30,"Month",AA$20)=0,NA(),GETPIVOTDATA("GBE",$T$3,"Year",$T30,"Month",AA$20)),NA()) -> 2898313.2 | AB30: =IFERROR(IF(GETPIVOTDATA("GBE",$T$3,"Year",$T30,"Month",AB$20)=0,NA(),GETPIVOTDATA("GBE",$T$3,"Year",$T30,"Month",AB$20)),NA()) -> 3244664.7 | ... AF30: =IFERROR(IF(GETPIVOTDATA("GBE",$T$3,"Year",$T30,"Month",AF$20)=0,NA(),GETPIVOTDATA("GBE",$T$3,"Year",$T30,"Month",AF$20)),NA()) -> 3169202.8
T31: =T30+1 -> 2026 | U31: =IFERROR(IF(GETPIVOTDATA("GBE",$T$3,"Year",$T31,"Month",U$20)=0,NA(),GETPIVOTDATA("GBE",$T$3,"Year",$T31,"Month",U$20)),NA()) -> 2808075.7 | V31: =IFERROR(IF(GETPIVOTDATA("GBE",$T$3,"Year",$T31,"Month",V$20)=0,NA(),GETPIVOTDATA("GBE",$T$3,"Year",$T31,"Month",V$20)),NA()) -> 2618119.8 | W31: =IFERROR(IF(GETPIVOTDATA("GBE",$T$3,"Year",$T31,"Month",W$20)=0,NA(),GETPIVOTDATA("GBE",$T$3,"Year",$T31,"Month",W$20)),NA()) -> 3058938.6 | X31: =IFERROR(IF(GETPIVOTDATA("GBE",$T$3,"Year",$T31,"Month",X$20)=0,NA(),GETPIVOTDATA("GBE",$T$3,"Year",$T31,"Month",X$20)),NA()) -> #N/A | Y31: =IFERROR(IF(GETPIVOTDATA("GBE",$T$3,"Year",$T31,"Month",Y$20)=0,NA(),GETPIVOTDATA("GBE",$T$3,"Year",$T31,"Month",Y$20)),NA()) -> #N/A | Z31: =IFERROR(IF(GETPIVOTDATA("GBE",$T$3,"Year",$T31,"Month",Z$20)=0,NA(),GETPIVOTDATA("GBE",$T$3,"Year",$T31,"Month",Z$20)),NA()) -> #N/A | AA31: =IFERROR(IF(GETPIVOTDATA("GBE",$T$3,"Year",$T31,"Month",AA$20)=0,NA(),GETPIVOTDATA("GBE",$T$3,"Year",$T31,"Month",AA$20)),NA()) -> #N/A | AB31: =IFERROR(IF(GETPIVOTDATA("GBE",$T$3,"Year",$T31,"Month",AB$20)=0,NA(),GETPIVOTDATA("GBE",$T$3,"Year",$T31,"Month",AB$20)),NA()) -> #N/A | ... AF31: =IFERROR(IF(GETPIVOTDATA("GBE",$T$3,"Year",$T31,"Month",AF$20)=0,NA(),GETPIVOTDATA("GBE",$T$3,"Year",$T31,"Month",AF$20)),NA()) -> #N/A
T32: =T31+1 -> 2027 | U32: =IFERROR(IF(GETPIVOTDATA("GBE",$T$3,"Year",$T32,"Month",U$20)=0,NA(),GETPIVOTDATA("GBE",$T$3,"Year",$T32,"Month",U$20)),NA()) -> #N/A | V32: =IFERROR(IF(GETPIVOTDATA("GBE",$T$3,"Year",$T32,"Month",V$20)=0,NA(),GETPIVOTDATA("GBE",$T$3,"Year",$T32,"Month",V$20)),NA()) -> #N/A | W32: =IFERROR(IF(GETPIVOTDATA("GBE",$T$3,"Year",$T32,"Month",W$20)=0,NA(),GETPIVOTDATA("GBE",$T$3,"Year",$T32,"Month",W$20)),NA()) -> #N/A | X32: =IFERROR(IF(GETPIVOTDATA("GBE",$T$3,"Year",$T32,"Month",X$20)=0,NA(),GETPIVOTDATA("GBE",$T$3,"Year",$T32,"Month",X$20)),NA()) -> #N/A | Y32: =IFERROR(IF(GETPIVOTDATA("GBE",$T$3,"Year",$T32,"Month",Y$20)=0,NA(),GETPIVOTDATA("GBE",$T$3,"Year",$T32,"Month",Y$20)),NA()) -> #N/A | Z32: =IFERROR(IF(GETPIVOTDATA("GBE",$T$3,"Year",$T32,"Month",Z$20)=0,NA(),GETPIVOTDATA("GBE",$T$3,"Year",$T32,"Month",Z$20)),NA()) -> #N/A | AA32: =IFERROR(IF(GETPIVOTDATA("GBE",$T$3,"Year",$T32,"Month",AA$20)=0,NA(),GETPIVOTDATA("GBE",$T$3,"Year",$T32,"Month",AA$20)),NA()) -> #N/A | AB32: =IFERROR(IF(GETPIVOTDATA("GBE",$T$3,"Year",$T32,"Month",AB$20)=0,NA(),GETPIVOTDATA("GBE",$T$3,"Year",$T32,"Month",AB$20)),NA()) -> #N/A | ... AF32: =IFERROR(IF(GETPIVOTDATA("GBE",$T$3,"Year",$T32,"Month",AF$20)=0,NA(),GETPIVOTDATA("GBE",$T$3,"Year",$T32,"Month",AF$20)),NA()) -> #N/A
T33: =T32+1 -> 2028 | U33: =IFERROR(IF(GETPIVOTDATA("GBE",$T$3,"Year",$T33,"Month",U$20)=0,NA(),GETPIVOTDATA("GBE",$T$3,"Year",$T33,"Month",U$20)),NA()) -> #N/A | V33: =IFERROR(IF(GETPIVOTDATA("GBE",$T$3,"Year",$T33,"Month",V$20)=0,NA(),GETPIVOTDATA("GBE",$T$3,"Year",$T33,"Month",V$20)),NA()) -> #N/A | W33: =IFERROR(IF(GETPIVOTDATA("GBE",$T$3,"Year",$T33,"Month",W$20)=0,NA(),GETPIVOTDATA("GBE",$T$3,"Year",$T33,"Month",W$20)),NA()) -> #N/A | X33: =IFERROR(IF(GETPIVOTDATA("GBE",$T$3,"Year",$T33,"Month",X$20)=0,NA(),GETPIVOTDATA("GBE",$T$3,"Year",$T33,"Month",X$20)),NA()) -> #N/A | Y33: =IFERROR(IF(GETPIVOTDATA("GBE",$T$3,"Year",$T33,"Month",Y$20)=0,NA(),GETPIVOTDATA("GBE",$T$3,"Year",$T33,"Month",Y$20)),NA()) -> #N/A | Z33: =IFERROR(IF(GETPIVOTDATA("GBE",$T$3,"Year",$T33,"Month",Z$20)=0,NA(),GETPIVOTDATA("GBE",$T$3,"Year",$T33,"Month",Z$20)),NA()) -> #N/A | AA33: =IFERROR(IF(GETPIVOTDATA("GBE",$T$3,"Year",$T33,"Month",AA$20)=0,NA(),GETPIVOTDATA("GBE",$T$3,"Year",$T33,"Month",AA$20)),NA()) -> #N/A | AB33: =IFERROR(IF(GETPIVOTDATA("GBE",$T$3,"Year",$T33,"Month",AB$20)=0,NA(),GETPIVOTDATA("GBE",$T$3,"Year",$T33,"Month",AB$20)),NA()) -> #N/A | ... AF33: =IFERROR(IF(GETPIVOTDATA("GBE",$T$3,"Year",$T33,"Month",AF$20)=0,NA(),GETPIVOTDATA("GBE",$T$3,"Year",$T33,"Month",AF$20)),NA()) -> #N/A
U38: Oct | V38: Nov | W38: Dec | X38: Jan | Y38: Feb | Z38: Mar | AA38: Apr | AB38: May | AC38: Jun | AD38: Jul | AE38: Aug | AF38: Sep
T39: 16/17 | U39: =AD21 -> 3362927.9 | V39: =AE21 -> 3276941.2 | W39: =AF21 -> 3261882.1 | X39: =U22 -> 2646464.4 | Y39: =V22 -> 2590825.4 | Z39: =W22 -> 2834349.1 | AA39: =X22 -> 2240098.3 | AB39: =Y22 -> 2602453.4 | AC39: =Z22 -> 2191499.2 | AD39: =AA22 -> 1873670.7 | AE39: =AB22 -> 2610143.6 | AF39: =AC22 -> 2441617.9
T40: 17/18 | U40: =AD22 -> 2901977.5 | V40: =AE22 -> 2965514 | W40: =AF22 -> 3025954.5 | X40: =U23 -> 2719936.4 | Y40: =V23 -> 2511588.4 | Z40: =W23 -> 2698364.4 | AA40: =X23 -> 2388754.9 | AB40: =Y23 -> 1729254.4 | AC40: =Z23 -> 2583614.4 | AD40: =AA23 -> 2465428.7 | AE40: =AB23 -> 3544383.4 | AF40: =AC23 -> 3150780.2
T41: 18/19 | U41: =AD23 -> 3937859.1 | V41: =AE23 -> 3902855.5 | W41: =AF23 -> 4004539.3 | X41: =U24 -> 3470505.8 | Y41: =V24 -> 3574654.8 | Z41: =W24 -> 3117169.6 | AA41: =X24 -> 3267213.7 | AB41: =Y24 -> 3886596.1 | AC41: =Z24 -> 3102695.8 | AD41: =AA24 -> 3390434.2 | AE41: =AB24 -> 3368913.6 | AF41: =AC24 -> 3495386.6
T42: 19/20 | U42: =AD24 -> 3670113.2 | V42: =AE24 -> 3281473.3 | W42: =AF24 -> 3072707 | X42: =U25 -> 3474087.5 | Y42: =V25 -> 3007658.8 | Z42: =W25 -> 3493433.1 | AA42: =X25 -> 3599225.9 | AB42: =Y25 -> 3282032.2 | AC42: =Z25 -> 3075571.5 | AD42: =AA25 -> 3242242.1 | AE42: =AB25 -> 3574279.8 | AF42: =AC25 -> 4232364.9
T43: 20/21 | U43: =AD25 -> 4504376.8 | V43: =AE25 -> 4770005.3 | W43: =AF25 -> 4409066.5 | X43: =U26 -> 3657291.2 | Y43: =V26 -> 3972949.6 | Z43: =W26 -> 3833416.6 | AA43: =X26 -> 3575943.7 | AB43: =Y26 -> 3443874.4 | AC43: =Z26 -> 3210269.5 | AD43: =AA26 -> 2813525.2 | AE43: =AB26 -> 2859143.3 | AF43: =AC26 -> 3291463
T44: 21/22 | U44: =AD26 -> 3289593.3 | V44: =AE26 -> 3257809 | W44: =AF26 -> 3944334.1 | X44: =U27 -> 3468385.6 | Y44: =V27 -> 3536274.6 | Z44: =W27 -> 3891975.8 | AA44: =X27 -> 3016609.1 | AB44: =Y27 -> 2961676.3 | AC44: =Z27 -> 3125363 | AD44: =AA27 -> 2752356.7 | AE44: =AB27 -> 2951452.1 | AF44: =AC27 -> 3444289.6
T45: 22/23 | U45: =AD27 -> 3589378.2 | V45: =AE27 -> 3583957.6 | W45: =AF27 -> 3137089.7 | X45: =U28 -> 2591523.7 | Y45: =V28 -> 2461834.5 | Z45: =W28 -> 3166636.1 | AA45: =X28 -> 2495688.7 | AB45: =Y28 -> 2667981.5 | AC45: =Z28 -> 2658586.2 | AD45: =AA28 -> 3152174.1 | AE45: =AB28 -> 3815631.6 | AF45: =AC28 -> 3765915.8
T46: 23/24 | U46: =AD28 -> 4412709.5 | V46: =AE28 -> 4329650.4 | W46: =AF28 -> 4186199.8 | X46: =U29 -> 3998730.6 | Y46: =V29 -> 3742175.5 | Z46: =W29 -> 4308615.3 | AA46: =X29 -> 4276347.5 | AB46: =Y29 -> 4446510.6 | AC46: =Z29 -> 3770707 | AD46: =AA29 -> 3881567 | AE46: =AB29 -> 4092677.6 | AF46: =AC29 -> 4921683.9
T47: 24/25 | U47: =AD29 -> 5112274.2 | V47: =AE29 -> 4323717.1 | W47: =AF29 -> 3872441.9 | X47: =U30 -> 3770072.6 | Y47: =V30 -> 3317751.2 | Z47: =W30 -> 3067521.3 | AA47: =X30 -> 2851110.3 | AB47: =Y30 -> 3054295.4 | AC47: =Z30 -> 2608187.6 | AD47: =AA30 -> 2898313.2 | AE47: =AB30 -> 3244664.7 | AF47: =AC30 -> 4040788.4
T48: 25/26 | U48: =AD30 -> 4261080.6 | V48: =AE30 -> 3650504 | W48: =AF30 -> 3169202.8 | X48: =U31 -> 2808075.7 | Y48: =V31 -> 2618119.8 | Z48: =W31 -> 3058938.6 | AA48: =X31 -> #N/A | AB48: =Y31 -> #N/A | AC48: =Z31 -> #N/A | AD48: =AA31 -> #N/A | AE48: =AB31 -> #N/A | AF48: =AC31 -> #N/A
...

Sheet Monthly Exports
A1: Source | B1: Origin | C1: GBE | D1: Custom | E1: Year | F1: Month
A2: MonthlyTradeStatistics 2016_01.xlsx | B2: Total | C2: 9861975.9 | D2: 2016_01.xlsx | E2: 2016 | F2: 1
A3: MonthlyTradeStatistics 2016_01.xlsx | B3: Colombian Milds | C3: 1182143.7 | D3: 2016_01.xlsx | E3: 2016 | F3: 1
A4: MonthlyTradeStatistics 2016_01.xlsx | B4: Other Milds | C4: 1672020.7 | D4: 2016_01.xlsx | E4: 2016 | F4: 1
A5: MonthlyTradeStatistics 2016_01.xlsx | B5: Brazilian Naturals | C5: 2865661.3 | D5: 2016_01.xlsx | E5: 2016 | F5: 1
A6: MonthlyTradeStatistics 2016_01.xlsx | B6: Robustas | C6: 4142150.2 | D6: 2016_01.xlsx | E6: 2016 | F6: 1
A7: MonthlyTradeStatistics 2016_01.xlsx | B7: Angola | C7: 600 | D7: 2016_01.xlsx | E7: 2016 | F7: 1
A8: MonthlyTradeStatistics 2016_01.xlsx | B8: Bolivia (Plurinational State of) | C8: 3759.3833 | D8: 2016_01.xlsx | E8: 2016 | F8: 1
A9: MonthlyTradeStatistics 2016_01.xlsx | B9: Brazil | C9: 2808927.8 | D9: 2016_01.xlsx | E9: 2016 | F9: 1
A10: MonthlyTradeStatistics 2016_01.xlsx | B10: Burundi | C10: 21932.314 | D10: 2016_01.xlsx | E10: 2016 | F10: 1
A11: MonthlyTradeStatistics 2016_01.xlsx | B11: Cameroon | C11: 5300 | D11: 2016_01.xlsx | E11: 2016 | F11: 1
A12: MonthlyTradeStatistics 2016_01.xlsx | B12: Central African Republic | C12: 11107 | D12: 2016_01.xlsx | E12: 2016 | F12: 1
A13: MonthlyTradeStatistics 2016_01.xlsx | B13: Colombia | C13: 1098487.4 | D13: 2016_01.xlsx | E13: 2016 | F13: 1
... A7254: MonthlyTradeStatistics 2026_03.xlsx | B7254: Zimbabwe | C7254: 0 | D7254: 2026_03.xlsx | E7254: 2026 | F7254: 3

Sheet Sheet1

Sheet Exports Dashboard
A1: ICO's Monthly Exports
AH2: YTD | AI2: =_xlfn.CONCAT(AE5," | ",S6) -> | YTD : Oct-Mar
C4: 1 | D4: 2 | E4: 3 | F4: 4 | G4: 5 | H4: 6 | I4: 7 | J4: 8 | K4: 9 | L4: 10 | M4: 11 | N4: 12
C5: ICO's Monthly Exports
C6: Oct | D6: Nov | E6: Dec | F6: Jan | G6: Feb | H6: Mar | I6: Apr | J6: May | K6: Jun | L6: Jul | M6: Aug | N6: Sep | P6: Total | Q6: % | S6: =_xlfn.CONCAT("YTD : ",IF(C56=1,"Oct Only",_xlfn.CONCAT("Oct-",OFFSET(B6,0,$C$56,1,1)))) -> YTD : Oct-Mar
A7: 1 | B7: 14/15 | O7: 14/15 | P7: =IF(COUNT(C7:N7)=12,SUM(C7:N7),"") | S7: 14/15 | T7: =IFERROR(IF(SUM(OFFSET(C7,0,0,1,$C$56))=0,"",SUM(OFFSET(C7,0,0,1,$C$56))),"")
A8: 2 | B8: 15/16 | O8: 15/16 | P8: =IF(COUNT(C8:N8)=12,SUM(C8:N8),"") | Q8: =IFERROR(P8/P7-1,"") | S8: 15/16 | T8: =IFERROR(IF(SUM(OFFSET(C8,0,0,1,$C$56))=0,"",SUM(OFFSET(C8,0,0,1,$C$56))),"") | U8: =IFERROR(T8/T7-1,"")
A9: 3 | B9: 16/17 | C9: =Pivot!U39 -> 3362927.9 | D9: =Pivot!V39 -> 3276941.2 | E9: =Pivot!W39 -> 3261882.1 | F9: =Pivot!X39 -> 2646464.4 | G9: =Pivot!Y39 -> 2590825.4 | H9: =Pivot!Z39 -> 2834349.1 | I9: =Pivot!AA39 -> 2240098.3 | J9: =Pivot!AB39 -> 2602453.4 | ... N9: =Pivot!AF39 -> 2441617.9 | O9: 16/17 | P9: =IF(COUNT(C9:N9)=12,SUM(C9:N9),"") -> 31932873 | Q9: =IFERROR(P9/P8-1,"") | S9: 16/17 | T9: =IFERROR(IF(SUM(OFFSET(C9,0,0,1,$C$56))=0,"",SUM(OFFSET(C9,0,0,1,$C$56))),"") -> 17973390 | U9: =IFERROR(T9/T8-1,"")
A10: 4 | B10: 17/18 | C10: =Pivot!U40 -> 2901977.5 | D10: =Pivot!V40 -> 2965514 | E10: =Pivot!W40 -> 3025954.5 | F10: =Pivot!X40 -> 2719936.4 | G10: =Pivot!Y40 -> 2511588.4 | H10: =Pivot!Z40 -> 2698364.4 | I10: =Pivot!AA40 -> 2388754.9 | J10: =Pivot!AB40 -> 1729254.4 | ... N10: =Pivot!AF40 -> 3150780.2 | O10: 17/18 | P10: =IF(COUNT(C10:N10)=12,SUM(C10:N10),"") -> 32685551 | Q10: =IFERROR(P10/P9-1,"") -> 0.023570626 | S10: 17/18 | T10: =IFERROR(IF(SUM(OFFSET(C10,0,0,1,$C$56))=0,"",SUM(OFFSET(C10,0,0,1,$C$56))),"") -> 16823335 | U10: =IFERROR(T10/T9-1,"") -> -0.06398654
A11: 5 | B11: 18/19 | C11: =Pivot!U41 -> 3937859.1 | D11: =Pivot!V41 -> 3902855.5 | E11: =Pivot!W41 -> 4004539.3 | F11: =Pivot!X41 -> 3470505.8 | G11: =Pivot!Y41 -> 3574654.8 | H11: =Pivot!Z41 -> 3117169.6 | I11: =Pivot!AA41 -> 3267213.7 | J11: =Pivot!AB41 -> 3886596.1 | ... N11: =Pivot!AF41 -> 3495386.6 | O11: 18/19 | P11: =IF(COUNT(C11:N11)=12,SUM(C11:N11),"") -> 42518824 | Q11: =IFERROR(P11/P10-1,"") -> 0.30084464 | S11: 18/19 | T11: =IFERROR(IF(SUM(OFFSET(C11,0,0,1,$C$56))=0,"",SUM(OFFSET(C11,0,0,1,$C$56))),"") -> 22007584 | U11: =IFERROR(T11/T10-1,"") -> 0.30815822
A12: 6 | B12: 19/20 | C12: =Pivot!U42 -> 3670113.2 | D12: =Pivot!V42 -> 3281473.3 | E12: =Pivot!W42 -> 3072707 | F12: =Pivot!X42 -> 3474087.5 | G12: =Pivot!Y42 -> 3007658.8 | H12: =Pivot!Z42 -> 3493433.1 | I12: =Pivot!AA42 -> 3599225.9 | J12: =Pivot!AB42 -> 3282032.2 | ... N12: =Pivot!AF42 -> 4232364.9 | O12: 19/20 | P12: =IF(COUNT(C12:N12)=12,SUM(C12:N12),"") -> 41005189 | Q12: =IFERROR(P12/P11-1,"") -> -0.03559917 | S12: 19/20 | T12: =IFERROR(IF(SUM(OFFSET(C12,0,0,1,$C$56))=0,"",SUM(OFFSET(C12,0,0,1,$C$56))),"") -> 19999473 | U12: =IFERROR(T12/T11-1,"") -> -0.091246328
A13: 7 | B13: 20/21 | C13: =Pivot!U43 -> 4504376.8 | D13: =Pivot!V43 -> 4770005.3 | E13: =Pivot!W43 -> 4409066.5 | F13: =Pivot!X43 -> 3657291.2 | G13: =Pivot!Y43 -> 3972949.6 | H13: =Pivot!Z43 -> 3833416.6 | I13: =Pivot!AA43 -> 3575943.7 | J13: =Pivot!AB43 -> 3443874.4 | ... N13: =Pivot!AF43 -> 3291463 | O13: 20/21 | P13: =IF(COUNT(C13:N13)=12,SUM(C13:N13),"") -> 44341325 | Q13: =IFERROR(P13/P12-1,"") -> 0.081358867 | S13: 20/21 | T13: =IFERROR(IF(SUM(OFFSET(C13,0,0,1,$C$56))=0,"",SUM(OFFSET(C13,0,0,1,$C$56))),"") -> 25147106 | U13: =IFERROR(T13/T12-1,"") -> 0.25738844
A14: 8 | B14: 21/22 | C14: =Pivot!U44 -> 3289593.3 | D14: =Pivot!V44 -> 3257809 | E14: =Pivot!W44 -> 3944334.1 | F14: =Pivot!X44 -> 3468385.6 | G14: =Pivot!Y44 -> 3536274.6 | H14: =Pivot!Z44 -> 3891975.8 | I14: =Pivot!AA44 -> 3016609.1 | J14: =Pivot!AB44 -> 2961676.3 | ... N14: =Pivot!AF44 -> 3444289.6 | O14: 21/22 | P14: =IF(COUNT(C14:N14)=12,SUM(C14:N14),"") -> 39640119 | Q14: =IFERROR(P14/P13-1,"") -> -0.10602313 | S14: 21/22 | T14: =IFERROR(IF(SUM(OFFSET(C14,0,0,1,$C$56))=0,"",SUM(OFFSET(C14,0,0,1,$C$56))),"") -> 21388372 | U14: =IFERROR(T14/T13-1,"") -> -0.14946983
A15: 9 | B15: 22/23 | C15: =Pivot!U45 -> 3589378.2 | D15: =Pivot!V45 -> 3583957.6 | E15: =Pivot!W45 -> 3137089.7 | F15: =Pivot!X45 -> 2591523.7 | G15: =Pivot!Y45 -> 2461834.5 | H15: =Pivot!Z45 -> 3166636.1 | I15: =Pivot!AA45 -> 2495688.7 | J15: =Pivot!AB45 -> 2667981.5 | ... N15: =Pivot!AF45 -> 3765915.8 | O15: 22/23 | P15: =IF(COUNT(C15:N15)=12,SUM(C15:N15),"") -> 37086398 | Q15: =IFERROR(P15/P14-1,"") -> -0.064422648 | S15: 22/23 | T15: =IFERROR(IF(SUM(OFFSET(C15,0,0,1,$C$56))=0,"",SUM(OFFSET(C15,0,0,1,$C$56))),"") -> 18530420 | U15: =IFERROR(T15/T14-1,"") -> -0.13362179
A16: 10 | B16: 23/24 | C16: =Pivot!U46 -> 4412709.5 | D16: =Pivot!V46 -> 4329650.4 | E16: =Pivot!W46 -> 4186199.8 | F16: =Pivot!X46 -> 3998730.6 | G16: =Pivot!Y46 -> 3742175.5 | H16: =Pivot!Z46 -> 4308615.3 | I16: =Pivot!AA46 -> 4276347.5 | J16: =Pivot!AB46 -> 4446510.6 | ... N16: =Pivot!AF46 -> 4921683.9 | O16: 23/24 | P16: =IF(COUNT(C16:N16)=12,SUM(C16:N16),"") -> 50367575 | Q16: =IFERROR(P16/P15-1,"") -> 0.35811451 | S16: 23/24 | T16: =IFERROR(IF(SUM(OFFSET(C16,0,0,1,$C$56))=0,"",SUM(OFFSET(C16,0,0,1,$C$56))),"") -> 24978081 | U16: =IFERROR(T16/T15-1,"") -> 0.3479501
A17: 11 | B17: 24/25 | C17: =Pivot!U47 -> 5112274.2 | D17: =Pivot!V47 -> 4323717.1 | E17: =Pivot!W47 -> 3872441.9 | F17: =Pivot!X47 -> 3770072.6 | G17: =Pivot!Y47 -> 3317751.2 | H17: =Pivot!Z47 -> 3067521.3 | I17: =Pivot!AA47 -> 2851110.3 | J17: =Pivot!AB47 -> 3054295.4 | ... N17: =Pivot!AF47 -> 4040788.4 | O17: 24/25 | P17: =IF(COUNT(C17:N17)=12,SUM(C17:N17),"") -> 42161138 | S17: 24/25 | T17: =IFERROR(IF(SUM(OFFSET(C17,0,0,1,$C$56))=0,"",SUM(OFFSET(C17,0,0,1,$C$56))),"") -> 23463778 | U17: =IFERROR(T17/T16-1,"") -> -0.060625269
A18: 12 | B18: 25/26 | C18: =Pivot!U48 -> 4261080.6 | D18: =Pivot!V48 -> 3650504 | E18: =Pivot!W48 -> 3169202.8 | F18: =Pivot!X48 -> 2808075.7 | G18: =Pivot!Y48 -> 2618119.8 | H18: =Pivot!Z48 -> 3058938.6 | I18: =Pivot!AA48 -> #N/A | J18: =Pivot!AB48 -> #N/A | ... N18: =Pivot!AF48 -> #N/A | O18: 25/26 | P18: =IF(COUNT(C18:N18)=12,SUM(C18:N18),"") | S18: 25/26 | T18: =IFERROR(IF(SUM(OFFSET(C18,0,0,1,$C$56))=0,"",SUM(OFFSET(C18,0,0,1,$C$56))),"") -> 19565921 | U18: =IFERROR(T18/T17-1,"") -> -0.1661223
A19: 13 | B19: 26/27 | C19: =Pivot!U49 -> #N/A | D19: =Pivot!V49 -> #N/A | E19: =Pivot!W49 -> #N/A | F19: =Pivot!X49 -> #N/A | G19: =Pivot!Y49 -> #N/A | H19: =Pivot!Z49 -> #N/A | I19: =Pivot!AA49 -> #N/A | J19: =Pivot!AB49 -> #N/A | ... N19: =Pivot!AF49 -> #N/A | O19: 26/27 | P19: =IF(COUNT(C19:N19)=12,SUM(C19:N19),"") | S19: 26/27 | T19: =IFERROR(IF(SUM(OFFSET(C19,0,0,1,$C$56))=0,"",SUM(OFFSET(C19,0,0,1,$C$56))),"")
B20: YoY | C20: =IFERROR(C18/C17-1,"") -> -0.16649999 | D20: =IFERROR(D18/D17-1,"") -> -0.15570239 | E20: =IFERROR(E18/E17-1,"") -> -0.18160096 | F20: =IFERROR(F18/F17-1,"") -> -0.25516666 | G20: =IFERROR(G18/G17-1,"") -> -0.21087517 | H20: =IFERROR(H18/H17-1,"") -> -0.0027979156 | I20: =IFERROR(I18/I17-1,"") | J20: =IFERROR(J18/J17-1,"") | ... N20: =IFERROR(N18/N17-1,"")
K27: =_xlfn.CONCAT(A1," | ",S6) -> ICO's Monthly Exports | YTD : Oct-Mar | Q27: =_xlfn.CONCAT(A1," | ","Cumulative") -> ICO's Monthly Exports | Cumulative
B56: Offset | C56: =COUNT(C18:N18) -> 6 | D56: =OFFSET(B6,0,$C$56,1,1) -> Mar | E56: =B18 -> 25/26 | F56: =_xlfn.CONCAT(D56,"'",E56) -> Mar'25/26
B65: Oct | C65: Nov | D65: Dec | E65: Jan | F65: Feb | G65: Mar | H65: Apr | I65: May | J65: Jun | K65: Jul | L65: Aug | M65: Sep
A66: =B18 -> 25/26 | B66: =C18 -> 4261080.6 | C66: =D18 -> 3650504 | D66: =E18 -> 3169202.8 | E66: =F18 -> 2808075.7 | F66: =G18 -> 2618119.8 | G66: =H18 -> 3058938.6 | H66: =I18 -> #N/A | ... M66: =N18 -> #N/A
A67: Min | B67: =MIN(C7:C17) -> 2901977.5 | C67: =MIN(D7:D17) -> 2965514 | D67: =MIN(E7:E17) -> 3025954.5 | E67: =MIN(F7:F17) -> 2591523.7 | F67: =MIN(G7:G17) -> 2461834.5 | G67: =MIN(H7:H17) -> 2698364.4 | H67: =MIN(I7:I17) -> 2240098.3 | I67: =MIN(J7:J17) -> 1729254.4 | ... M67: =MIN(N7:N17) -> 2441617.9
A68: Max | B68: =MAX(C7:C17) -> 5112274.2 | C68: =MAX(D7:D17) -> 4770005.3 | D68: =MAX(E7:E17) -> 4409066.5 | E68: =MAX(F7:F17) -> 3998730.6 | F68: =MAX(G7:G17) -> 3972949.6 | G68: =MAX(H7:H17) -> 4308615.3 | H68: =MAX(I7:I17) -> 4276347.5 | I68: =MAX(J7:J17) -> 4446510.6 | ... M68: =MAX(N7:N17) -> 4921683.9
A69: Avg(5) | B69: =AVERAGE(C12:C17) -> 4096407.5 | C69: =AVERAGE(D12:D17) -> 3924435.4 | D69: =AVERAGE(E12:E17) -> 3770306.5 | E69: =AVERAGE(F12:F17) -> 3493348.5 | F69: =AVERAGE(G12:G17) -> 3339774 | G69: =AVERAGE(H12:H17) -> 3626933 | H69: =AVERAGE(I12:I17) -> 3302487.5 | I69: =AVERAGE(J12:J17) -> 3309395.1 | ... M69: =AVERAGE(N12:N17) -> 3949417.6
B74: 1 | C74: 1 | D74: =INDEX($C$7:$N$19,MATCH(B74,$A$7:$A$19),MATCH(C74,$C$4:$N$4)) -> 0 | E74: =_xlfn.XLOOKUP(B74,$A$7:$A$19,$B$7:$B$19) -> 14/15 | F74: =_xlfn.XLOOKUP(C74,$C$4:$N$4,$C$6:$N$6) -> Oct | G74: =_xlfn.CONCAT(F74,"'",E74) -> Oct'14/15 | N74: Cumulative
B75: 1 | C75: 2 | D75: =INDEX($C$7:$N$19,MATCH(B75,$A$7:$A$19),MATCH(C75,$C$4:$N$4)) -> 0 | E75: =_xlfn.XLOOKUP(B75,$A$7:$A$19,$B$7:$B$19) -> 14/15 | F75: =_xlfn.XLOOKUP(C75,$C$4:$N$4,$C$6:$N$6) -> Nov | G75: =_xlfn.CONCAT(F75,"'",E75) -> Nov'14/15 | N75: Oct | O75: Nov | P75: Dec | Q75: Jan | R75: Feb | S75: Mar | T75: Apr | U75: May | V75: Jun | W75: Jul | X75: Aug | Y75: Sep
B76: 1 | C76: 3 | D76: =INDEX($C$7:$N$19,MATCH(B76,$A$7:$A$19),MATCH(C76,$C$4:$N$4)) -> 0 | E76: =_xlfn.XLOOKUP(B76,$A$7:$A$19,$B$7:$B$19) -> 14/15 | F76: =_xlfn.XLOOKUP(C76,$C$4:$N$4,$C$6:$N$6) -> Dec | G76: =_xlfn.CONCAT(F76,"'",E76) -> Dec'14/15 | M76: 14/15 | N76: =C7 -> 0 | O76: =N76+D7 -> 0 | P76: =O76+E7 -> 0 | Q76: =P76+F7 -> 0 | R76: =Q76+G7 -> 0 | S76: =R76+H7 -> 0 | T76: =S76+I7 -> 0 | U76: =T76+J7 -> 0 | V76: =U76+K7 -> 0 | ... Y76: =X76+N7 -> 0
B77: 1 | C77: 4 | D77: =INDEX($C$7:$N$19,MATCH(B77,$A$7:$A$19),MATCH(C77,$C$4:$N$4)) -> 0 | E77: =_xlfn.XLOOKUP(B77,$A$7:$A$19,$B$7:$B$19) -> 14/15 | F77: =_xlfn.XLOOKUP(C77,$C$4:$N$4,$C$6:$N$6) -> Jan | G77: =_xlfn.CONCAT(F77,"'",E77) -> Jan'14/15 | M77: 15/16 | N77: =C8 -> 0 | O77: =N77+D8 -> 0 | P77: =O77+E8 -> 0 | Q77: =P77+F8 -> 0 | R77: =Q77+G8 -> 0 | S77: =R77+H8 -> 0 | T77: =S77+I8 -> 0 | U77: =T77+J8 -> 0 | V77: =U77+K8 -> 0 | ... Y77: =X77+N8 -> 0
B78: 1 | C78: 5 | D78: =INDEX($C$7:$N$19,MATCH(B78,$A$7:$A$19),MATCH(C78,$C$4:$N$4)) -> 0 | E78: =_xlfn.XLOOKUP(B78,$A$7:$A$19,$B$7:$B$19) -> 14/15 | F78: =_xlfn.XLOOKUP(C78,$C$4:$N$4,$C$6:$N$6) -> Feb | G78: =_xlfn.CONCAT(F78,"'",E78) -> Feb'14/15 | M78: 16/17 | N78: =C9 -> 3362927.9 | O78: =N78+D9 -> 6639869.2 | P78: =O78+E9 -> 9901751.3 | Q78: =P78+F9 -> 12548216 | R78: =Q78+G9 -> 15139041 | S78: =R78+H9 -> 17973390 | T78: =S78+I9 -> 20213489 | U78: =T78+J9 -> 22815942 | V78: =U78+K9 -> 25007441 | ... Y78: =X78+N9 -> 31932873
B79: 1 | C79: 6 | D79: =INDEX($C$7:$N$19,MATCH(B79,$A$7:$A$19),MATCH(C79,$C$4:$N$4)) -> 0 | E79: =_xlfn.XLOOKUP(B79,$A$7:$A$19,$B$7:$B$19) -> 14/15 | F79: =_xlfn.XLOOKUP(C79,$C$4:$N$4,$C$6:$N$6) -> Mar | G79: =_xlfn.CONCAT(F79,"'",E79) -> Mar'14/15 | M79: 17/18 | N79: =C10 -> 2901977.5 | O79: =N79+D10 -> 5867491.5 | P79: =O79+E10 -> 8893446 | Q79: =P79+F10 -> 11613382 | R79: =Q79+G10 -> 14124971 | S79: =R79+H10 -> 16823335 | T79: =S79+I10 -> 19212090 | U79: =T79+J10 -> 20941344 | V79: =U79+K10 -> 23524959 | ... Y79: =X79+N10 -> 32685551
B80: 1 | C80: 7 | D80: =INDEX($C$7:$N$19,MATCH(B80,$A$7:$A$19),MATCH(C80,$C$4:$N$4)) -> 0 | E80: =_xlfn.XLOOKUP(B80,$A$7:$A$19,$B$7:$B$19) -> 14/15 | F80: =_xlfn.XLOOKUP(C80,$C$4:$N$4,$C$6:$N$6) -> Apr | G80: =_xlfn.CONCAT(F80,"'",E80) -> Apr'14/15 | M80: 18/19 | N80: =C11 -> 3937859.1 | O80: =N80+D11 -> 7840714.6 | P80: =O80+E11 -> 11845254 | Q80: =P80+F11 -> 15315760 | R80: =Q80+G11 -> 18890415 | S80: =R80+H11 -> 22007584 | T80: =S80+I11 -> 25274798 | U80: =T80+J11 -> 29161394 | V80: =U80+K11 -> 32264090 | ... Y80: =X80+N11 -> 42518824
B81: 1 | C81: 8 | D81: =INDEX($C$7:$N$19,MATCH(B81,$A$7:$A$19),MATCH(C81,$C$4:$N$4)) -> 0 | E81: =_xlfn.XLOOKUP(B81,$A$7:$A$19,$B$7:$B$19) -> 14/15 | F81: =_xlfn.XLOOKUP(C81,$C$4:$N$4,$C$6:$N$6) -> May | G81: =_xlfn.CONCAT(F81,"'",E81) -> May'14/15 | M81: 19/20 | N81: =C12 -> 3670113.2 | O81: =N81+D12 -> 6951586.5 | P81: =O81+E12 -> 10024294 | Q81: =P81+F12 -> 13498381 | R81: =Q81+G12 -> 16506040 | S81: =R81+H12 -> 19999473 | T81: =S81+I12 -> 23598699 | U81: =T81+J12 -> 26880731 | V81: =U81+K12 -> 29956303 | ... Y81: =X81+N12 -> 41005189
B82: 1 | C82: 9 | D82: =INDEX($C$7:$N$19,MATCH(B82,$A$7:$A$19),MATCH(C82,$C$4:$N$4)) -> 0 | E82: =_xlfn.XLOOKUP(B82,$A$7:$A$19,$B$7:$B$19) -> 14/15 | F82: =_xlfn.XLOOKUP(C82,$C$4:$N$4,$C$6:$N$6) -> Jun | G82: =_xlfn.CONCAT(F82,"'",E82) -> Jun'14/15 | M82: 20/21 | N82: =C13 -> 4504376.8 | O82: =N82+D13 -> 9274382.1 | P82: =O82+E13 -> 13683449 | Q82: =P82+F13 -> 17340740 | R82: =Q82+G13 -> 21313689 | S82: =R82+H13 -> 25147106 | T82: =S82+I13 -> 28723050 | U82: =T82+J13 -> 32166924 | V82: =U82+K13 -> 35377194 | ... Y82: =X82+N13 -> 44341325
B83: 1 | C83: 10 | D83: =INDEX($C$7:$N$19,MATCH(B83,$A$7:$A$19),MATCH(C83,$C$4:$N$4)) -> 0 | E83: =_xlfn.XLOOKUP(B83,$A$7:$A$19,$B$7:$B$19) -> 14/15 | F83: =_xlfn.XLOOKUP(C83,$C$4:$N$4,$C$6:$N$6) -> Jul | G83: =_xlfn.CONCAT(F83,"'",E83) -> Jul'14/15 | M83: 21/22 | N83: =C14 -> 3289593.3 | O83: =N83+D14 -> 6547402.2 | P83: =O83+E14 -> 10491736 | Q83: =P83+F14 -> 13960122 | R83: =Q83+G14 -> 17496397 | S83: =R83+H14 -> 21388372 | T83: =S83+I14 -> 24404981 | U83: =T83+J14 -> 27366658 | V83: =U83+K14 -> 30492021 | ... Y83: =X83+N14 -> 39640119
B84: 1 | C84: 11 | D84: =INDEX($C$7:$N$19,MATCH(B84,$A$7:$A$19),MATCH(C84,$C$4:$N$4)) -> 0 | E84: =_xlfn.XLOOKUP(B84,$A$7:$A$19,$B$7:$B$19) -> 14/15 | F84: =_xlfn.XLOOKUP(C84,$C$4:$N$4,$C$6:$N$6) -> Aug | G84: =_xlfn.CONCAT(F84,"'",E84) -> Aug'14/15 | H84: Month | I84: Rolling 12m Sum | M84: 22/23 | N84: =C15 -> 3589378.2 | O84: =N84+D15 -> 7173335.8 | P84: =O84+E15 -> 10310425 | Q84: =P84+F15 -> 12901949 | R84: =Q84+G15 -> 15363784 | S84: =R84+H15 -> 18530420 | T84: =S84+I15 -> 21026108 | U84: =T84+J15 -> 23694090 | V84: =U84+K15 -> 26352676 | ... Y84: =X84+N15 -> 37086398
B85: 1 | C85: 12 | D85: =INDEX($C$7:$N$19,MATCH(B85,$A$7:$A$19),MATCH(C85,$C$4:$N$4)) -> 0 | E85: =_xlfn.XLOOKUP(B85,$A$7:$A$19,$B$7:$B$19) -> 14/15 | F85: =_xlfn.XLOOKUP(C85,$C$4:$N$4,$C$6:$N$6) -> Sep | G85: =_xlfn.CONCAT(F85,"'",E85) -> Sep'14/15 | H85: =G85 -> Sep'14/15 | I85: =SUM(D74:D85)/1000000 -> 0 | M85: 23/24 | N85: =C16 -> 4412709.5 | O85: =N85+D16 -> 8742359.9 | P85: =O85+E16 -> 12928560 | Q85: =P85+F16 -> 16927290 | R85: =Q85+G16 -> 20669466 | S85: =R85+H16 -> 24978081 | T85: =S85+I16 -> 29254429 | U85: =T85+J16 -> 33700939 | V85: =U85+K16 -> 37471646 | ... Y85: =X85+N16 -> 50367575
B86: =B74+1 -> 2 | C86: =C74 -> 1 | D86: =INDEX($C$7:$N$19,MATCH(B86,$A$7:$A$19),MATCH(C86,$C$4:$N$4)) -> 0 | E86: =_xlfn.XLOOKUP(B86,$A$7:$A$19,$B$7:$B$19) -> 15/16 | F86: =_xlfn.XLOOKUP(C86,$C$4:$N$4,$C$6:$N$6) -> Oct | G86: =_xlfn.CONCAT(F86,"'",E86) -> Oct'15/16 | H86: =G86 -> Oct'15/16 | I86: =SUM(D75:D86)/1000000 -> 0 | M86: 24/25 | N86: =C17 -> 5112274.2 | O86: =N86+D17 -> 9435991.2 | P86: =O86+E17 -> 13308433 | Q86: =P86+F17 -> 17078506 | R86: =Q86+G17 -> 20396257 | S86: =R86+H17 -> 23463778 | T86: =S86+I17 -> 26314888 | U86: =T86+J17 -> 29369184 | V86: =U86+K17 -> 31977371 | ... Y86: =X86+N17 -> 42161138
B87: =B75+1 -> 2 | C87: =C75 -> 2 | D87: =INDEX($C$7:$N$19,MATCH(B87,$A$7:$A$19),MATCH(C87,$C$4:$N$4)) -> 0 | E87: =_xlfn.XLOOKUP(B87,$A$7:$A$19,$B$7:$B$19) -> 15/16 | F87: =_xlfn.XLOOKUP(C87,$C$4:$N$4,$C$6:$N$6) -> Nov | G87: =_xlfn.CONCAT(F87,"'",E87) -> Nov'15/16 | H87: =G87 -> Nov'15/16 | I87: =SUM(D76:D87)/1000000 -> 0 | M87: 25/26 | N87: =C18 -> 4261080.6 | O87: =N87+D18 -> 7911584.6 | P87: =O87+E18 -> 11080787 | Q87: =P87+F18 -> 13888863 | R87: =Q87+G18 -> 16506983 | S87: =R87+H18 -> 19565921 | T87: =S87+I18 -> #N/A | U87: =T87+J18 -> #N/A | V87: =U87+K18 -> #N/A | ... Y87: =X87+N18 -> #N/A
...
