Workbook

Sheet Menu
A1: Coffee Aggregated Exports
A4: =NOW() -> 46314.492
C6: Arabica | G6: Latest Month | J6: Robusta | N6: Latest Month
D9: Brazil | G9: ='Brazil Arabica'!$F$56 -> Sep'25/26 | K9: Vietnam | N9: =Vietnam!$F$56 -> Sep'25/26
D12: Colombia | G12: =Colombia!$F$56 -> Aug'25/26 | K12: Brazil | N12: ='Brazil Robusta'!$F$56 -> Sep'25/26
D15: Honduras | G15: =Honduras!$F$56 -> Aug'25/26 | K15: Indonesia | N15: =Indonesia!$F$56 -> Apr'25/26
D18: Ethiopia | G18: =Ethiopia!$F$56 -> May'25/26 | K18: Uganda | N18: =Uganda!$F$56 -> Jul'25/26
D21: Peru | G21: =Peru!$F$56 -> May'24/25 | K21: India | N21: =India!$F$56 -> Apr'25/26
L26: =Aggregated!F56 -> Apr'25/26
L30: ='Agg (Peru Included)'!F56 -> Sep'24/25

Sheet Marex total
C3: Last 5 Year Average
D5: marex avg | E5: Super 10 | F5: Share
C6: Oct | D6: 10 | E6: 8.7270099 | F6: =E6/D6 -> 0.87270099
C7: Nov | D7: 10 | E7: 9.0577548 | F7: =E7/D7 -> 0.90577548
C8: Dec | D8: 11.6 | E8: 10.279129 | F8: =E8/D8 -> 0.88613177
C9: Jan | D9: 11 | E9: 9.8442192 | F9: =E9/D9 -> 0.89492902
C10: Feb | D10: 11.6 | E10: 9.4219663 | F10: =E10/D10 -> 0.81223848
C11: Mar | D11: 13 | E11: 10.624494 | F11: =E11/D11 -> 0.81726874
C12: Apr | D12: 11.6 | E12: 9.1028456 | F12: =E12/D12 -> 0.78472807
C13: May | D13: 11.7 | E13: 8.9853244 | F13: =E13/D13 -> 0.76797645
C14: Jun | D14: 11.6 | E14: 8.9204849 | F14: =E14/D14 -> 0.76900732
C15: Jul | D15: 11.2 | E15: 8.8781342 | F15: =E15/D15 -> 0.79269055
C16: Aug | D16: 11 | E16: 8.7938333 | F16: =E16/D16 -> 0.79943939
C17: Sep | D17: 10.8 | E17: 8.640352 | F17: =E17/D17 -> 0.80003259

Sheet Global derived
A1: Global Coffee Exports
AH2: YTD | AI2: =_xlfn.CONCAT(AE5," | ",S6) -> | YTD : Oct-Apr
C4: 1 | D4: 2 | E4: 3 | F4: 4 | G4: 5 | H4: 6 | I4: 7 | J4: 8 | K4: 9 | L4: 10 | M4: 11 | N4: 12
C5: =_xlfn.CONCAT(A1," (Monthly)") -> Global Coffee Exports (Monthly)
C6: Oct | D6: Nov | E6: Dec | F6: Jan | G6: Feb | H6: Mar | I6: Apr | J6: May | K6: Jun | L6: Jul | M6: Aug | N6: Sep | P6: Total | Q6: % | S6: =_xlfn.CONCAT("YTD : ",IF(C56=1,"Oct Only",_xlfn.CONCAT("Oct-",OFFSET(B6,0,$C$56,1,1)))) -> YTD : Oct-Apr
A7: 1 | B7: 14/15 | C7: #N/A | D7: #N/A | E7: #N/A | F7: #N/A | G7: #N/A | H7: #N/A | I7: #N/A | J7: #N/A | K7: #N/A | L7: #N/A | M7: #N/A | N7: #N/A | O7: 14/15 | P7: =IF(COUNT(C7:N7)=12,SUM(C7:N7),"") | S7: 14/15
A8: 2 | B8: 15/16 | C8: #N/A | D8: #N/A | E8: #N/A | F8: #N/A | G8: #N/A | H8: #N/A | I8: #N/A | J8: #N/A | K8: #N/A | L8: #N/A | M8: #N/A | N8: #N/A | O8: 15/16 | P8: =IF(COUNT(C8:N8)=12,SUM(C8:N8),"") | Q8: =IFERROR(P8/P7-1,"") | S8: 15/16 | U8: =IFERROR(T8/T7-1,"")
A9: 3 | B9: 16/17 | C9: #N/A | D9: #N/A | E9: #N/A | F9: #N/A | G9: #N/A | H9: #N/A | I9: #N/A | J9: #N/A | K9: #N/A | L9: #N/A | M9: #N/A | N9: #N/A | O9: 16/17 | P9: =IF(COUNT(C9:N9)=12,SUM(C9:N9),"") | Q9: =IFERROR(P9/P8-1,"") | S9: 16/17 | U9: =IFERROR(T9/T8-1,"")
A10: 4 | B10: 17/18 | C10: ='Agg (Peru Included)'!C10/B$62 -> 8630970.5 | D10: ='Agg (Peru Included)'!D10/C$62 -> 9055937.6 | E10: ='Agg (Peru Included)'!E10/D$62 -> 10146942 | F10: ='Agg (Peru Included)'!F10/E$62 -> 10686469 | G10: ='Agg (Peru Included)'!G10/F$62 -> 10033224 | H10: ='Agg (Peru Included)'!H10/G$62 -> 11149435 | I10: ='Agg (Peru Included)'!I10/H$62 -> 10299318 | J10: ='Agg (Peru Included)'!J10/I$62 -> 9788242.8 | ... N10: ='Agg (Peru Included)'!N10/M$62 -> 10386830 | O10: 17/18 | P10: =IF(COUNT(C10:N10)=12,SUM(C10:N10),"") -> 1.2193451e+08 | Q10: =IFERROR(P10/P9-1,"") | S10: 17/18 | T10: =IF(SUM(OFFSET(C10,0,0,1,$C$56))=0,"",SUM(OFFSET(C10,0,0,1,$C$56))) -> 70002296 | U10: =IFERROR(T10/T9-1,"")
A11: 5 | B11: 18/19 | C11: ='Agg (Peru Included)'!C11/B$62 -> 10671216 | D11: ='Agg (Peru Included)'!D11/C$62 -> 10743708 | E11: ='Agg (Peru Included)'!E11/D$62 -> 10946305 | F11: ='Agg (Peru Included)'!F11/E$62 -> 11402899 | G11: ='Agg (Peru Included)'!G11/F$62 -> 10870670 | H11: ='Agg (Peru Included)'!H11/G$62 -> 11355909 | I11: ='Agg (Peru Included)'!I11/H$62 -> 11009151 | J11: ='Agg (Peru Included)'!J11/I$62 -> 12302119 | ... N11: ='Agg (Peru Included)'!N11/M$62 -> 10612658 | O11: 18/19 | P11: =IF(COUNT(C11:N11)=12,SUM(C11:N11),"") -> 1.3408852e+08 | Q11: =IFERROR(P11/P10-1,"") -> 0.099676516 | S11: 18/19 | T11: =IF(SUM(OFFSET(C11,0,0,1,$C$56))=0,"",SUM(OFFSET(C11,0,0,1,$C$56))) -> 76999858 | U11: =IFERROR(T11/T10-1,"") -> 0.099961885
A12: 6 | B12: 19/20 | C12: ='Agg (Peru Included)'!C12/B$62 -> 9950618.6 | D12: ='Agg (Peru Included)'!D12/C$62 -> 9643185.1 | E12: ='Agg (Peru Included)'!E12/D$62 -> 10815733 | F12: ='Agg (Peru Included)'!F12/E$62 -> 10204715 | G12: ='Agg (Peru Included)'!G12/F$62 -> 11530570 | H12: ='Agg (Peru Included)'!H12/G$62 -> 12146818 | I12: ='Agg (Peru Included)'!I12/H$62 -> 11261492 | J12: ='Agg (Peru Included)'!J12/I$62 -> 10719891 | ... N12: ='Agg (Peru Included)'!N12/M$62 -> 11117875 | O12: 19/20 | P12: =IF(COUNT(C12:N12)=12,SUM(C12:N12),"") -> 1.2906282e+08 | Q12: =IFERROR(P12/P11-1,"") -> -0.037480448 | S12: 19/20 | T12: =IF(SUM(OFFSET(C12,0,0,1,$C$56))=0,"",SUM(OFFSET(C12,0,0,1,$C$56))) -> 75553132 | U12: =IFERROR(T12/T11-1,"") -> -0.018788685
A13: 7 | B13: 20/21 | C13: ='Agg (Peru Included)'!C13/B$62 -> 10162602 | D13: ='Agg (Peru Included)'!D13/C$62 -> 10538824 | E13: ='Agg (Peru Included)'!E13/D$62 -> 11492075 | F13: ='Agg (Peru Included)'!F13/E$62 -> 10563890 | G13: ='Agg (Peru Included)'!G13/F$62 -> 11616779 | H13: ='Agg (Peru Included)'!H13/G$62 -> 12688275 | I13: ='Agg (Peru Included)'!I13/H$62 -> 11757782 | J13: ='Agg (Peru Included)'!J13/I$62 -> 10523204 | ... N13: ='Agg (Peru Included)'!N13/M$62 -> 10786931 | O13: 20/21 | P13: =IF(COUNT(C13:N13)=12,SUM(C13:N13),"") -> 1.3337181e+08 | Q13: =IFERROR(P13/P12-1,"") -> 0.033386777 | S13: 20/21 | T13: =IF(SUM(OFFSET(C13,0,0,1,$C$56))=0,"",SUM(OFFSET(C13,0,0,1,$C$56))) -> 78820228 | U13: =IFERROR(T13/T12-1,"") -> 0.043242365
A14: 8 | B14: 21/22 | C14: ='Agg (Peru Included)'!C14/B$62 -> 9949518.2 | D14: ='Agg (Peru Included)'!D14/C$62 -> 9804067.7 | E14: ='Agg (Peru Included)'!E14/D$62 -> 11958329 | F14: ='Agg (Peru Included)'!F14/E$62 -> 12230473 | G14: ='Agg (Peru Included)'!G14/F$62 -> 11436850 | H14: ='Agg (Peru Included)'!H14/G$62 -> 13501957 | I14: ='Agg (Peru Included)'!I14/H$62 -> 11053003 | J14: ='Agg (Peru Included)'!J14/I$62 -> 11157468 | ... N14: ='Agg (Peru Included)'!N14/M$62 -> 10524776 | O14: 21/22 | P14: =IF(COUNT(C14:N14)=12,SUM(C14:N14),"") -> 1.3386133e+08 | Q14: =IFERROR(P14/P13-1,"") -> 0.0036702904 | S14: 21/22 | T14: =IF(SUM(OFFSET(C14,0,0,1,$C$56))=0,NA(),SUM(OFFSET(C14,0,0,1,$C$56))) -> 79934198 | U14: =IFERROR(T14/T13-1,"") -> 0.014133054
A15: 9 | B15: 22/23 | C15: ='Agg (Peru Included)'!C15/B$62 -> 9284589.2 | D15: ='Agg (Peru Included)'!D15/C$62 -> 10009216 | E15: ='Agg (Peru Included)'!E15/D$62 -> 10436284 | F15: ='Agg (Peru Included)'!F15/E$62 -> 9284724.4 | G15: ='Agg (Peru Included)'!G15/F$62 -> 10011139 | H15: ='Agg (Peru Included)'!H15/G$62 -> 11791649 | I15: ='Agg (Peru Included)'!I15/H$62 -> 10468151 | J15: ='Agg (Peru Included)'!J15/I$62 -> 10767191 | ... N15: ='Agg (Peru Included)'!N15/M$62 -> 9030134.5 | O15: 22/23 | P15: =IF(COUNT(C15:N15)=12,SUM(C15:N15),"") -> 1.2308611e+08 | Q15: =IFERROR(P15/P14-1,"") -> -0.080495379 | S15: 22/23 | T15: =IF(SUM(OFFSET(C15,0,0,1,$C$56))=0,NA(),SUM(OFFSET(C15,0,0,1,$C$56))) -> 71285753 | U15: =IFERROR(T15/T14-1,"") -> -0.10819456
A16: 10 | B16: 23/24 | C16: ='Agg (Peru Included)'!C16/B$62 -> 9231980.4 | D16: ='Agg (Peru Included)'!D16/C$62 -> 10576042 | E16: ='Agg (Peru Included)'!E16/D$62 -> 11674083 | F16: ='Agg (Peru Included)'!F16/E$62 -> 11865036 | G16: ='Agg (Peru Included)'!G16/F$62 -> 11768315 | H16: ='Agg (Peru Included)'!H16/G$62 -> 13170237 | I16: ='Agg (Peru Included)'!I16/H$62 -> 12194971 | J16: ='Agg (Peru Included)'!J16/I$62 -> 12267034 | ... N16: ='Agg (Peru Included)'!N16/M$62 -> 11372709 | O16: 23/24 | P16: =IF(COUNT(C16:N16)=12,SUM(C16:N16),"") -> 1.3859341e+08 | Q16: =IFERROR(P16/P15-1,"") -> 0.12598745 | S16: 23/24 | T16: =IF(SUM(OFFSET(C16,0,0,1,$C$56))=0,NA(),SUM(OFFSET(C16,0,0,1,$C$56))) -> 80480664 | U16: =IFERROR(T16/T15-1,"") -> 0.12898666
A17: 11 | B17: 24/25 | C17: ='Agg (Peru Included)'!C17/B$62 -> 10738180 | D17: ='Agg (Peru Included)'!D17/C$62 -> 9660552.2 | E17: ='Agg (Peru Included)'!E17/D$62 -> 11407317 | F17: ='Agg (Peru Included)'!F17/E$62 -> 10330331 | G17: ='Agg (Peru Included)'!G17/F$62 -> 12152402 | H17: ='Agg (Peru Included)'!H17/G$62 -> 13077777 | I17: ='Agg (Peru Included)'!I17/H$62 -> 12045430 | J17: ='Agg (Peru Included)'!J17/I$62 -> 12729545 | ... N17: ='Agg (Peru Included)'!N17/M$62 -> 11947550 | O17: 24/25 | P17: =IF(COUNT(C17:N17)=12,SUM(C17:N17),"") -> 1.3937611e+08 | Q17: =IFERROR(P17/P16-1,"") -> 0.0056474142 | S17: 24/25 | T17: =IF(SUM(OFFSET(C17,0,0,1,$C$56))=0,NA(),SUM(OFFSET(C17,0,0,1,$C$56))) -> 79411989 | U17: =IFERROR(T17/T16-1,"") -> -0.013278652
A18: 12 | B18: 25/26 | C18: ='Agg (Peru Included)'!C18/B$62 -> 10619765 | D18: ='Agg (Peru Included)'!D18/C$62 -> 9968464.3 | E18: ='Agg (Peru Included)'!E18/D$62 -> 10827103 | F18: ='Agg (Peru Included)'!F18/E$62 -> 10717514 | G18: ='Agg (Peru Included)'!G18/F$62 -> 10334148 | H18: ='Agg (Peru Included)'!H18/G$62 -> 11708877 | I18: ='Agg (Peru Included)'!I18/H$62 -> 12258305 | J18: ='Agg (Peru Included)'!J18/I$62 -> #N/A | ... N18: ='Agg (Peru Included)'!N18/M$62 -> #N/A | O18: 25/26 | P18: =IF(COUNT(C18:N18)=12,SUM(C18:N18),"") | Q18: =IFERROR(P18/P17-1,"") | S18: 25/26 | T18: =IF(SUM(OFFSET(C18,0,0,1,$C$56))=0,NA(),SUM(OFFSET(C18,0,0,1,$C$56))) -> 76434175 | U18: =IFERROR(T18/T17-1,"") -> -0.037498291
A19: 13 | B19: 26/27 | C19: ='Agg (Peru Included)'!C19/B$62 -> #N/A | D19: ='Agg (Peru Included)'!D19/C$62 -> #N/A | E19: ='Agg (Peru Included)'!E19/D$62 -> #N/A | F19: ='Agg (Peru Included)'!F19/E$62 -> #N/A | G19: ='Agg (Peru Included)'!G19/F$62 -> #N/A | H19: ='Agg (Peru Included)'!H19/G$62 -> #N/A | I19: ='Agg (Peru Included)'!I19/H$62 -> #N/A | J19: ='Agg (Peru Included)'!J19/I$62 -> #N/A | ... N19: ='Agg (Peru Included)'!N19/M$62 -> #N/A | O19: 26/27 | P19: =IF(COUNT(C19:N19)=12,SUM(C19:N19),"") | S19: 26/27 | T19: =IF(SUM(OFFSET(C19,0,0,1,$C$56))=0,NA(),SUM(OFFSET(C19,0,0,1,$C$56))) -> #N/A
B20: YoY | C20: =IFERROR(C18/C17-1,"") -> -0.011027472 | D20: =IFERROR(D18/D17-1,"") -> 0.031873141 | E20: =IFERROR(E18/E17-1,"") -> -0.05086332 | F20: =IFERROR(F18/F17-1,"") -> 0.037480147 | G20: =IFERROR(G18/G17-1,"") -> -0.14962099 | H20: =IFERROR(H18/H17-1,"") -> -0.10467372 | I20: =IFERROR(I18/I17-1,"") -> 0.017672642 | J20: =IFERROR(J18/J17-1,"") | ... N20: =IFERROR(N18/N17-1,"")
K27: =_xlfn.CONCAT(A1," | ",S6) -> Global Coffee Exports | YTD : Oct-Apr | Q27: =_xlfn.CONCAT(A1," | ","Cumulative") -> Global Coffee Exports | Cumulative
B56: Offset | C56: =COUNT(C18:N18) -> 7 | D56: =OFFSET(B6,0,$C$56,1,1) -> Apr | E56: =B18 -> 25/26 | F56: =_xlfn.CONCAT(D56,"'",E56) -> Apr'25/26
B58: =_xlfn.CONCAT(#REF!," (Monthly)") -> #REF!
B59: Oct | C59: Nov | D59: Dec | E59: Jan | F59: Feb | G59: Mar | H59: Apr | I59: May | J59: Jun | K59: Jul | L59: Aug | M59: Sep
A60: Proportion | B60: 0.76027428 | C60: 0.75388157 | D60: 0.79417851 | E60: 0.76566518 | F60: 0.75094893 | G60: 0.73124205 | H60: 0.70087238 | I60: 0.69260286 | J60: 0.71137729 | K60: 0.71381188 | L60: 0.75289842 | M60: 0.75875422
A62: Marex | B62: 0.87270099 | C62: 0.89 | D62: 0.88613177 | E62: 0.89492902 | F62: 0.81223848 | G62: 0.81726874 | H62: 0.78472807 | I62: 0.76797645 | J62: 0.76900732 | K62: 0.79269055 | L62: 0.79943939 | M62: 0.80003259
B65: Oct | C65: Nov | D65: Dec | E65: Jan | F65: Feb | G65: Mar | H65: Apr | I65: May | J65: Jun | K65: Jul | L65: Aug | M65: Sep
A66: =B18 -> 25/26 | B66: =C18 -> 10619765 | C66: =D18 -> 9968464.3 | D66: =E18 -> 10827103 | E66: =F18 -> 10717514 | F66: =G18 -> 10334148 | G66: =H18 -> 11708877 | H66: =I18 -> 12258305 | ... M66: =N18 -> #N/A
A67: Min | B67: =MIN(C10:C17) -> 8630970.5 | C67: =MIN(D10:D17) -> 9055937.6 | D67: =MIN(E10:E17) -> 10146942 | E67: =MIN(F10:F17) -> 9284724.4 | F67: =MIN(G10:G17) -> 10011139 | G67: =MIN(H10:H17) -> 11149435 | H67: =MIN(I10:I17) -> 10299318 | I67: =MIN(J10:J17) -> 9788242.8 | ... M67: =MIN(N10:N17) -> 9030134.5
A68: Max | B68: =MAX(C10:C17) -> 10738180 | C68: =MAX(D10:D17) -> 10743708 | D68: =MAX(E10:E17) -> 11958329 | E68: =MAX(F10:F17) -> 12230473 | F68: =MAX(G10:G17) -> 12152402 | G68: =MAX(H10:H17) -> 13501957 | H68: =MAX(I10:I17) -> 12194971 | I68: =MAX(J10:J17) -> 12729545 | ... M68: =MAX(N10:N17) -> 11947550
A69: Avg(5) | B69: =AVERAGE(C13:C17) -> 9873373.9 | C69: =AVERAGE(D13:D17) -> 10117740 | D69: =AVERAGE(E13:E17) -> 11393617 | E69: =AVERAGE(F13:F17) -> 10854891 | F69: =AVERAGE(G13:G17) -> 11397097 | G69: =AVERAGE(H13:H17) -> 12845979 | H69: =AVERAGE(I13:I17) -> 11503868 | I69: =AVERAGE(J13:J17) -> 11488888 | ... M69: =AVERAGE(N13:N17) -> 10732420
B74: 1 | C74: 1 | D74: =INDEX($C$7:$N$19,MATCH(B74,$A$7:$A$19),MATCH(C74,$C$4:$N$4)) -> #N/A | E74: =_xlfn.XLOOKUP(B74,$A$7:$A$19,$B$7:$B$19) -> 14/15 | F74: =_xlfn.XLOOKUP(C74,$C$4:$N$4,$C$6:$N$6) -> Oct | G74: =_xlfn.CONCAT(F74,"'",E74) -> Oct'14/15 | N74: Cumulative
B75: 1 | C75: 2 | D75: =INDEX($C$7:$N$19,MATCH(B75,$A$7:$A$19),MATCH(C75,$C$4:$N$4)) -> #N/A | E75: =_xlfn.XLOOKUP(B75,$A$7:$A$19,$B$7:$B$19) -> 14/15 | F75: =_xlfn.XLOOKUP(C75,$C$4:$N$4,$C$6:$N$6) -> Nov | G75: =_xlfn.CONCAT(F75,"'",E75) -> Nov'14/15 | N75: Oct | O75: Nov | P75: Dec | Q75: Jan | R75: Feb | S75: Mar | T75: Apr | U75: May | V75: Jun | W75: Jul | X75: Aug | Y75: Sep
B76: 1 | C76: 3 | D76: =INDEX($C$7:$N$19,MATCH(B76,$A$7:$A$19),MATCH(C76,$C$4:$N$4)) -> #N/A | E76: =_xlfn.XLOOKUP(B76,$A$7:$A$19,$B$7:$B$19) -> 14/15 | F76: =_xlfn.XLOOKUP(C76,$C$4:$N$4,$C$6:$N$6) -> Dec | G76: =_xlfn.CONCAT(F76,"'",E76) -> Dec'14/15 | M76: 14/15 | N76: =C7 -> #N/A | O76: =N76+D7 -> #N/A | P76: =O76+E7 -> #N/A | Q76: =P76+F7 -> #N/A | R76: =Q76+G7 -> #N/A | S76: =R76+H7 -> #N/A | T76: =S76+I7 -> #N/A | U76: =T76+J7 -> #N/A | V76: =U76+K7 -> #N/A | ... Y76: =X76+N7 -> #N/A
B77: 1 | C77: 4 | D77: =INDEX($C$7:$N$19,MATCH(B77,$A$7:$A$19),MATCH(C77,$C$4:$N$4)) -> #N/A | E77: =_xlfn.XLOOKUP(B77,$A$7:$A$19,$B$7:$B$19) -> 14/15 | F77: =_xlfn.XLOOKUP(C77,$C$4:$N$4,$C$6:$N$6) -> Jan | G77: =_xlfn.CONCAT(F77,"'",E77) -> Jan'14/15 | M77: 15/16 | N77: =C8 -> #N/A | O77: =N77+D8 -> #N/A | P77: =O77+E8 -> #N/A | Q77: =P77+F8 -> #N/A | R77: =Q77+G8 -> #N/A | S77: =R77+H8 -> #N/A | T77: =S77+I8 -> #N/A | U77: =T77+J8 -> #N/A | V77: =U77+K8 -> #N/A | ... Y77: =X77+N8 -> #N/A
B78: 1 | C78: 5 | D78: =INDEX($C$7:$N$19,MATCH(B78,$A$7:$A$19),MATCH(C78,$C$4:$N$4)) -> #N/A | E78: =_xlfn.XLOOKUP(B78,$A$7:$A$19,$B$7:$B$19) -> 14/15 | F78: =_xlfn.XLOOKUP(C78,$C$4:$N$4,$C$6:$N$6) -> Feb | G78: =_xlfn.CONCAT(F78,"'",E78) -> Feb'14/15 | M78: 16/17 | N78: =C9 -> #N/A | O78: =N78+D9 -> #N/A | P78: =O78+E9 -> #N/A | Q78: =P78+F9 -> #N/A | R78: =Q78+G9 -> #N/A | S78: =R78+H9 -> #N/A | T78: =S78+I9 -> #N/A | U78: =T78+J9 -> #N/A | V78: =U78+K9 -> #N/A | ... Y78: =X78+N9 -> #N/A
B79: 1 | C79: 6 | D79: =INDEX($C$7:$N$19,MATCH(B79,$A$7:$A$19),MATCH(C79,$C$4:$N$4)) -> #N/A | E79: =_xlfn.XLOOKUP(B79,$A$7:$A$19,$B$7:$B$19) -> 14/15 | F79: =_xlfn.XLOOKUP(C79,$C$4:$N$4,$C$6:$N$6) -> Mar | G79: =_xlfn.CONCAT(F79,"'",E79) -> Mar'14/15 | M79: 17/18 | N79: =C10 -> 8630970.5 | O79: =N79+D10 -> 17686908 | P79: =O79+E10 -> 27833850 | Q79: =P79+F10 -> 38520320 | R79: =Q79+G10 -> 48553544 | S79: =R79+H10 -> 59702979 | T79: =S79+I10 -> 70002296 | U79: =T79+J10 -> 79790539 | V79: =U79+K10 -> 90544458 | ... Y79: =X79+N10 -> 1.2193451e+08
B80: 1 | C80: 7 | D80: =INDEX($C$7:$N$19,MATCH(B80,$A$7:$A$19),MATCH(C80,$C$4:$N$4)) -> #N/A | E80: =_xlfn.XLOOKUP(B80,$A$7:$A$19,$B$7:$B$19) -> 14/15 | F80: =_xlfn.XLOOKUP(C80,$C$4:$N$4,$C$6:$N$6) -> Apr | G80: =_xlfn.CONCAT(F80,"'",E80) -> Apr'14/15 | M80: 18/19 | N80: =C11 -> 10671216 | O80: =N80+D11 -> 21414924 | P80: =O80+E11 -> 32361229 | Q80: =P80+F11 -> 43764128 | R80: =Q80+G11 -> 54634798 | S80: =R80+H11 -> 65990707 | T80: =S80+I11 -> 76999858 | U80: =T80+J11 -> 89301977 | V80: =U80+K11 -> 1.0072678e+08 | ... Y80: =X80+N11 -> 1.3408852e+08
B81: 1 | C81: 8 | D81: =INDEX($C$7:$N$19,MATCH(B81,$A$7:$A$19),MATCH(C81,$C$4:$N$4)) -> #N/A | E81: =_xlfn.XLOOKUP(B81,$A$7:$A$19,$B$7:$B$19) -> 14/15 | F81: =_xlfn.XLOOKUP(C81,$C$4:$N$4,$C$6:$N$6) -> May | G81: =_xlfn.CONCAT(F81,"'",E81) -> May'14/15 | M81: 19/20 | N81: =C12 -> 9950618.6 | O81: =N81+D12 -> 19593804 | P81: =O81+E12 -> 30409536 | Q81: =P81+F12 -> 40614251 | R81: =Q81+G12 -> 52144822 | S81: =R81+H12 -> 64291640 | T81: =S81+I12 -> 75553132 | U81: =T81+J12 -> 86273023 | V81: =U81+K12 -> 96936618 | ... Y81: =X81+N12 -> 1.2906282e+08
B82: 1 | C82: 9 | D82: =INDEX($C$7:$N$19,MATCH(B82,$A$7:$A$19),MATCH(C82,$C$4:$N$4)) -> #N/A | E82: =_xlfn.XLOOKUP(B82,$A$7:$A$19,$B$7:$B$19) -> 14/15 | F82: =_xlfn.XLOOKUP(C82,$C$4:$N$4,$C$6:$N$6) -> Jun | G82: =_xlfn.CONCAT(F82,"'",E82) -> Jun'14/15 | M82: 20/21 | N82: =C13 -> 10162602 | O82: =N82+D13 -> 20701427 | P82: =O82+E13 -> 32193501 | Q82: =P82+F13 -> 42757392 | R82: =Q82+G13 -> 54374171 | S82: =R82+H13 -> 67062446 | T82: =S82+I13 -> 78820228 | U82: =T82+J13 -> 89343432 | V82: =U82+K13 -> 1.0097994e+08 | ... Y82: =X82+N13 -> 1.3337181e+08
B83: 1 | C83: 10 | D83: =INDEX($C$7:$N$19,MATCH(B83,$A$7:$A$19),MATCH(C83,$C$4:$N$4)) -> #N/A | E83: =_xlfn.XLOOKUP(B83,$A$7:$A$19,$B$7:$B$19) -> 14/15 | F83: =_xlfn.XLOOKUP(C83,$C$4:$N$4,$C$6:$N$6) -> Jul | G83: =_xlfn.CONCAT(F83,"'",E83) -> Jul'14/15 | M83: 21/22 | N83: =C14 -> 9949518.2 | O83: =N83+D14 -> 19753586 | P83: =O83+E14 -> 31711915 | Q83: =P83+F14 -> 43942388 | R83: =Q83+G14 -> 55379238 | S83: =R83+H14 -> 68881195 | T83: =S83+I14 -> 79934198 | U83: =T83+J14 -> 91091666 | V83: =U83+K14 -> 1.0266955e+08 | ... Y83: =X83+N14 -> 1.3386133e+08
...

Sheet Global TDM + Vietnam
A1: Global + Vietnam
AH2: YTD | AI2: =_xlfn.CONCAT(AE5," | ",S6) -> | YTD : Oct-Apr
C4: 1 | D4: 2 | E4: 3 | F4: 4 | G4: 5 | H4: 6 | I4: 7 | J4: 8 | K4: 9 | L4: 10 | M4: 11 | N4: 12
C5: =_xlfn.CONCAT(A1," (Monthly)") -> Global + Vietnam (Monthly)
C6: Oct | D6: Nov | E6: Dec | F6: Jan | G6: Feb | H6: Mar | I6: Apr | J6: May | K6: Jun | L6: Jul | M6: Aug | N6: Sep | P6: Total | Q6: % | S6: =_xlfn.CONCAT("YTD : ",IF(C56=1,"Oct Only",_xlfn.CONCAT("Oct-",OFFSET(B6,0,$C$56,1,1)))) -> YTD : Oct-Apr
A7: 1 | B7: 14/15 | C7: #N/A | D7: #N/A | E7: #N/A | F7: #N/A | G7: #N/A | H7: #N/A | I7: #N/A | J7: #N/A | K7: #N/A | L7: #N/A | M7: #N/A | N7: #N/A | O7: 14/15 | P7: =IF(COUNT(C7:N7)=12,SUM(C7:N7),"") | S7: 14/15
A8: 2 | B8: 15/16 | C8: #N/A | D8: #N/A | E8: #N/A | F8: #N/A | G8: #N/A | H8: #N/A | I8: #N/A | J8: #N/A | K8: #N/A | L8: #N/A | M8: #N/A | N8: #N/A | O8: 15/16 | P8: =IF(COUNT(C8:N8)=12,SUM(C8:N8),"") | Q8: =IFERROR(P8/P7-1,"") | S8: 15/16 | U8: =IFERROR(T8/T7-1,"")
A9: 3 | B9: 16/17 | C9: 10954100 | D9: 11034100 | E9: 12652217 | F9: 11826133 | G9: 11680583 | H9: 13757350 | I9: 11601317 | J9: 12376150 | K9: 11541050 | L9: 11045100 | M9: 11236051 | N9: 10290317 | O9: 16/17 | P9: =IF(COUNT(C9:N9)=12,SUM(C9:N9),"") -> 1.3999447e+08 | Q9: =IFERROR(P9/P8-1,"") | S9: 16/17 | U9: =IFERROR(T9/T8-1,"")
A10: 4 | B10: 17/18 | C10: 10396267 | D10: 10860351 | E10: 11342100 | F10: 12900467 | G10: 11260350 | H10: 13237333 | I10: 12122650 | J10: 11890000 | K10: 12149100 | L10: 10616000 | M10: 11784100 | N10: 11177767 | O10: 17/18 | P10: =IF(COUNT(C10:N10)=12,SUM(C10:N10),"") -> 1.3973648e+08 | Q10: =IFERROR(P10/P9-1,"") -> -0.0018428112 | S10: 17/18 | T10: =IF(SUM(OFFSET(C10,0,0,1,$C$56))=0,"",SUM(OFFSET(C10,0,0,1,$C$56))) -> 82119518 | U10: =IFERROR(T10/T9-1,"")
A11: 5 | B11: 18/19 | C11: 12224967 | D11: 12735067 | E11: 12779850 | F11: 13426450 | G11: 12432000 | H11: 13950517 | I11: 12753717 | J11: 13959567 | K11: 12584000 | L11: 13364417 | M11: 12094300 | N11: 11605883 | O11: 18/19 | P11: =IF(COUNT(C11:N11)=12,SUM(C11:N11),"") -> 1.5391073e+08 | Q11: =IFERROR(P11/P10-1,"") -> 0.10143556 | S11: 18/19 | T11: =IF(SUM(OFFSET(C11,0,0,1,$C$56))=0,"",SUM(OFFSET(C11,0,0,1,$C$56))) -> 90302567 | U11: =IFERROR(T11/T10-1,"") -> 0.099648037
A12: 6 | B12: 19/20 | C12: 11643650 | D12: 11555817 | E12: 12828433 | F12: 11830383 | G12: 12610883 | H12: 13620083 | I12: 12939433 | J12: 12454833 | K12: 11763600 | L12: 12146700 | M12: 11151850 | N12: 11916917 | O12: 19/20 | P12: =IF(COUNT(C12:N12)=12,SUM(C12:N12),"") -> 1.4646258e+08 | Q12: =IFERROR(P12/P11-1,"") -> -0.048392661 | S12: 19/20 | T12: =IF(SUM(OFFSET(C12,0,0,1,$C$56))=0,"",SUM(OFFSET(C12,0,0,1,$C$56))) -> 87028683 | U12: =IFERROR(T12/T11-1,"") -> -0.036254599
A13: 7 | B13: 20/21 | C13: 11567333 | D13: 12117267 | E13: 13407133 | F13: 12576567 | G13: 12320967 | H13: 15164233 | I13: 13353100 | J13: 12368717 | K13: 12728500 | L13: 12304033 | M13: 11984117 | N13: 11860167 | O13: 20/21 | P13: =IF(COUNT(C13:N13)=12,SUM(C13:N13),"") -> 1.5175213e+08 | Q13: =IFERROR(P13/P12-1,"") -> 0.036115367 | S13: 20/21 | T13: =IF(SUM(OFFSET(C13,0,0,1,$C$56))=0,"",SUM(OFFSET(C13,0,0,1,$C$56))) -> 90506600 | U13: =IFERROR(T13/T12-1,"") -> 0.039962878
A14: 8 | B14: 21/22 | C14: 11563100 | D14: 11724150 | E14: 13447867 | F14: 13967500 | G14: 13086683 | H14: 15474783 | I14: 12712517 | J14: 12360383 | K14: 13552800 | L14: 13886233 | M14: 11867867 | N14: 11724367 | O14: 21/22 | P14: =IF(COUNT(C14:N14)=12,SUM(C14:N14),"") -> 155368250 | Q14: =IFERROR(P14/P13-1,"") -> 0.023829099 | S14: 21/22 | T14: =IF(SUM(OFFSET(C14,0,0,1,$C$56))=0,NA(),SUM(OFFSET(C14,0,0,1,$C$56))) -> 91976600 | U14: =IFERROR(T14/T13-1,"") -> 0.016241909
A15: 9 | B15: 22/23 | C15: 11325750 | D15: 12293467 | E15: 12538867 | F15: 10804587 | G15: 11385232 | H15: 12848742 | I15: 12011142 | J15: 12007556 | K15: 12114723 | L15: 12432448 | M15: 12144480 | N15: 9968256.5 | O15: 22/23 | P15: =IF(COUNT(C15:N15)=12,SUM(C15:N15),"") -> 1.4187525e+08 | Q15: =IFERROR(P15/P14-1,"") -> -0.086845287 | S15: 22/23 | T15: =IF(SUM(OFFSET(C15,0,0,1,$C$56))=0,NA(),SUM(OFFSET(C15,0,0,1,$C$56))) -> 83207786 | U15: =IFERROR(T15/T14-1,"") -> -0.095337446
A16: 10 | B16: 23/24 | C16: 10973177 | D16: 12626364 | E16: 13550975 | F16: 13829033 | G16: 12851367 | H16: 13485100 | I16: 14038250 | J16: 13329833 | K16: 12012067 | L16: 12524250 | M16: 12108167 | N16: 11953750 | O16: 23/24 | P16: =IF(COUNT(C16:N16)=12,SUM(C16:N16),"") -> 1.5328233e+08 | Q16: =IFERROR(P16/P15-1,"") -> 0.080402204 | S16: 23/24 | T16: =IF(SUM(OFFSET(C16,0,0,1,$C$56))=0,NA(),SUM(OFFSET(C16,0,0,1,$C$56))) -> 91354266 | U16: =IFERROR(T16/T15-1,"") -> 0.097905261
A17: 11 | B17: 24/25 | C17: 12596066 | D17: 11889967 | E17: 11809533 | F17: 13087433 | G17: 12776267 | H17: 14938467 | I17: 13238250 | J17: 13465617 | K17: 11940617 | L17: 12149850 | M17: 10918183 | N17: 11755967 | O17: 24/25 | P17: =IF(COUNT(C17:N17)=12,SUM(C17:N17),"") -> 1.5056622e+08 | Q17: =IFERROR(P17/P16-1,"") -> -0.017719697 | S17: 24/25 | T17: =IF(SUM(OFFSET(C17,0,0,1,$C$56))=0,NA(),SUM(OFFSET(C17,0,0,1,$C$56))) -> 90335983 | U17: =IFERROR(T17/T16-1,"") -> -0.011146527
A18: 12 | B18: 25/26 | C18: 10567150 | D18: ='S5 Arabica'!D18+'S5 Robusta'!D18 -> 8871933.3 | E18: ='S5 Arabica'!E18+'S5 Robusta'!E18 -> 9594239.5 | F18: ='S5 Arabica'!F18+'S5 Robusta'!F18 -> 9591414 | G18: ='S5 Arabica'!G18+'S5 Robusta'!G18 -> 8393792.3 | H18: ='S5 Arabica'!H18+'S5 Robusta'!H18 -> 9569299.3 | I18: ='S5 Arabica'!I18+'S5 Robusta'!I18 -> 9619436 | J18: ='S5 Arabica'!J18+'S5 Robusta'!J18 -> #N/A | K18: ='S5 Arabica'!K18+'S5 Robusta'!K18 -> #N/A | ... N18: ='S5 Arabica'!N18+'S5 Robusta'!N18 -> #N/A | O18: 25/26 | P18: =IF(COUNT(C18:N18)=12,SUM(C18:N18),"") | Q18: =IFERROR(P18/P17-1,"") | S18: 25/26 | T18: =IF(SUM(OFFSET(C18,0,0,1,$C$56))=0,NA(),SUM(OFFSET(C18,0,0,1,$C$56))) -> 66207264 | U18: =IFERROR(T18/T17-1,"") -> -0.26709975
A19: 13 | B19: 26/27 | C19: =NA() -> #N/A | D19: =NA() -> #N/A | E19: =NA() -> #N/A | F19: =NA() -> #N/A | G19: =NA() -> #N/A | H19: =NA() -> #N/A | I19: =NA() -> #N/A | J19: =NA() -> #N/A | ... N19: =NA() -> #N/A | O19: 26/27 | P19: =IF(COUNT(C19:N19)=12,SUM(C19:N19),"") | S19: 26/27 | T19: =IF(SUM(OFFSET(C19,0,0,1,$C$56))=0,NA(),SUM(OFFSET(C19,0,0,1,$C$56))) -> #N/A
B20: YoY | C20: =IFERROR(C18/C17-1,"") -> -0.16107539 | D20: =IFERROR(D18/D17-1,"") -> -0.25383027 | E20: =IFERROR(E18/E17-1,"") -> -0.18758521 | F20: =IFERROR(F18/F17-1,"") -> -0.26712796 | G20: =IFERROR(G18/G17-1,"") -> -0.34301682 | H20: =IFERROR(H18/H17-1,"") -> -0.35941891 | I20: =IFERROR(I18/I17-1,"") -> -0.27336045 | J20: =IFERROR(J18/J17-1,"") | ... N20: =IFERROR(N18/N17-1,"")
K27: =_xlfn.CONCAT(A1," | ",S6) -> Global + Vietnam | YTD : Oct-Apr | Q27: =_xlfn.CONCAT(A1," | ","Cumulative") -> Global + Vietnam | Cumulative
B56: Offset | C56: =COUNT(C18:N18) -> 7 | D56: =OFFSET(B6,0,$C$56,1,1) -> Apr | E56: =B18 -> 25/26 | F56: =_xlfn.CONCAT(D56,"'",E56) -> Apr'25/26
B58: =_xlfn.CONCAT(#REF!," (Monthly)") -> #REF!
B59: Oct | C59: Nov | D59: Dec | E59: Jan | F59: Feb | G59: Mar | H59: Apr | I59: May | J59: Jun | K59: Jul | L59: Aug | M59: Sep
A60: Proportion | B60: 0.76027428 | C60: 0.75388157 | D60: 0.79417851 | E60: 0.76566518 | F60: 0.75094893 | G60: 0.73124205 | H60: 0.70087238 | I60: 0.69260286 | J60: 0.71137729 | K60: 0.71381188 | L60: 0.75289842 | M60: 0.75875422
B65: Oct | C65: Nov | D65: Dec | E65: Jan | F65: Feb | G65: Mar | H65: Apr | I65: May | J65: Jun | K65: Jul | L65: Aug | M65: Sep
A66: =B18 -> 25/26 | B66: =C18 -> 10567150 | C66: =D18 -> 8871933.3 | D66: =E18 -> 9594239.5 | E66: =F18 -> 9591414 | F66: =G18 -> 8393792.3 | G66: =H18 -> 9569299.3 | H66: =I18 -> 9619436 | ... M66: =N18 -> #N/A
A67: Min | B67: =MIN(C10:C17) -> 10396267 | C67: =MIN(D10:D17) -> 10860351 | D67: =MIN(E10:E17) -> 11342100 | E67: =MIN(F10:F17) -> 10804587 | F67: =MIN(G10:G17) -> 11260350 | G67: =MIN(H10:H17) -> 12848742 | H67: =MIN(I10:I17) -> 12011142 | I67: =MIN(J10:J17) -> 11890000 | ... M67: =MIN(N10:N17) -> 9968256.5
A68: Max | B68: =MAX(C10:C17) -> 12596066 | C68: =MAX(D10:D17) -> 12735067 | D68: =MAX(E10:E17) -> 13550975 | E68: =MAX(F10:F17) -> 13967500 | F68: =MAX(G10:G17) -> 13086683 | G68: =MAX(H10:H17) -> 15474783 | H68: =MAX(I10:I17) -> 14038250 | I68: =MAX(J10:J17) -> 13959567 | ... M68: =MAX(N10:N17) -> 11953750
A69: Avg(5) | B69: =AVERAGE(C13:C17) -> 11605085 | C69: =AVERAGE(D13:D17) -> 12130243 | D69: =AVERAGE(E13:E17) -> 12950875 | E69: =AVERAGE(F13:F17) -> 12853024 | F69: =AVERAGE(G13:G17) -> 12484103 | G69: =AVERAGE(H13:H17) -> 14382265 | H69: =AVERAGE(I13:I17) -> 13070652 | I69: =AVERAGE(J13:J17) -> 12706421 | ... M69: =AVERAGE(N13:N17) -> 11452501
B74: 1 | C74: 1 | D74: =INDEX($C$7:$N$19,MATCH(B74,$A$7:$A$19),MATCH(C74,$C$4:$N$4)) -> #N/A | E74: =_xlfn.XLOOKUP(B74,$A$7:$A$19,$B$7:$B$19) -> 14/15 | F74: =_xlfn.XLOOKUP(C74,$C$4:$N$4,$C$6:$N$6) -> Oct | G74: =_xlfn.CONCAT(F74,"'",E74) -> Oct'14/15 | N74: Cumulative
B75: 1 | C75: 2 | D75: =INDEX($C$7:$N$19,MATCH(B75,$A$7:$A$19),MATCH(C75,$C$4:$N$4)) -> #N/A | E75: =_xlfn.XLOOKUP(B75,$A$7:$A$19,$B$7:$B$19) -> 14/15 | F75: =_xlfn.XLOOKUP(C75,$C$4:$N$4,$C$6:$N$6) -> Nov | G75: =_xlfn.CONCAT(F75,"'",E75) -> Nov'14/15 | N75: Oct | O75: Nov | P75: Dec | Q75: Jan | R75: Feb | S75: Mar | T75: Apr | U75: May | V75: Jun | W75: Jul | X75: Aug | Y75: Sep
B76: 1 | C76: 3 | D76: =INDEX($C$7:$N$19,MATCH(B76,$A$7:$A$19),MATCH(C76,$C$4:$N$4)) -> #N/A | E76: =_xlfn.XLOOKUP(B76,$A$7:$A$19,$B$7:$B$19) -> 14/15 | F76: =_xlfn.XLOOKUP(C76,$C$4:$N$4,$C$6:$N$6) -> Dec | G76: =_xlfn.CONCAT(F76,"'",E76) -> Dec'14/15 | M76: 14/15 | N76: =C7 -> #N/A | O76: =N76+D7 -> #N/A | P76: =O76+E7 -> #N/A | Q76: =P76+F7 -> #N/A | R76: =Q76+G7 -> #N/A | S76: =R76+H7 -> #N/A | T76: =S76+I7 -> #N/A | U76: =T76+J7 -> #N/A | V76: =U76+K7 -> #N/A | ... Y76: =X76+N7 -> #N/A
B77: 1 | C77: 4 | D77: =INDEX($C$7:$N$19,MATCH(B77,$A$7:$A$19),MATCH(C77,$C$4:$N$4)) -> #N/A | E77: =_xlfn.XLOOKUP(B77,$A$7:$A$19,$B$7:$B$19) -> 14/15 | F77: =_xlfn.XLOOKUP(C77,$C$4:$N$4,$C$6:$N$6) -> Jan | G77: =_xlfn.CONCAT(F77,"'",E77) -> Jan'14/15 | M77: 15/16 | N77: =C8 -> #N/A | O77: =N77+D8 -> #N/A | P77: =O77+E8 -> #N/A | Q77: =P77+F8 -> #N/A | R77: =Q77+G8 -> #N/A | S77: =R77+H8 -> #N/A | T77: =S77+I8 -> #N/A | U77: =T77+J8 -> #N/A | V77: =U77+K8 -> #N/A | ... Y77: =X77+N8 -> #N/A
B78: 1 | C78: 5 | D78: =INDEX($C$7:$N$19,MATCH(B78,$A$7:$A$19),MATCH(C78,$C$4:$N$4)) -> #N/A | E78: =_xlfn.XLOOKUP(B78,$A$7:$A$19,$B$7:$B$19) -> 14/15 | F78: =_xlfn.XLOOKUP(C78,$C$4:$N$4,$C$6:$N$6) -> Feb | G78: =_xlfn.CONCAT(F78,"'",E78) -> Feb'14/15 | M78: 16/17 | N78: =C9 -> 10954100 | O78: =N78+D9 -> 21988200 | P78: =O78+E9 -> 34640417 | Q78: =P78+F9 -> 46466550 | R78: =Q78+G9 -> 58147133 | S78: =R78+H9 -> 71904483 | T78: =S78+I9 -> 83505800 | U78: =T78+J9 -> 95881950 | V78: =U78+K9 -> 1.07423e+08 | ... Y78: =X78+N9 -> 1.3999447e+08
B79: 1 | C79: 6 | D79: =INDEX($C$7:$N$19,MATCH(B79,$A$7:$A$19),MATCH(C79,$C$4:$N$4)) -> #N/A | E79: =_xlfn.XLOOKUP(B79,$A$7:$A$19,$B$7:$B$19) -> 14/15 | F79: =_xlfn.XLOOKUP(C79,$C$4:$N$4,$C$6:$N$6) -> Mar | G79: =_xlfn.CONCAT(F79,"'",E79) -> Mar'14/15 | M79: 17/18 | N79: =C10 -> 10396267 | O79: =N79+D10 -> 21256618 | P79: =O79+E10 -> 32598718 | Q79: =P79+F10 -> 45499185 | R79: =Q79+G10 -> 56759535 | S79: =R79+H10 -> 69996868 | T79: =S79+I10 -> 82119518 | U79: =T79+J10 -> 94009518 | V79: =U79+K10 -> 1.0615862e+08 | ... Y79: =X79+N10 -> 1.3973648e+08
B80: 1 | C80: 7 | D80: =INDEX($C$7:$N$19,MATCH(B80,$A$7:$A$19),MATCH(C80,$C$4:$N$4)) -> #N/A | E80: =_xlfn.XLOOKUP(B80,$A$7:$A$19,$B$7:$B$19) -> 14/15 | F80: =_xlfn.XLOOKUP(C80,$C$4:$N$4,$C$6:$N$6) -> Apr | G80: =_xlfn.CONCAT(F80,"'",E80) -> Apr'14/15 | M80: 18/19 | N80: =C11 -> 12224967 | O80: =N80+D11 -> 24960033 | P80: =O80+E11 -> 37739883 | Q80: =P80+F11 -> 51166333 | R80: =Q80+G11 -> 63598333 | S80: =R80+H11 -> 77548850 | T80: =S80+I11 -> 90302567 | U80: =T80+J11 -> 1.0426213e+08 | V80: =U80+K11 -> 1.1684613e+08 | ... Y80: =X80+N11 -> 1.5391073e+08
B81: 1 | C81: 8 | D81: =INDEX($C$7:$N$19,MATCH(B81,$A$7:$A$19),MATCH(C81,$C$4:$N$4)) -> #N/A | E81: =_xlfn.XLOOKUP(B81,$A$7:$A$19,$B$7:$B$19) -> 14/15 | F81: =_xlfn.XLOOKUP(C81,$C$4:$N$4,$C$6:$N$6) -> May | G81: =_xlfn.CONCAT(F81,"'",E81) -> May'14/15 | M81: 19/20 | N81: =C12 -> 11643650 | O81: =N81+D12 -> 23199467 | P81: =O81+E12 -> 36027900 | Q81: =P81+F12 -> 47858283 | R81: =Q81+G12 -> 60469167 | S81: =R81+H12 -> 74089250 | T81: =S81+I12 -> 87028683 | U81: =T81+J12 -> 99483517 | V81: =U81+K12 -> 1.1124712e+08 | ... Y81: =X81+N12 -> 1.4646258e+08
B82: 1 | C82: 9 | D82: =INDEX($C$7:$N$19,MATCH(B82,$A$7:$A$19),MATCH(C82,$C$4:$N$4)) -> #N/A | E82: =_xlfn.XLOOKUP(B82,$A$7:$A$19,$B$7:$B$19) -> 14/15 | F82: =_xlfn.XLOOKUP(C82,$C$4:$N$4,$C$6:$N$6) -> Jun | G82: =_xlfn.CONCAT(F82,"'",E82) -> Jun'14/15 | M82: 20/21 | N82: =C13 -> 11567333 | O82: =N82+D13 -> 23684600 | P82: =O82+E13 -> 37091733 | Q82: =P82+F13 -> 49668300 | R82: =Q82+G13 -> 61989267 | S82: =R82+H13 -> 77153500 | T82: =S82+I13 -> 90506600 | U82: =T82+J13 -> 1.0287532e+08 | V82: =U82+K13 -> 1.1560382e+08 | ... Y82: =X82+N13 -> 1.5175213e+08
B83: 1 | C83: 10 | D83: =INDEX($C$7:$N$19,MATCH(B83,$A$7:$A$19),MATCH(C83,$C$4:$N$4)) -> #N/A | E83: =_xlfn.XLOOKUP(B83,$A$7:$A$19,$B$7:$B$19) -> 14/15 | F83: =_xlfn.XLOOKUP(C83,$C$4:$N$4,$C$6:$N$6) -> Jul | G83: =_xlfn.CONCAT(F83,"'",E83) -> Jul'14/15 | M83: 21/22 | N83: =C14 -> 11563100 | O83: =N83+D14 -> 23287250 | P83: =O83+E14 -> 36735117 | Q83: =P83+F14 -> 50702617 | R83: =Q83+G14 -> 63789300 | S83: =R83+H14 -> 79264083 | T83: =S83+I14 -> 91976600 | U83: =T83+J14 -> 1.0433698e+08 | V83: =U83+K14 -> 1.1788978e+08 | ... Y83: =X83+N14 -> 155368250
B84: 1 | C84: 11 | D84: =INDEX($C$7:$N$19,MATCH(B84,$A$7:$A$19),MATCH(C84,$C$4:$N$4)) -> #N/A | E84: =_xlfn.XLOOKUP(B84,$A$7:$A$19,$B$7:$B$19) -> 14/15 | F84: =_xlfn.XLOOKUP(C84,$C$4:$N$4,$C$6:$N$6) -> Aug | G84: =_xlfn.CONCAT(F84,"'",E84) -> Aug'14/15 | H84: Month | I84: Rolling 12m Sum | M84: 22/23 | N84: =C15 -> 11325750 | O84: =N84+D15 -> 23619217 | P84: =O84+E15 -> 36158083 | Q84: =P84+F15 -> 46962670 | R84: =Q84+G15 -> 58347902 | S84: =R84+H15 -> 71196644 | T84: =S84+I15 -> 83207786 | U84: =T84+J15 -> 95215342 | V84: =U84+K15 -> 1.0733006e+08 | ... Y84: =X84+N15 -> 1.4187525e+08
...

Sheet Total TDM
D7: Oct | E7: Nov | F7: Dec | G7: Jan | H7: Feb | I7: Mar | J7: Apr | K7: May | L7: Jun | M7: Jul | N7: Aug | O7: Sep
C8: 16/17 | D8: 9003483.3 | E8: 9124466.7 | F8: 10191050 | G8: 8744183.3 | H8: 8882583.3 | I8: 10657183 | J8: 9207983.3 | K8: 10248000 | L8: 9513283.3 | M8: 9364916.7 | N8: 9653016.7 | O8: 8965316.7
C9: 17/18 | D9: 9075233.3 | E9: 9114483.3 | F9: 8609816.7 | G9: 9294016.7 | H9: 8985750 | I9: 9728583.3 | J9: 9396500 | K9: 9301300 | L9: 9551416.7 | M9: 8372466.7 | N9: 9232516.7 | O9: 9167066.7
C10: 18/19 | D10: 9929800 | E10: 10413233 | F10: 10222200 | G10: 10065750 | H10: 10525033 | I10: 11086733 | J10: 10359700 | K10: 11541350 | L10: 10179417 | M10: 11009717 | N10: 10192300 | O10: 10067467
C11: 19/20 | D11: 10158533 | E11: 9687900 | F11: 9698716.7 | G11: 9405900 | H11: 9501916.7 | I11: 10558450 | J11: 10155133 | K11: 10285900 | L11: 9635700 | M11: 10312950 | N11: 9482650 | O11: 10254750
C12: 20/21 | D12: 10033733 | E12: 10721633 | F12: 11089700 | G12: 9900050 | H12: 10270217 | I12: 12337400 | J12: 11152483 | K12: 10197933 | L12: 10595183 | M12: 10268583 | N12: 10122500 | O12: 10187833
B13: tdm global | C13: 21/22 | D13: 9908950 | E13: 9932933.3 | F13: 10625383 | G13: 10109717 | H13: 10756483 | I13: 11964783 | J13: 10091933 | K13: 9986716.7 | L13: 11263667 | M13: 11988700 | N13: 9992350 | O13: 10181867
C14: 22/23 | D14: 9995200 | E14: 10153417 | F14: 9254250 | G14: 18381517 | H14: 17358500 | I14: 20666350 | J14: 17833667 | K14: 19742900 | L14: 19269517 | M14: 18194550 | N14: 19656117 | O14: 18864267
C15: 23/24 | D15: 20424533 | E15: 20423217 | F15: 19893700 | G15: 9857933.3 | H15: 10174967 | I15: 10335567 | J15: 11503700 | K15: 12007200 | L15: 10842033 | M15: 11241217 | N15: 10837933 | O15: 11163783
C16: 24/25 | D16: 11862733 | E16: 10839650 | F16: 9709533.3 | G16: 10854017 | H16: 9945733.3 | I16: 11919883 | J16: 10461483 | K16: 10986250 | L16: 9974233.3 | M16: 10450200 | N16: 9517150 | O16: 10404317
C17: 25/26 | D17: 9428550
C20: 16/17 | D20: 1950616.7 | E20: 1909633.3 | F20: 2461166.7 | G20: 3081950 | H20: 2798000 | I20: 3100166.7 | J20: 2393333.3 | K20: 2128150 | L20: 2027766.7 | M20: 1680183.3 | N20: 1583034.6 | O20: 1325000
C21: 17/18 | D21: 1321033.3 | E21: 1745867.9 | F21: 2732283.3 | G21: 3606450 | H21: 2274600 | I21: 3508750 | J21: 2726150 | K21: 2588700 | L21: 2597683.3 | M21: 2243533.3 | N21: 2551583.3 | O21: 2010700
C22: 18/19 | D22: 2295166.7 | E22: 2321833.3 | F22: 2557650 | G22: 3360700 | H22: 1906966.7 | I22: 2863783.3 | J22: 2394016.7 | K22: 2418216.7 | L22: 2404583.3 | M22: 2354700 | N22: 1902000 | O22: 1538416.7
B23: vietnam | C23: 19/20 | D23: 1485116.7 | E23: 1867916.7 | F23: 3129716.7 | G23: 2424483.3 | H23: 3108966.7 | I23: 3061633.3 | J23: 2784300 | K23: 2168933.3 | L23: 2127900 | M23: 1833750 | N23: 1669200 | O23: 1662166.7
C24: 20/21 | D24: 1533600 | E24: 1395633.3 | F24: 2317433.3 | G24: 2676516.7 | H24: 2050750 | I24: 2826833.3 | J24: 2200616.7 | K24: 2170783.3 | L24: 2133316.7 | M24: 2035450 | N24: 1861616.7 | O24: 1672333.3
C25: 21/22 | D25: 1654150 | E25: 1791216.7 | F25: 2822483.3 | G25: 3857783.3 | H25: 2330200 | I25: 3510000 | J25: 2620583.3 | K25: 2373666.7 | L25: 2289133.3 | M25: 1897533.3 | N25: 1875516.7 | O25: 1542500
C26: 22/23 | D26: 1330550 | E26: 2140050 | F26: 3284616.7 | G26: 2798175.3 | H26: 2889494.8 | I26: 3563541.7 | J26: 2790325 | K26: 2533780.3 | L26: 2406991.7 | M26: 1995386.2 | N26: 1563541.7 | O26: 912991.69
C27: 23/24 | D27: 728750 | E27: 1988283.3 | F27: 3460216.7 | G27: 3971100 | H27: 2676400 | I27: 3149533.3 | J27: 2534550 | K27: 1322633.3 | L27: 1170033.3 | M27: 1283033.3 | N27: 1270233.3 | O27: 789966.67
C28: 24/25 | D28: 733333 | E28: 1050316.7 | F28: 2100000 | G28: 2233416.7 | H28: 2830533.3 | I28: 3018583.3 | J28: 2776766.7 | K28: 2479366.7 | L28: 1966383.3 | M28: 1699650 | N28: 1401033 | O28: 1351650
C29: 25/26 | D29: 1138600 | E29: 1480200 | F29: 2537266.7
D32: Oct | E32: Nov | F32: Dec | G32: Jan | H32: Feb | I32: Mar | J32: Apr | K32: May | L32: Jun | M32: Jul | N32: Aug | O32: Sep
C33: 16/17 | D33: =D8+D20 -> 10954100 | E33: =E8+E20 -> 11034100 | F33: =F8+F20 -> 12652217 | G33: =G8+G20 -> 11826133 | H33: =H8+H20 -> 11680583 | I33: =I8+I20 -> 13757350 | J33: =J8+J20 -> 11601317 | K33: =K8+K20 -> 12376150 | ... O33: =O8+O20 -> 10290317
C34: 17/18 | D34: =D9+D21 -> 10396267 | E34: =E9+E21 -> 10860351 | F34: =F9+F21 -> 11342100 | G34: =G9+G21 -> 12900467 | H34: =H9+H21 -> 11260350 | I34: =I9+I21 -> 13237333 | J34: =J9+J21 -> 12122650 | K34: =K9+K21 -> 11890000 | ... O34: =O9+O21 -> 11177767
C35: 18/19 | D35: =D10+D22 -> 12224967 | E35: =E10+E22 -> 12735067 | F35: =F10+F22 -> 12779850 | G35: =G10+G22 -> 13426450 | H35: =H10+H22 -> 12432000 | I35: =I10+I22 -> 13950517 | J35: =J10+J22 -> 12753717 | K35: =K10+K22 -> 13959567 | ... O35: =O10+O22 -> 11605883
C36: 19/20 | D36: =D11+D23 -> 11643650 | E36: =E11+E23 -> 11555817 | F36: =F11+F23 -> 12828433 | G36: =G11+G23 -> 11830383 | H36: =H11+H23 -> 12610883 | I36: =I11+I23 -> 13620083 | J36: =J11+J23 -> 12939433 | K36: =K11+K23 -> 12454833 | ... O36: =O11+O23 -> 11916917
B37: tdm total | C37: 20/21 | D37: =D12+D24 -> 11567333 | E37: =E12+E24 -> 12117267 | F37: =F12+F24 -> 13407133 | G37: =G12+G24 -> 12576567 | H37: =H12+H24 -> 12320967 | I37: =I12+I24 -> 15164233 | J37: =J12+J24 -> 13353100 | K37: =K12+K24 -> 12368717 | ... O37: =O12+O24 -> 11860167
C38: 21/22 | D38: =D13+D25 -> 11563100 | E38: =E13+E25 -> 11724150 | F38: =F13+F25 -> 13447867 | G38: =G13+G25 -> 13967500 | H38: =H13+H25 -> 13086683 | I38: =I13+I25 -> 15474783 | J38: =J13+J25 -> 12712517 | K38: =K13+K25 -> 12360383 | ... O38: =O13+O25 -> 11724367
C39: 22/23 | D39: =D14+D26 -> 11325750 | E39: =E14+E26 -> 12293467 | F39: =F14+F26 -> 12538867 | G39: =G14+G26 -> 21179692 | H39: =H14+H26 -> 20247995 | I39: =I14+I26 -> 24229892 | J39: =J14+J26 -> 20623992 | K39: =K14+K26 -> 22276680 | ... O39: =O14+O26 -> 19777258
C40: 23/24 | D40: =D15+D27 -> 21153283 | E40: =E15+E27 -> 22411500 | F40: =F15+F27 -> 23353917 | G40: =G15+G27 -> 13829033 | H40: =H15+H27 -> 12851367 | I40: =I15+I27 -> 13485100 | J40: =J15+J27 -> 14038250 | K40: =K15+K27 -> 13329833 | ... O40: =O15+O27 -> 11953750
C41: 24/25 | D41: =D16+D28 -> 12596066 | E41: =E16+E28 -> 11889967 | F41: =F16+F28 -> 11809533 | G41: =G16+G28 -> 13087433 | H41: =H16+H28 -> 12776267 | I41: =I16+I28 -> 14938467 | J41: =J16+J28 -> 13238250 | K41: =K16+K28 -> 13465617 | ... O41: =O16+O28 -> 11755967
C42: 25/26 | D42: =D17+D29 -> 10567150
C45: 17/18 | D45: 7786276.9 | E45: 8577446.3 | F45: 9539526.4 | G45: 9810956.6 | H45: 8597343.8 | I45: 9526847.3 | J45: 8666045.7 | K45: 8218553.2 | L45: 8482591.5 | M45: 8295286.2 | N45: 9350969.3 | O45: 8823046.9
C46: 18/19 | D46: 9860270.7 | E46: 9674323.3 | F46: 10034336 | G46: 10231727 | H46: 8854355.4 | I46: 9562093.2 | J46: 8828496.4 | K46: 9676456.7 | L46: 8881595.1 | M46: 9229902.9 | N46: 8907822.5 | O46: 8507275.2
C47: 19/20 | D47: 8912990.5 | E47: 8651562.7 | F47: 9682259.1 | G47: 9136271.4 | H47: 9561644.5 | I47: 10069078 | J47: 9289163.8 | K47: 8344654.8 | L47: 8267565.2 | M47: 8735440.8 | N47: 8488994.7 | O47: 9253891.7
B48: our view | C48: 20/21 | D48: 8906947.5 | E48: 9414183.4 | F48: 10619967 | G48: 9581099 | H48: 9543095.3 | I48: 10481680 | J48: 9355817.4 | K48: 7596084.1 | L48: 8991112.5 | M48: 8851147.7 | N48: 8433988 | O48: 8666624.3
B49: \\ | C49: 21/22 | D49: 8714128.5 | E49: 8784803.3 | F49: 10732452 | G49: 11026764 | H49: 9514232.6 | I49: 11227009 | J49: 8811105.4 | K49: 8691944.8 | L49: 9029889.6 | M49: 8346158.2 | N49: 8479472.3 | O49: 8648643
C50: 22/23 | D50: 8311515.1 | E50: 8941209.3 | F50: 9314815 | G50: 8514876.3 | H50: 8458348 | I50: 9854369.5 | J50: 8283852.3 | K50: 8600166.5 | L50: 8467434.7 | M50: 8463237 | N50: 8907229.5 | O50: 7437109.6
C51: 23/24 | D51: 8373416.4 | E51: 9578483.5 | F51: 10646680 | G51: 10879313 | H51: 9751992.3 | I51: 10901364 | J51: 9633841.8 | K51: 9720769.5 | L51: 8788031.1 | M51: 9523905.6 | N51: 9110027.2 | O51: 9019039.7
C52: 24/25 | D52: 9329042.2 | E52: 8570094.6 | F52: 10081729 | G52: 9219043.8 | H52: 9842163.4 | I52: 10658045 | J52: 9429611 | K52: 9743869.7 | L52: 9325956.3 | M52: 9206222.3 | N52: 9038449.6 | O52: 9430343.4
...

Sheet Aggregated
A1: Robusta + Arabica Exports | Q1: Excluding Peru
AH2: YTD | AI2: =_xlfn.CONCAT(AE5," | ",S6) -> | YTD : Oct-Apr
C4: 1 | D4: 2 | E4: 3 | F4: 4 | G4: 5 | H4: 6 | I4: 7 | J4: 8 | K4: 9 | L4: 10 | M4: 11 | N4: 12
C5: =_xlfn.CONCAT(A1," (Monthly)") -> Robusta + Arabica Exports (Monthly)
C6: Oct | D6: Nov | E6: Dec | F6: Jan | G6: Feb | H6: Mar | I6: Apr | J6: May | K6: Jun | L6: Jul | M6: Aug | N6: Sep | P6: Total | Q6: % | S6: =_xlfn.CONCAT("YTD : ",IF(C56=1,"Oct Only",_xlfn.CONCAT("Oct-",OFFSET(B6,0,$C$56,1,1)))) -> YTD : Oct-Apr
A7: 1 | B7: 14/15 | O7: 14/15 | P7: =IF(COUNT(C7:N7)=12,SUM(C7:N7),"") | S7: 14/15 | T7: =IFERROR(IF(SUM(OFFSET(C7,0,0,1,$C$56))=0,"",SUM(OFFSET(C7,0,0,1,$C$56))),"")
A8: 2 | B8: 15/16 | O8: 15/16 | P8: =IF(COUNT(C8:N8)=12,SUM(C8:N8),"") | Q8: =IFERROR(P8/P7-1,"") | S8: 15/16 | T8: =IFERROR(IF(SUM(OFFSET(C8,0,0,1,$C$56))=0,"",SUM(OFFSET(C8,0,0,1,$C$56))),"") | U8: =IFERROR(T8/T7-1,"") | AI8: Excluding Peru | AJ8: 0
A9: 3 | B9: 16/17 | O9: 16/17 | P9: =IF(COUNT(C9:N9)=12,SUM(C9:N9),"") | Q9: =IFERROR(P9/P8-1,"") | S9: 16/17 | T9: =IFERROR(IF(SUM(OFFSET(C9,0,0,1,$C$56))=0,"",SUM(OFFSET(C9,0,0,1,$C$56))),"") | U9: =IFERROR(T9/T8-1,"") | AI9: Including Peru | AJ9: 1
A10: 4 | B10: 17/18 | C10: ='S4 Arabica'!C10+'S5 Robusta'!C10 -> 6833010.2 | D10: ='S4 Arabica'!D10+'S5 Robusta'!D10 -> 7405175.2 | E10: ='S4 Arabica'!E10+'S5 Robusta'!E10 -> 8494818.4 | F10: ='S4 Arabica'!F10+'S5 Robusta'!F10 -> 9291366 | G10: ='S4 Arabica'!G10+'S5 Robusta'!G10 -> 7983993.2 | H10: ='S4 Arabica'!H10+'S5 Robusta'!H10 -> 9033040.9 | I10: ='S4 Arabica'!I10+'S5 Robusta'!I10 -> 8026632.8 | J10: ='S4 Arabica'!J10+'S5 Robusta'!J10 -> 7401659 | ... N10: ='S4 Arabica'!N10+'S5 Robusta'!N10 -> 7623555.6 | O10: 17/18 | P10: =IF(COUNT(C10:N10)=12,SUM(C10:N10),"") -> 95855298 | Q10: =IFERROR(P10/P9-1,"") | S10: 17/18 | T10: =IFERROR(IF(SUM(OFFSET(C10,0,0,1,$C$56))=0,"",SUM(OFFSET(C10,0,0,1,$C$56))),"") -> 57068037 | U10: =IFERROR(T10/T9-1,"")
A11: 5 | B11: 18/19 | C11: ='S4 Arabica'!C11+'S5 Robusta'!C11 -> 8467730.9 | D11: ='S4 Arabica'!D11+'S5 Robusta'!D11 -> 8939840.3 | E11: ='S4 Arabica'!E11+'S5 Robusta'!E11 -> 9197958.4 | F11: ='S4 Arabica'!F11+'S5 Robusta'!F11 -> 9930162.9 | G11: ='S4 Arabica'!G11+'S5 Robusta'!G11 -> 8710529.7 | H11: ='S4 Arabica'!H11+'S5 Robusta'!H11 -> 9221964.6 | I11: ='S4 Arabica'!I11+'S5 Robusta'!I11 -> 8577485.8 | J11: ='S4 Arabica'!J11+'S5 Robusta'!J11 -> 9360810.2 | ... N11: ='S4 Arabica'!N11+'S5 Robusta'!N11 -> 7813668.6 | O11: 18/19 | P11: =IF(COUNT(C11:N11)=12,SUM(C11:N11),"") -> 1.0598315e+08 | Q11: =IFERROR(P11/P10-1,"") -> 0.10565774 | S11: 18/19 | T11: =IFERROR(IF(SUM(OFFSET(C11,0,0,1,$C$56))=0,"",SUM(OFFSET(C11,0,0,1,$C$56))),"") -> 63045673 | U11: =IFERROR(T11/T10-1,"") -> 0.10474578
A12: 6 | B12: 19/20 | C12: ='S4 Arabica'!C12+'S5 Robusta'!C12 -> 8093038.9 | D12: ='S4 Arabica'!D12+'S5 Robusta'!D12 -> 8033227.6 | E12: ='S4 Arabica'!E12+'S5 Robusta'!E12 -> 9055351.3 | F12: ='S4 Arabica'!F12+'S5 Robusta'!F12 -> 8962610 | G12: ='S4 Arabica'!G12+'S5 Robusta'!G12 -> 9284799.8 | H12: ='S4 Arabica'!H12+'S5 Robusta'!H12 -> 9890221.6 | I12: ='S4 Arabica'!I12+'S5 Robusta'!I12 -> 8779765 | J12: ='S4 Arabica'!J12+'S5 Robusta'!J12 -> 8124567.3 | ... N12: ='S4 Arabica'!N12+'S5 Robusta'!N12 -> 8307500.7 | O12: 19/20 | P12: =IF(COUNT(C12:N12)=12,SUM(C12:N12),"") -> 1.0241375e+08 | Q12: =IFERROR(P12/P11-1,"") -> -0.033678947 | S12: 19/20 | T12: =IFERROR(IF(SUM(OFFSET(C12,0,0,1,$C$56))=0,"",SUM(OFFSET(C12,0,0,1,$C$56))),"") -> 62099014 | U12: =IFERROR(T12/T11-1,"") -> -0.015015436 | AI12: =_xlfn.XLOOKUP(Q1,$AI$8:$AI$9,AJ8:AJ9) -> 0
A13: 7 | B13: 20/21 | C13: ='S4 Arabica'!C13+'S5 Robusta'!C13 -> 8453083 | D13: ='S4 Arabica'!D13+'S5 Robusta'!D13 -> 8856397.2 | E13: ='S4 Arabica'!E13+'S5 Robusta'!E13 -> 9752196.3 | F13: ='S4 Arabica'!F13+'S5 Robusta'!F13 -> 9270005.3 | G13: ='S4 Arabica'!G13+'S5 Robusta'!G13 -> 9348363.9 | H13: ='S4 Arabica'!H13+'S5 Robusta'!H13 -> 10306913 | I13: ='S4 Arabica'!I13+'S5 Robusta'!I13 -> 9176402.7 | J13: ='S4 Arabica'!J13+'S5 Robusta'!J13 -> 8016814.1 | ... N13: ='S4 Arabica'!N13+'S5 Robusta'!N13 -> 8075279.7 | O13: 20/21 | P13: =IF(COUNT(C13:N13)=12,SUM(C13:N13),"") -> 1.0666928e+08 | Q13: =IFERROR(P13/P12-1,"") -> 0.041552274 | S13: 20/21 | T13: =IFERROR(IF(SUM(OFFSET(C13,0,0,1,$C$56))=0,"",SUM(OFFSET(C13,0,0,1,$C$56))),"") -> 65163362 | U13: =IFERROR(T13/T12-1,"") -> 0.04934615
A14: 8 | B14: 21/22 | C14: ='S4 Arabica'!C14+'S5 Robusta'!C14 -> 8118274.1 | D14: ='S4 Arabica'!D14+'S5 Robusta'!D14 -> 8170179.8 | E14: ='S4 Arabica'!E14+'S5 Robusta'!E14 -> 10029931 | F14: ='S4 Arabica'!F14+'S5 Robusta'!F14 -> 10434924 | G14: ='S4 Arabica'!G14+'S5 Robusta'!G14 -> 8851085.2 | H14: ='S4 Arabica'!H14+'S5 Robusta'!H14 -> 10788066 | I14: ='S4 Arabica'!I14+'S5 Robusta'!I14 -> 8566342.7 | J14: ='S4 Arabica'!J14+'S5 Robusta'!J14 -> 8456691.9 | ... N14: ='S4 Arabica'!N14+'S5 Robusta'!N14 -> 7831576.6 | O14: 21/22 | P14: =IF(COUNT(C14:N14)=12,SUM(C14:N14),"") -> 1.0552477e+08 | Q14: =IFERROR(P14/P13-1,"") -> -0.010729436 | S14: 21/22 | T14: =IFERROR(IF(SUM(OFFSET(C14,0,0,1,$C$56))=0,"",SUM(OFFSET(C14,0,0,1,$C$56))),"") -> 64958803 | U14: =IFERROR(T14/T13-1,"") -> -0.003139168
A15: 9 | B15: 22/23 | C15: ='S4 Arabica'!C15+'S5 Robusta'!C15 -> 7561106.7 | D15: ='S4 Arabica'!D15+'S5 Robusta'!D15 -> 8502755.4 | E15: ='S4 Arabica'!E15+'S5 Robusta'!E15 -> 8925436.8 | F15: ='S4 Arabica'!F15+'S5 Robusta'!F15 -> 8094056.4 | G15: ='S4 Arabica'!G15+'S5 Robusta'!G15 -> 8053002.5 | H15: ='S4 Arabica'!H15+'S5 Robusta'!H15 -> 9588221.4 | I15: ='S4 Arabica'!I15+'S5 Robusta'!I15 -> 8172030.9 | J15: ='S4 Arabica'!J15+'S5 Robusta'!J15 -> 8173643.4 | ... N15: ='S4 Arabica'!N15+'S5 Robusta'!N15 -> 6682272.4 | O15: 22/23 | P15: =IF(COUNT(C15:N15)=12,SUM(C15:N15),"") -> 98125074 | Q15: =IFERROR(P15/P14-1,"") -> -0.070122867 | S15: 22/23 | T15: =IFERROR(IF(SUM(OFFSET(C15,0,0,1,$C$56))=0,"",SUM(OFFSET(C15,0,0,1,$C$56))),"") -> 58896610 | U15: =IFERROR(T15/T14-1,"") -> -0.093323652
A16: 10 | B16: 23/24 | C16: ='S4 Arabica'!C16+'S5 Robusta'!C16 -> 7436082.2 | D16: ='S4 Arabica'!D16+'S5 Robusta'!D16 -> 8816020.3 | E16: ='S4 Arabica'!E16+'S5 Robusta'!E16 -> 9760201.6 | F16: ='S4 Arabica'!F16+'S5 Robusta'!F16 -> 10206683 | G16: ='S4 Arabica'!G16+'S5 Robusta'!G16 -> 9280221.4 | H16: ='S4 Arabica'!H16+'S5 Robusta'!H16 -> 10613253 | I16: ='S4 Arabica'!I16+'S5 Robusta'!I16 -> 9490552.4 | J16: ='S4 Arabica'!J16+'S5 Robusta'!J16 -> 9285578.6 | ... N16: ='S4 Arabica'!N16+'S5 Robusta'!N16 -> 8435922.6 | O16: 23/24 | P16: =IF(COUNT(C16:N16)=12,SUM(C16:N16),"") -> 1.0907777e+08 | Q16: =IFERROR(P16/P15-1,"") -> 0.11161976 | S16: 23/24 | T16: =IFERROR(IF(SUM(OFFSET(C16,0,0,1,$C$56))=0,"",SUM(OFFSET(C16,0,0,1,$C$56))),"") -> 65603013 | U16: =IFERROR(T16/T15-1,"") -> 0.11386739
A17: 11 | B17: 24/25 | C17: ='S4 Arabica'!C17+'S5 Robusta'!C17 -> 8837729.3 | D17: ='S4 Arabica'!D17+'S5 Robusta'!D17 -> 8266814.1 | E17: ='S4 Arabica'!E17+'S5 Robusta'!E17 -> 9853980.6 | F17: ='S4 Arabica'!F17+'S5 Robusta'!F17 -> 9137737.4 | G17: ='S4 Arabica'!G17+'S5 Robusta'!G17 -> 9800870.4 | H17: ='S4 Arabica'!H17+'S5 Robusta'!H17 -> 10626759 | I17: ='S4 Arabica'!I17+'S5 Robusta'!I17 -> 9384016.2 | J17: ='S4 Arabica'!J17+'S5 Robusta'!J17 -> 9626982.3 | ... N17: ='S4 Arabica'!N17+'S5 Robusta'!N17 -> 8768594.3 | O17: 24/25 | P17: =IF(COUNT(C17:N17)=12,SUM(C17:N17),"") -> 1.1066271e+08 | S17: 24/25 | T17: =IFERROR(IF(SUM(OFFSET(C17,0,0,1,$C$56))=0,"",SUM(OFFSET(C17,0,0,1,$C$56))),"") -> 65907907 | U17: =IFERROR(T17/T16-1,"") -> 0.0046475593
A18: 12 | B18: 25/26 | C18: ='S4 Arabica'!C18+'S5 Robusta'!C18 -> 8608395.9 | D18: ='S4 Arabica'!D18+'S5 Robusta'!D18 -> 8341499.9 | E18: ='S4 Arabica'!E18+'S5 Robusta'!E18 -> 9201239.5 | F18: ='S4 Arabica'!F18+'S5 Robusta'!F18 -> 9401730.7 | G18: ='S4 Arabica'!G18+'S5 Robusta'!G18 -> 8318875.7 | H18: ='S4 Arabica'!H18+'S5 Robusta'!H18 -> 9517766 | I18: ='S4 Arabica'!I18+'S5 Robusta'!I18 -> 9552886 | J18: ='S4 Arabica'!J18+'S5 Robusta'!J18 -> #N/A | ... N18: ='S4 Arabica'!N18+'S5 Robusta'!N18 -> #N/A | O18: 25/26 | P18: =IF(COUNT(C18:N18)=12,SUM(C18:N18),"") | S18: 25/26 | T18: =IFERROR(IF(SUM(OFFSET(C18,0,0,1,$C$56))=0,"",SUM(OFFSET(C18,0,0,1,$C$56))),"") -> 62942394
A19: 13 | B19: 26/27 | C19: ='S4 Arabica'!C19+'S5 Robusta'!C19 -> #N/A | D19: ='S4 Arabica'!D19+'S5 Robusta'!D19 -> #N/A | E19: ='S4 Arabica'!E19+'S5 Robusta'!E19 -> #N/A | F19: ='S4 Arabica'!F19+'S5 Robusta'!F19 -> #N/A | G19: ='S4 Arabica'!G19+'S5 Robusta'!G19 -> #N/A | H19: ='S4 Arabica'!H19+'S5 Robusta'!H19 -> #N/A | I19: ='S4 Arabica'!I19+'S5 Robusta'!I19 -> #N/A | J19: ='S4 Arabica'!J19+'S5 Robusta'!J19 -> #N/A | ... N19: ='S4 Arabica'!N19+'S5 Robusta'!N19 -> #N/A | O19: 26/27 | P19: =IF(COUNT(C19:N19)=12,SUM(C19:N19),"") | S19: 26/27 | T19: =IFERROR(IF(SUM(OFFSET(C19,0,0,1,$C$56))=0,"",SUM(OFFSET(C19,0,0,1,$C$56))),"")
B20: YoY | C20: =IFERROR(C18/C17-1,"") -> -0.025949364 | D20: =IFERROR(D18/D17-1,"") -> 0.0090344085 | E20: =IFERROR(E18/E17-1,"") -> -0.066241361 | F20: =IFERROR(F18/F17-1,"") -> 0.028890442 | G20: =IFERROR(G18/G17-1,"") -> -0.15121052 | H20: =IFERROR(H18/H17-1,"") -> -0.10435855 | I20: =IFERROR(I18/I17-1,"") -> 0.017995475 | J20: =IFERROR(J18/J17-1,"") | ... N20: =IFERROR(N18/N17-1,"")
K27: =_xlfn.CONCAT(A1," | ",S6) -> Robusta + Arabica Exports | YTD : Oct-Apr | Q27: =_xlfn.CONCAT(A1," | ","Cumulative") -> Robusta + Arabica Exports | Cumulative
B56: Offset | C56: =COUNT(C18:N18) -> 7 | D56: =OFFSET(B6,0,$C$56,1,1) -> Apr | E56: =B18 -> 25/26 | F56: =_xlfn.CONCAT(D56,"'",E56) -> Apr'25/26
B65: Oct | C65: Nov | D65: Dec | E65: Jan | F65: Feb | G65: Mar | H65: Apr | I65: May | J65: Jun | K65: Jul | L65: Aug | M65: Sep
A66: =B18 -> 25/26 | B66: =C18 -> 8608395.9 | C66: =D18 -> 8341499.9 | D66: =E18 -> 9201239.5 | E66: =F18 -> 9401730.7 | F66: =G18 -> 8318875.7 | G66: =H18 -> 9517766 | H66: =I18 -> 9552886 | ... M66: =N18 -> #N/A
A67: Min | B67: =MIN(C7:C17) -> 6833010.2 | C67: =MIN(D7:D17) -> 7405175.2 | D67: =MIN(E7:E17) -> 8494818.4 | E67: =MIN(F7:F17) -> 8094056.4 | F67: =MIN(G7:G17) -> 7983993.2 | G67: =MIN(H7:H17) -> 9033040.9 | H67: =MIN(I7:I17) -> 8026632.8 | I67: =MIN(J7:J17) -> 7401659 | ... M67: =MIN(N7:N17) -> 6682272.4
A68: Max | B68: =MAX(C7:C17) -> 8837729.3 | C68: =MAX(D7:D17) -> 8939840.3 | D68: =MAX(E7:E17) -> 10029931 | E68: =MAX(F7:F17) -> 10434924 | F68: =MAX(G7:G17) -> 9800870.4 | G68: =MAX(H7:H17) -> 10788066 | H68: =MAX(I7:I17) -> 9490552.4 | I68: =MAX(J7:J17) -> 9626982.3 | ... M68: =MAX(N7:N17) -> 8768594.3
A69: Avg(5) | B69: =AVERAGE(C12:C17) -> 8083219 | C69: =AVERAGE(D12:D17) -> 8440899.1 | D69: =AVERAGE(E12:E17) -> 9562849.6 | E69: =AVERAGE(F12:F17) -> 9351002.6 | F69: =AVERAGE(G12:G17) -> 9103057.2 | G69: =AVERAGE(H12:H17) -> 10302239 | H69: =AVERAGE(I12:I17) -> 8928185 | I69: =AVERAGE(J12:J17) -> 8614046.3 | ... M69: =AVERAGE(N12:N17) -> 8016857.7
B74: 1 | C74: 1 | D74: =INDEX($C$7:$N$19,MATCH(B74,$A$7:$A$19),MATCH(C74,$C$4:$N$4)) -> 0 | E74: =_xlfn.XLOOKUP(B74,$A$7:$A$19,$B$7:$B$19) -> 14/15 | F74: =_xlfn.XLOOKUP(C74,$C$4:$N$4,$C$6:$N$6) -> Oct | G74: =_xlfn.CONCAT(F74,"'",E74) -> Oct'14/15 | N74: Cumulative
B75: 1 | C75: 2 | D75: =INDEX($C$7:$N$19,MATCH(B75,$A$7:$A$19),MATCH(C75,$C$4:$N$4)) -> 0 | E75: =_xlfn.XLOOKUP(B75,$A$7:$A$19,$B$7:$B$19) -> 14/15 | F75: =_xlfn.XLOOKUP(C75,$C$4:$N$4,$C$6:$N$6) -> Nov | G75: =_xlfn.CONCAT(F75,"'",E75) -> Nov'14/15 | N75: Oct | O75: Nov | P75: Dec | Q75: Jan | R75: Feb | S75: Mar | T75: Apr | U75: May | V75: Jun | W75: Jul | X75: Aug | Y75: Sep
B76: 1 | C76: 3 | D76: =INDEX($C$7:$N$19,MATCH(B76,$A$7:$A$19),MATCH(C76,$C$4:$N$4)) -> 0 | E76: =_xlfn.XLOOKUP(B76,$A$7:$A$19,$B$7:$B$19) -> 14/15 | F76: =_xlfn.XLOOKUP(C76,$C$4:$N$4,$C$6:$N$6) -> Dec | G76: =_xlfn.CONCAT(F76,"'",E76) -> Dec'14/15 | M76: 14/15 | N76: =C7 -> 0 | O76: =N76+D7 -> 0 | P76: =O76+E7 -> 0 | Q76: =P76+F7 -> 0 | R76: =Q76+G7 -> 0 | S76: =R76+H7 -> 0 | T76: =S76+I7 -> 0 | U76: =T76+J7 -> 0 | V76: =U76+K7 -> 0 | ... Y76: =X76+N7 -> 0
B77: 1 | C77: 4 | D77: =INDEX($C$7:$N$19,MATCH(B77,$A$7:$A$19),MATCH(C77,$C$4:$N$4)) -> 0 | E77: =_xlfn.XLOOKUP(B77,$A$7:$A$19,$B$7:$B$19) -> 14/15 | F77: =_xlfn.XLOOKUP(C77,$C$4:$N$4,$C$6:$N$6) -> Jan | G77: =_xlfn.CONCAT(F77,"'",E77) -> Jan'14/15 | M77: 15/16 | N77: =C8 -> 0 | O77: =N77+D8 -> 0 | P77: =O77+E8 -> 0 | Q77: =P77+F8 -> 0 | R77: =Q77+G8 -> 0 | S77: =R77+H8 -> 0 | T77: =S77+I8 -> 0 | U77: =T77+J8 -> 0 | V77: =U77+K8 -> 0 | ... Y77: =X77+N8 -> 0
B78: 1 | C78: 5 | D78: =INDEX($C$7:$N$19,MATCH(B78,$A$7:$A$19),MATCH(C78,$C$4:$N$4)) -> 0 | E78: =_xlfn.XLOOKUP(B78,$A$7:$A$19,$B$7:$B$19) -> 14/15 | F78: =_xlfn.XLOOKUP(C78,$C$4:$N$4,$C$6:$N$6) -> Feb | G78: =_xlfn.CONCAT(F78,"'",E78) -> Feb'14/15 | M78: 16/17 | N78: =C9 -> 0 | O78: =N78+D9 -> 0 | P78: =O78+E9 -> 0 | Q78: =P78+F9 -> 0 | R78: =Q78+G9 -> 0 | S78: =R78+H9 -> 0 | T78: =S78+I9 -> 0 | U78: =T78+J9 -> 0 | V78: =U78+K9 -> 0 | ... Y78: =X78+N9 -> 0
B79: 1 | C79: 6 | D79: =INDEX($C$7:$N$19,MATCH(B79,$A$7:$A$19),MATCH(C79,$C$4:$N$4)) -> 0 | E79: =_xlfn.XLOOKUP(B79,$A$7:$A$19,$B$7:$B$19) -> 14/15 | F79: =_xlfn.XLOOKUP(C79,$C$4:$N$4,$C$6:$N$6) -> Mar | G79: =_xlfn.CONCAT(F79,"'",E79) -> Mar'14/15 | M79: 17/18 | N79: =C10 -> 6833010.2 | O79: =N79+D10 -> 14238185 | P79: =O79+E10 -> 22733004 | Q79: =P79+F10 -> 32024370 | R79: =Q79+G10 -> 40008363 | S79: =R79+H10 -> 49041404 | T79: =S79+I10 -> 57068037 | U79: =T79+J10 -> 64469696 | V79: =U79+K10 -> 72501153 | ... Y79: =X79+N10 -> 95855298
B80: 1 | C80: 7 | D80: =INDEX($C$7:$N$19,MATCH(B80,$A$7:$A$19),MATCH(C80,$C$4:$N$4)) -> 0 | E80: =_xlfn.XLOOKUP(B80,$A$7:$A$19,$B$7:$B$19) -> 14/15 | F80: =_xlfn.XLOOKUP(C80,$C$4:$N$4,$C$6:$N$6) -> Apr | G80: =_xlfn.CONCAT(F80,"'",E80) -> Apr'14/15 | M80: 18/19 | N80: =C11 -> 8467730.9 | O80: =N80+D11 -> 17407571 | P80: =O80+E11 -> 26605530 | Q80: =P80+F11 -> 36535693 | R80: =Q80+G11 -> 45246222 | S80: =R80+H11 -> 54468187 | T80: =S80+I11 -> 63045673 | U80: =T80+J11 -> 72406483 | V80: =U80+K11 -> 81009585 | ... Y80: =X80+N11 -> 1.0598315e+08
B81: 1 | C81: 8 | D81: =INDEX($C$7:$N$19,MATCH(B81,$A$7:$A$19),MATCH(C81,$C$4:$N$4)) -> 0 | E81: =_xlfn.XLOOKUP(B81,$A$7:$A$19,$B$7:$B$19) -> 14/15 | F81: =_xlfn.XLOOKUP(C81,$C$4:$N$4,$C$6:$N$6) -> May | G81: =_xlfn.CONCAT(F81,"'",E81) -> May'14/15 | M81: 19/20 | N81: =C12 -> 8093038.9 | O81: =N81+D12 -> 16126267 | P81: =O81+E12 -> 25181618 | Q81: =P81+F12 -> 34144228 | R81: =Q81+G12 -> 43429028 | S81: =R81+H12 -> 53319249 | T81: =S81+I12 -> 62099014 | U81: =T81+J12 -> 70223582 | V81: =U81+K12 -> 78272903 | ... Y81: =X81+N12 -> 1.0241375e+08
B82: 1 | C82: 9 | D82: =INDEX($C$7:$N$19,MATCH(B82,$A$7:$A$19),MATCH(C82,$C$4:$N$4)) -> 0 | E82: =_xlfn.XLOOKUP(B82,$A$7:$A$19,$B$7:$B$19) -> 14/15 | F82: =_xlfn.XLOOKUP(C82,$C$4:$N$4,$C$6:$N$6) -> Jun | G82: =_xlfn.CONCAT(F82,"'",E82) -> Jun'14/15 | M82: 20/21 | N82: =C13 -> 8453083 | O82: =N82+D13 -> 17309480 | P82: =O82+E13 -> 27061676 | Q82: =P82+F13 -> 36331682 | R82: =Q82+G13 -> 45680046 | S82: =R82+H13 -> 55986959 | T82: =S82+I13 -> 65163362 | U82: =T82+J13 -> 73180176 | V82: =U82+K13 -> 81979173 | ... Y82: =X82+N13 -> 1.0666928e+08
B83: 1 | C83: 10 | D83: =INDEX($C$7:$N$19,MATCH(B83,$A$7:$A$19),MATCH(C83,$C$4:$N$4)) -> 0 | E83: =_xlfn.XLOOKUP(B83,$A$7:$A$19,$B$7:$B$19) -> 14/15 | F83: =_xlfn.XLOOKUP(C83,$C$4:$N$4,$C$6:$N$6) -> Jul | G83: =_xlfn.CONCAT(F83,"'",E83) -> Jul'14/15 | M83: 21/22 | N83: =C14 -> 8118274.1 | O83: =N83+D14 -> 16288454 | P83: =O83+E14 -> 26318385 | Q83: =P83+F14 -> 36753309 | R83: =Q83+G14 -> 45604394 | S83: =R83+H14 -> 56392460 | T83: =S83+I14 -> 64958803 | U83: =T83+J14 -> 73415495 | V83: =U83+K14 -> 82104455 | ... Y83: =X83+N14 -> 1.0552477e+08
B84: 1 | C84: 11 | D84: =INDEX($C$7:$N$19,MATCH(B84,$A$7:$A$19),MATCH(C84,$C$4:$N$4)) -> 0 | E84: =_xlfn.XLOOKUP(B84,$A$7:$A$19,$B$7:$B$19) -> 14/15 | F84: =_xlfn.XLOOKUP(C84,$C$4:$N$4,$C$6:$N$6) -> Aug | G84: =_xlfn.CONCAT(F84,"'",E84) -> Aug'14/15 | H84: Month | I84: Rolling 12m Sum | M84: 22/23 | N84: =C15 -> 7561106.7 | O84: =N84+D15 -> 16063862 | P84: =O84+E15 -> 24989299 | Q84: =P84+F15 -> 33083355 | R84: =Q84+G15 -> 41136358 | S84: =R84+H15 -> 50724579 | T84: =S84+I15 -> 58896610 | U84: =T84+J15 -> 67070253 | V84: =U84+K15 -> 75187710 | ... Y84: =X84+N15 -> 98125074
B85: 1 | C85: 12 | D85: =INDEX($C$7:$N$19,MATCH(B85,$A$7:$A$19),MATCH(C85,$C$4:$N$4)) -> 0 | E85: =_xlfn.XLOOKUP(B85,$A$7:$A$19,$B$7:$B$19) -> 14/15 | F85: =_xlfn.XLOOKUP(C85,$C$4:$N$4,$C$6:$N$6) -> Sep | G85: =_xlfn.CONCAT(F85,"'",E85) -> Sep'14/15 | H85: =G85 -> Sep'14/15 | I85: =SUM(D74:D85)/1000000 -> 0 | M85: 23/24 | N85: =C16 -> 7436082.2 | O85: =N85+D16 -> 16252102 | P85: =O85+E16 -> 26012304 | Q85: =P85+F16 -> 36218987 | R85: =Q85+G16 -> 45499208 | S85: =R85+H16 -> 56112461 | T85: =S85+I16 -> 65603013 | U85: =T85+J16 -> 74888592 | V85: =U85+K16 -> 83270828 | ... Y85: =X85+N16 -> 1.0907777e+08
B86: =B74+1 -> 2 | C86: =C74 -> 1 | D86: =INDEX($C$7:$N$19,MATCH(B86,$A$7:$A$19),MATCH(C86,$C$4:$N$4)) -> 0 | E86: =_xlfn.XLOOKUP(B86,$A$7:$A$19,$B$7:$B$19) -> 15/16 | F86: =_xlfn.XLOOKUP(C86,$C$4:$N$4,$C$6:$N$6) -> Oct | G86: =_xlfn.CONCAT(F86,"'",E86) -> Oct'15/16 | H86: =G86 -> Oct'15/16 | I86: =SUM(D75:D86)/1000000 -> 0 | M86: 24/25 | N86: =C17 -> 8837729.3 | O86: =N86+D17 -> 17104543 | P86: =O86+E17 -> 26958524 | Q86: =P86+F17 -> 36096261 | R86: =Q86+G17 -> 45897132 | S86: =R86+H17 -> 56523891 | T86: =S86+I17 -> 65907907 | U86: =T86+J17 -> 75534889 | V86: =U86+K17 -> 84554462 | ... Y86: =X86+N17 -> 1.1066271e+08
B87: =B75+1 -> 2 | C87: =C75 -> 2 | D87: =INDEX($C$7:$N$19,MATCH(B87,$A$7:$A$19),MATCH(C87,$C$4:$N$4)) -> 0 | E87: =_xlfn.XLOOKUP(B87,$A$7:$A$19,$B$7:$B$19) -> 15/16 | F87: =_xlfn.XLOOKUP(C87,$C$4:$N$4,$C$6:$N$6) -> Nov | G87: =_xlfn.CONCAT(F87,"'",E87) -> Nov'15/16 | H87: =G87 -> Nov'15/16 | I87: =SUM(D76:D87)/1000000 -> 0 | M87: 25/26 | N87: =C18 -> 8608395.9 | O87: =N87+D18 -> 16949896 | P87: =O87+E18 -> 26151135 | Q87: =P87+F18 -> 35552866 | R87: =Q87+G18 -> 43871742 | S87: =R87+H18 -> 53389508 | T87: =S87+I18 -> 62942394 | U87: =T87+J18 -> #N/A | V87: =U87+K18 -> #N/A | ... Y87: =X87+N18 -> #N/A
...

Sheet Agg (Peru Included)
A1: Robusta + Arabica Exports | Q1: Including Peru
AH2: YTD | AI2: =_xlfn.CONCAT(AE5," | ",S6) -> | YTD : Oct-Sep
C4: 1 | D4: 2 | E4: 3 | F4: 4 | G4: 5 | H4: 6 | I4: 7 | J4: 8 | K4: 9 | L4: 10 | M4: 11 | N4: 12
C5: =_xlfn.CONCAT(A1," (Monthly)") -> Robusta + Arabica Exports (Monthly)
C6: Oct | D6: Nov | E6: Dec | F6: Jan | G6: Feb | H6: Mar | I6: Apr | J6: May | K6: Jun | L6: Jul | M6: Aug | N6: Sep | P6: Total | Q6: % | S6: =_xlfn.CONCAT("YTD : ",IF(C56=1,"Oct Only",_xlfn.CONCAT("Oct-",OFFSET(B6,0,$C$56,1,1)))) -> YTD : Oct-Sep
A7: 1 | B7: 14/15 | O7: 14/15 | P7: =IF(COUNT(C7:N7)=12,SUM(C7:N7),"") | S7: 14/15 | T7: =IFERROR(IF(SUM(OFFSET(C7,0,0,1,$C$56))=0,"",SUM(OFFSET(C7,0,0,1,$C$56))),"")
A8: 2 | B8: 15/16 | O8: 15/16 | P8: =IF(COUNT(C8:N8)=12,SUM(C8:N8),"") | Q8: =IFERROR(P8/P7-1,"") | S8: 15/16 | T8: =IFERROR(IF(SUM(OFFSET(C8,0,0,1,$C$56))=0,"",SUM(OFFSET(C8,0,0,1,$C$56))),"") | U8: =IFERROR(T8/T7-1,"") | AI8: Excluding Peru | AJ8: 0
A9: 3 | B9: 16/17 | O9: 16/17 | P9: =IF(COUNT(C9:N9)=12,SUM(C9:N9),"") | Q9: =IFERROR(P9/P8-1,"") | S9: 16/17 | T9: =IFERROR(IF(SUM(OFFSET(C9,0,0,1,$C$56))=0,"",SUM(OFFSET(C9,0,0,1,$C$56))),"") | U9: =IFERROR(T9/T8-1,"") | AI9: Including Peru | AJ9: 1
